Internal Server Error: /api/users/register/
Traceback (most recent call last):
  File "C:\Users\phara\OneDrive\Desktop\Django_project\dictionary_project\venv\Lib\site-packages\django\core\handlers\exception.py", line 55, in inner
    response = get_response(request)
  File "C:\Users\phara\OneDrive\Desktop\Django_project\dictionary_project\venv\Lib\site-packages\django\core\handlers\base.py", line 197, in _get_response
    response = wrapped_callback(request, *callback_args, **callback_kwargs)
  File "C:\Users\phara\OneDrive\Desktop\Django_project\dictionary_project\venv\Lib\site-packages\django\views\decorators\csrf.py", line 65, in _view_wrapper
    return view_func(request, *args, **kwargs)
  File "C:\Users\phara\OneDrive\Desktop\Django_project\dictionary_project\venv\Lib\site-packages\django\views\generic\base.py", line 104, in view
    return self.dispatch(request, *args, **kwargs)
           ~~~~~~~~~~~~~^^^^^^^^^^^^^^^^^^^^^^^^^^
  File "C:\Users\phara\OneDrive\Desktop\Django_project\dictionary_project\venv\Lib\site-packages\rest_framework\views.py", line 509, in dispatch
    response = self.handle_exception(exc)
  File "C:\Users\phara\OneDrive\Desktop\Django_project\dictionary_project\venv\Lib\site-packages\rest_framework\views.py", line 469, in handle_exception
    self.raise_uncaught_exception(exc)
    ~~~~~~~~~~~~~~~~~~~~~~~~~~~~~^^^^^
  File "C:\Users\phara\OneDrive\Desktop\Django_project\dictionary_project\venv\Lib\site-packages\rest_framework\views.py", line 480, in raise_uncaught_exception
    raise exc
  File "C:\Users\phara\OneDrive\Desktop\Django_project\dictionary_project\venv\Lib\site-packages\rest_framework\views.py", line 506, in dispatch
    response = handler(request, *args, **kwargs)
  File "C:\Users\phara\OneDrive\Desktop\Django_project\dictionary_project\users\views.py", line 125, in post
    if serializer.is_valid():
       ~~~~~~~~~~~~~~~~~~~^^
  File "C:\Users\phara\OneDrive\Desktop\Django_project\dictionary_project\venv\Lib\site-packages\rest_framework\serializers.py", line 223, in is_valid
    self._validated_data = self.run_validation(self.initial_data)
                           ~~~~~~~~~~~~~~~~~~~^^^^^^^^^^^^^^^^^^^
  File "C:\Users\phara\OneDrive\Desktop\Django_project\dictionary_project\venv\Lib\site-packages\rest_framework\serializers.py", line 442, in run_validation
    value = self.to_internal_value(data)
  File "C:\Users\phara\OneDrive\Desktop\Django_project\dictionary_project\venv\Lib\site-packages\rest_framework\serializers.py", line 495, in to_internal_value
    for field in fields:
                 ^^^^^^
  File "C:\Users\phara\OneDrive\Desktop\Django_project\dictionary_project\venv\Lib\site-packages\rest_framework\serializers.py", line 378, in _writable_fields
    for field in self.fields.values():
                 ^^^^^^^^^^^
  File "C:\Users\phara\OneDrive\Desktop\Django_project\dictionary_project\venv\Lib\site-packages\django\utils\functional.py", line 47, in __get__
    res = instance.__dict__[self.name] = self.func(instance)
                                         ~~~~~~~~~^^^^^^^^^^
  File "C:\Users\phara\OneDrive\Desktop\Django_project\dictionary_project\venv\Lib\site-packages\rest_framework\serializers.py", line 372, in fields
    for key, value in self.get_fields().items():
                      ~~~~~~~~~~~~~~~^^
  File "C:\Users\phara\OneDrive\Desktop\Django_project\dictionary_project\venv\Lib\site-packages\rest_framework\serializers.py", line 1103, in get_fields
    field_class, field_kwargs = self.build_field(
                                ~~~~~~~~~~~~~~~~^
        source, info, model, depth
        ^^^^^^^^^^^^^^^^^^^^^^^^^^
    )
    ^
  File "C:\Users\phara\OneDrive\Desktop\Django_project\dictionary_project\venv\Lib\site-packages\rest_framework\serializers.py", line 1249, in build_field
    return self.build_unknown_field(field_name, model_class)
           ~~~~~~~~~~~~~~~~~~~~~~~~^^^^^^^^^^^^^^^^^^^^^^^^^
  File "C:\Users\phara\OneDrive\Desktop\Django_project\dictionary_project\venv\Lib\site-packages\rest_framework\serializers.py", line 1367, in build_unknown_field
    raise ImproperlyConfigured(
    ...<2 lines>...
    )
django.core.exceptions.ImproperlyConfigured: Field name `phone_number` is not valid for model `User` in `users.serializers.UserSerializer`.
"POST /api/users/register/ HTTP/1.1" 500 149783
Internal Server Error: /swagger/
Traceback (most recent call last):
  File "C:\Users\phara\OneDrive\Desktop\Django_project\dictionary_project\venv\Lib\site-packages\django\core\handlers\exception.py", line 55, in inner
    response = get_response(request)
  File "C:\Users\phara\OneDrive\Desktop\Django_project\dictionary_project\venv\Lib\site-packages\django\core\handlers\base.py", line 197, in _get_response
    response = wrapped_callback(request, *callback_args, **callback_kwargs)
  File "C:\Users\phara\OneDrive\Desktop\Django_project\dictionary_project\venv\Lib\site-packages\django\views\decorators\csrf.py", line 65, in _view_wrapper
    return view_func(request, *args, **kwargs)
  File "C:\Users\phara\OneDrive\Desktop\Django_project\dictionary_project\venv\Lib\site-packages\django\views\generic\base.py", line 104, in view
    return self.dispatch(request, *args, **kwargs)
           ~~~~~~~~~~~~~^^^^^^^^^^^^^^^^^^^^^^^^^^
  File "C:\Users\phara\OneDrive\Desktop\Django_project\dictionary_project\venv\Lib\site-packages\rest_framework\views.py", line 509, in dispatch
    response = self.handle_exception(exc)
  File "C:\Users\phara\OneDrive\Desktop\Django_project\dictionary_project\venv\Lib\site-packages\rest_framework\views.py", line 469, in handle_exception
    self.raise_uncaught_exception(exc)
    ~~~~~~~~~~~~~~~~~~~~~~~~~~~~~^^^^^
  File "C:\Users\phara\OneDrive\Desktop\Django_project\dictionary_project\venv\Lib\site-packages\rest_framework\views.py", line 480, in raise_uncaught_exception
    raise exc
  File "C:\Users\phara\OneDrive\Desktop\Django_project\dictionary_project\venv\Lib\site-packages\rest_framework\views.py", line 506, in dispatch
    response = handler(request, *args, **kwargs)
  File "C:\Users\phara\OneDrive\Desktop\Django_project\dictionary_project\venv\Lib\site-packages\drf_yasg\views.py", line 112, in get
    schema = generator.get_schema(request, self.public)
  File "C:\Users\phara\OneDrive\Desktop\Django_project\dictionary_project\venv\Lib\site-packages\drf_yasg\generators.py", line 276, in get_schema
    paths, prefix = self.get_paths(endpoints, components, request, public)
                    ~~~~~~~~~~~~~~^^^^^^^^^^^^^^^^^^^^^^^^^^^^^^^^^^^^^^^^
  File "C:\Users\phara\OneDrive\Desktop\Django_project\dictionary_project\venv\Lib\site-packages\drf_yasg\generators.py", line 482, in get_paths
    operation = self.get_operation(view, path, prefix, method, components, request)
  File "C:\Users\phara\OneDrive\Desktop\Django_project\dictionary_project\venv\Lib\site-packages\drf_yasg\generators.py", line 524, in get_operation
    operation = view_inspector.get_operation(operation_keys)
  File "C:\Users\phara\OneDrive\Desktop\Django_project\dictionary_project\venv\Lib\site-packages\drf_yasg\inspectors\view.py", line 32, in get_operation
    body = self.get_request_body_parameters(consumes)
  File "C:\Users\phara\OneDrive\Desktop\Django_project\dictionary_project\venv\Lib\site-packages\drf_yasg\inspectors\view.py", line 71, in get_request_body_parameters
    serializer = self.get_request_serializer()
  File "C:\Users\phara\OneDrive\Desktop\Django_project\dictionary_project\venv\Lib\site-packages\drf_yasg\inspectors\view.py", line 118, in get_request_serializer
    body_override = self._get_request_body_override()
  File "C:\Users\phara\OneDrive\Desktop\Django_project\dictionary_project\venv\Lib\site-packages\drf_yasg\inspectors\view.py", line 104, in _get_request_body_override
    raise SwaggerGenerationError("request_body can only be applied to (" + ','.join(self.body_methods) +
                                 "); are you looking for query_serializer or manual_parameters?")
drf_yasg.errors.SwaggerGenerationError: request_body can only be applied to (PUT,PATCH,POST,DELETE); are you looking for query_serializer or manual_parameters?
"GET /swagger/?format=openapi HTTP/1.1" 500 157200
Internal Server Error: /swagger/
Traceback (most recent call last):
  File "C:\Users\phara\OneDrive\Desktop\Django_project\dictionary_project\venv\Lib\site-packages\django\core\handlers\exception.py", line 55, in inner
    response = get_response(request)
  File "C:\Users\phara\OneDrive\Desktop\Django_project\dictionary_project\venv\Lib\site-packages\django\core\handlers\base.py", line 197, in _get_response
    response = wrapped_callback(request, *callback_args, **callback_kwargs)
  File "C:\Users\phara\OneDrive\Desktop\Django_project\dictionary_project\venv\Lib\site-packages\django\views\decorators\csrf.py", line 65, in _view_wrapper
    return view_func(request, *args, **kwargs)
  File "C:\Users\phara\OneDrive\Desktop\Django_project\dictionary_project\venv\Lib\site-packages\django\views\generic\base.py", line 104, in view
    return self.dispatch(request, *args, **kwargs)
           ~~~~~~~~~~~~~^^^^^^^^^^^^^^^^^^^^^^^^^^
  File "C:\Users\phara\OneDrive\Desktop\Django_project\dictionary_project\venv\Lib\site-packages\rest_framework\views.py", line 509, in dispatch
    response = self.handle_exception(exc)
  File "C:\Users\phara\OneDrive\Desktop\Django_project\dictionary_project\venv\Lib\site-packages\rest_framework\views.py", line 469, in handle_exception
    self.raise_uncaught_exception(exc)
    ~~~~~~~~~~~~~~~~~~~~~~~~~~~~~^^^^^
  File "C:\Users\phara\OneDrive\Desktop\Django_project\dictionary_project\venv\Lib\site-packages\rest_framework\views.py", line 480, in raise_uncaught_exception
    raise exc
  File "C:\Users\phara\OneDrive\Desktop\Django_project\dictionary_project\venv\Lib\site-packages\rest_framework\views.py", line 506, in dispatch
    response = handler(request, *args, **kwargs)
  File "C:\Users\phara\OneDrive\Desktop\Django_project\dictionary_project\venv\Lib\site-packages\drf_yasg\views.py", line 112, in get
    schema = generator.get_schema(request, self.public)
  File "C:\Users\phara\OneDrive\Desktop\Django_project\dictionary_project\venv\Lib\site-packages\drf_yasg\generators.py", line 276, in get_schema
    paths, prefix = self.get_paths(endpoints, components, request, public)
                    ~~~~~~~~~~~~~~^^^^^^^^^^^^^^^^^^^^^^^^^^^^^^^^^^^^^^^^
  File "C:\Users\phara\OneDrive\Desktop\Django_project\dictionary_project\venv\Lib\site-packages\drf_yasg\generators.py", line 482, in get_paths
    operation = self.get_operation(view, path, prefix, method, components, request)
  File "C:\Users\phara\OneDrive\Desktop\Django_project\dictionary_project\venv\Lib\site-packages\drf_yasg\generators.py", line 524, in get_operation
    operation = view_inspector.get_operation(operation_keys)
  File "C:\Users\phara\OneDrive\Desktop\Django_project\dictionary_project\venv\Lib\site-packages\drf_yasg\inspectors\view.py", line 32, in get_operation
    body = self.get_request_body_parameters(consumes)
  File "C:\Users\phara\OneDrive\Desktop\Django_project\dictionary_project\venv\Lib\site-packages\drf_yasg\inspectors\view.py", line 71, in get_request_body_parameters
    serializer = self.get_request_serializer()
  File "C:\Users\phara\OneDrive\Desktop\Django_project\dictionary_project\venv\Lib\site-packages\drf_yasg\inspectors\view.py", line 118, in get_request_serializer
    body_override = self._get_request_body_override()
  File "C:\Users\phara\OneDrive\Desktop\Django_project\dictionary_project\venv\Lib\site-packages\drf_yasg\inspectors\view.py", line 104, in _get_request_body_override
    raise SwaggerGenerationError("request_body can only be applied to (" + ','.join(self.body_methods) +
                                 "); are you looking for query_serializer or manual_parameters?")
drf_yasg.errors.SwaggerGenerationError: request_body can only be applied to (PUT,PATCH,POST,DELETE); are you looking for query_serializer or manual_parameters?
"GET /swagger/?name=schema-swagger-ui HTTP/1.1" 500 157325
Internal Server Error: /swagger/
Traceback (most recent call last):
  File "C:\Users\phara\OneDrive\Desktop\Django_project\dictionary_project\venv\Lib\site-packages\django\core\handlers\exception.py", line 55, in inner
    response = get_response(request)
  File "C:\Users\phara\OneDrive\Desktop\Django_project\dictionary_project\venv\Lib\site-packages\django\core\handlers\base.py", line 197, in _get_response
    response = wrapped_callback(request, *callback_args, **callback_kwargs)
  File "C:\Users\phara\OneDrive\Desktop\Django_project\dictionary_project\venv\Lib\site-packages\django\views\decorators\csrf.py", line 65, in _view_wrapper
    return view_func(request, *args, **kwargs)
  File "C:\Users\phara\OneDrive\Desktop\Django_project\dictionary_project\venv\Lib\site-packages\django\views\generic\base.py", line 104, in view
    return self.dispatch(request, *args, **kwargs)
           ~~~~~~~~~~~~~^^^^^^^^^^^^^^^^^^^^^^^^^^
  File "C:\Users\phara\OneDrive\Desktop\Django_project\dictionary_project\venv\Lib\site-packages\rest_framework\views.py", line 509, in dispatch
    response = self.handle_exception(exc)
  File "C:\Users\phara\OneDrive\Desktop\Django_project\dictionary_project\venv\Lib\site-packages\rest_framework\views.py", line 469, in handle_exception
    self.raise_uncaught_exception(exc)
    ~~~~~~~~~~~~~~~~~~~~~~~~~~~~~^^^^^
  File "C:\Users\phara\OneDrive\Desktop\Django_project\dictionary_project\venv\Lib\site-packages\rest_framework\views.py", line 480, in raise_uncaught_exception
    raise exc
  File "C:\Users\phara\OneDrive\Desktop\Django_project\dictionary_project\venv\Lib\site-packages\rest_framework\views.py", line 506, in dispatch
    response = handler(request, *args, **kwargs)
  File "C:\Users\phara\OneDrive\Desktop\Django_project\dictionary_project\venv\Lib\site-packages\drf_yasg\views.py", line 112, in get
    schema = generator.get_schema(request, self.public)
  File "C:\Users\phara\OneDrive\Desktop\Django_project\dictionary_project\venv\Lib\site-packages\drf_yasg\generators.py", line 276, in get_schema
    paths, prefix = self.get_paths(endpoints, components, request, public)
                    ~~~~~~~~~~~~~~^^^^^^^^^^^^^^^^^^^^^^^^^^^^^^^^^^^^^^^^
  File "C:\Users\phara\OneDrive\Desktop\Django_project\dictionary_project\venv\Lib\site-packages\drf_yasg\generators.py", line 482, in get_paths
    operation = self.get_operation(view, path, prefix, method, components, request)
  File "C:\Users\phara\OneDrive\Desktop\Django_project\dictionary_project\venv\Lib\site-packages\drf_yasg\generators.py", line 524, in get_operation
    operation = view_inspector.get_operation(operation_keys)
  File "C:\Users\phara\OneDrive\Desktop\Django_project\dictionary_project\venv\Lib\site-packages\drf_yasg\inspectors\view.py", line 32, in get_operation
    body = self.get_request_body_parameters(consumes)
  File "C:\Users\phara\OneDrive\Desktop\Django_project\dictionary_project\venv\Lib\site-packages\drf_yasg\inspectors\view.py", line 71, in get_request_body_parameters
    serializer = self.get_request_serializer()
  File "C:\Users\phara\OneDrive\Desktop\Django_project\dictionary_project\venv\Lib\site-packages\drf_yasg\inspectors\view.py", line 118, in get_request_serializer
    body_override = self._get_request_body_override()
  File "C:\Users\phara\OneDrive\Desktop\Django_project\dictionary_project\venv\Lib\site-packages\drf_yasg\inspectors\view.py", line 104, in _get_request_body_override
    raise SwaggerGenerationError("request_body can only be applied to (" + ','.join(self.body_methods) +
                                 "); are you looking for query_serializer or manual_parameters?")
drf_yasg.errors.SwaggerGenerationError: request_body can only be applied to (PUT,PATCH,POST,DELETE); are you looking for query_serializer or manual_parameters?
"GET /swagger/?format=openapi HTTP/1.1" 500 157200
Internal Server Error: /swagger/
Traceback (most recent call last):
  File "C:\Users\phara\OneDrive\Desktop\Django_project\dictionary_project\venv\Lib\site-packages\django\core\handlers\exception.py", line 55, in inner
    response = get_response(request)
  File "C:\Users\phara\OneDrive\Desktop\Django_project\dictionary_project\venv\Lib\site-packages\django\core\handlers\base.py", line 197, in _get_response
    response = wrapped_callback(request, *callback_args, **callback_kwargs)
  File "C:\Users\phara\OneDrive\Desktop\Django_project\dictionary_project\venv\Lib\site-packages\django\views\decorators\csrf.py", line 65, in _view_wrapper
    return view_func(request, *args, **kwargs)
  File "C:\Users\phara\OneDrive\Desktop\Django_project\dictionary_project\venv\Lib\site-packages\django\views\generic\base.py", line 104, in view
    return self.dispatch(request, *args, **kwargs)
           ~~~~~~~~~~~~~^^^^^^^^^^^^^^^^^^^^^^^^^^
  File "C:\Users\phara\OneDrive\Desktop\Django_project\dictionary_project\venv\Lib\site-packages\rest_framework\views.py", line 509, in dispatch
    response = self.handle_exception(exc)
  File "C:\Users\phara\OneDrive\Desktop\Django_project\dictionary_project\venv\Lib\site-packages\rest_framework\views.py", line 469, in handle_exception
    self.raise_uncaught_exception(exc)
    ~~~~~~~~~~~~~~~~~~~~~~~~~~~~~^^^^^
  File "C:\Users\phara\OneDrive\Desktop\Django_project\dictionary_project\venv\Lib\site-packages\rest_framework\views.py", line 480, in raise_uncaught_exception
    raise exc
  File "C:\Users\phara\OneDrive\Desktop\Django_project\dictionary_project\venv\Lib\site-packages\rest_framework\views.py", line 506, in dispatch
    response = handler(request, *args, **kwargs)
  File "C:\Users\phara\OneDrive\Desktop\Django_project\dictionary_project\venv\Lib\site-packages\drf_yasg\views.py", line 112, in get
    schema = generator.get_schema(request, self.public)
  File "C:\Users\phara\OneDrive\Desktop\Django_project\dictionary_project\venv\Lib\site-packages\drf_yasg\generators.py", line 276, in get_schema
    paths, prefix = self.get_paths(endpoints, components, request, public)
                    ~~~~~~~~~~~~~~^^^^^^^^^^^^^^^^^^^^^^^^^^^^^^^^^^^^^^^^
  File "C:\Users\phara\OneDrive\Desktop\Django_project\dictionary_project\venv\Lib\site-packages\drf_yasg\generators.py", line 482, in get_paths
    operation = self.get_operation(view, path, prefix, method, components, request)
  File "C:\Users\phara\OneDrive\Desktop\Django_project\dictionary_project\venv\Lib\site-packages\drf_yasg\generators.py", line 524, in get_operation
    operation = view_inspector.get_operation(operation_keys)
  File "C:\Users\phara\OneDrive\Desktop\Django_project\dictionary_project\venv\Lib\site-packages\drf_yasg\inspectors\view.py", line 32, in get_operation
    body = self.get_request_body_parameters(consumes)
  File "C:\Users\phara\OneDrive\Desktop\Django_project\dictionary_project\venv\Lib\site-packages\drf_yasg\inspectors\view.py", line 71, in get_request_body_parameters
    serializer = self.get_request_serializer()
  File "C:\Users\phara\OneDrive\Desktop\Django_project\dictionary_project\venv\Lib\site-packages\drf_yasg\inspectors\view.py", line 118, in get_request_serializer
    body_override = self._get_request_body_override()
  File "C:\Users\phara\OneDrive\Desktop\Django_project\dictionary_project\venv\Lib\site-packages\drf_yasg\inspectors\view.py", line 104, in _get_request_body_override
    raise SwaggerGenerationError("request_body can only be applied to (" + ','.join(self.body_methods) +
                                 "); are you looking for query_serializer or manual_parameters?")
drf_yasg.errors.SwaggerGenerationError: request_body can only be applied to (PUT,PATCH,POST,DELETE); are you looking for query_serializer or manual_parameters?
"GET /swagger/?format=openapi HTTP/1.1" 500 157200
Internal Server Error: /api/token/
Traceback (most recent call last):
  File "C:\Users\phara\OneDrive\Desktop\Django_project\dictionary_project\venv\Lib\site-packages\django\core\handlers\exception.py", line 55, in inner
    response = get_response(request)
  File "C:\Users\phara\OneDrive\Desktop\Django_project\dictionary_project\venv\Lib\site-packages\django\core\handlers\base.py", line 197, in _get_response
    response = wrapped_callback(request, *callback_args, **callback_kwargs)
  File "C:\Users\phara\OneDrive\Desktop\Django_project\dictionary_project\venv\Lib\site-packages\django\views\decorators\csrf.py", line 65, in _view_wrapper
    return view_func(request, *args, **kwargs)
  File "C:\Users\phara\OneDrive\Desktop\Django_project\dictionary_project\venv\Lib\site-packages\django\views\generic\base.py", line 104, in view
    return self.dispatch(request, *args, **kwargs)
           ~~~~~~~~~~~~~^^^^^^^^^^^^^^^^^^^^^^^^^^
  File "C:\Users\phara\OneDrive\Desktop\Django_project\dictionary_project\venv\Lib\site-packages\rest_framework\views.py", line 509, in dispatch
    response = self.handle_exception(exc)
  File "C:\Users\phara\OneDrive\Desktop\Django_project\dictionary_project\venv\Lib\site-packages\rest_framework\views.py", line 469, in handle_exception
    self.raise_uncaught_exception(exc)
    ~~~~~~~~~~~~~~~~~~~~~~~~~~~~~^^^^^
  File "C:\Users\phara\OneDrive\Desktop\Django_project\dictionary_project\venv\Lib\site-packages\rest_framework\views.py", line 480, in raise_uncaught_exception
    raise exc
  File "C:\Users\phara\OneDrive\Desktop\Django_project\dictionary_project\venv\Lib\site-packages\rest_framework\views.py", line 506, in dispatch
    response = handler(request, *args, **kwargs)
  File "C:\Users\phara\OneDrive\Desktop\Django_project\dictionary_project\venv\Lib\site-packages\rest_framework_simplejwt\views.py", line 41, in post
    serializer = self.get_serializer(data=request.data)
  File "C:\Users\phara\OneDrive\Desktop\Django_project\dictionary_project\venv\Lib\site-packages\rest_framework\generics.py", line 114, in get_serializer
    return serializer_class(*args, **kwargs)
  File "C:\Users\phara\OneDrive\Desktop\Django_project\dictionary_project\users\views.py", line 511, in __init__
    self.fields.pop('username')
    ~~~~~~~~~~~~~~~^^^^^^^^^^^^
  File "<frozen _collections_abc>", line 950, in pop
  File "C:\Users\phara\OneDrive\Desktop\Django_project\dictionary_project\venv\Lib\site-packages\rest_framework\utils\serializer_helpers.py", line 170, in __getitem__
    return self.fields[key]
           ~~~~~~~~~~~^^^^^
KeyError: 'username'
"POST /api/token/ HTTP/1.1" 500 114593
Internal Server Error: /swagger/
Traceback (most recent call last):
  File "C:\Users\phara\OneDrive\Desktop\Django_project\dictionary_project\venv\Lib\site-packages\django\core\handlers\exception.py", line 55, in inner
    response = get_response(request)
  File "C:\Users\phara\OneDrive\Desktop\Django_project\dictionary_project\venv\Lib\site-packages\django\core\handlers\base.py", line 197, in _get_response
    response = wrapped_callback(request, *callback_args, **callback_kwargs)
  File "C:\Users\phara\OneDrive\Desktop\Django_project\dictionary_project\venv\Lib\site-packages\django\views\decorators\csrf.py", line 65, in _view_wrapper
    return view_func(request, *args, **kwargs)
  File "C:\Users\phara\OneDrive\Desktop\Django_project\dictionary_project\venv\Lib\site-packages\django\views\generic\base.py", line 104, in view
    return self.dispatch(request, *args, **kwargs)
           ~~~~~~~~~~~~~^^^^^^^^^^^^^^^^^^^^^^^^^^
  File "C:\Users\phara\OneDrive\Desktop\Django_project\dictionary_project\venv\Lib\site-packages\rest_framework\views.py", line 509, in dispatch
    response = self.handle_exception(exc)
  File "C:\Users\phara\OneDrive\Desktop\Django_project\dictionary_project\venv\Lib\site-packages\rest_framework\views.py", line 469, in handle_exception
    self.raise_uncaught_exception(exc)
    ~~~~~~~~~~~~~~~~~~~~~~~~~~~~~^^^^^
  File "C:\Users\phara\OneDrive\Desktop\Django_project\dictionary_project\venv\Lib\site-packages\rest_framework\views.py", line 480, in raise_uncaught_exception
    raise exc
  File "C:\Users\phara\OneDrive\Desktop\Django_project\dictionary_project\venv\Lib\site-packages\rest_framework\views.py", line 506, in dispatch
    response = handler(request, *args, **kwargs)
  File "C:\Users\phara\OneDrive\Desktop\Django_project\dictionary_project\venv\Lib\site-packages\drf_yasg\views.py", line 112, in get
    schema = generator.get_schema(request, self.public)
  File "C:\Users\phara\OneDrive\Desktop\Django_project\dictionary_project\venv\Lib\site-packages\drf_yasg\generators.py", line 276, in get_schema
    paths, prefix = self.get_paths(endpoints, components, request, public)
                    ~~~~~~~~~~~~~~^^^^^^^^^^^^^^^^^^^^^^^^^^^^^^^^^^^^^^^^
  File "C:\Users\phara\OneDrive\Desktop\Django_project\dictionary_project\venv\Lib\site-packages\drf_yasg\generators.py", line 482, in get_paths
    operation = self.get_operation(view, path, prefix, method, components, request)
  File "C:\Users\phara\OneDrive\Desktop\Django_project\dictionary_project\venv\Lib\site-packages\drf_yasg\generators.py", line 524, in get_operation
    operation = view_inspector.get_operation(operation_keys)
  File "C:\Users\phara\OneDrive\Desktop\Django_project\dictionary_project\venv\Lib\site-packages\drf_yasg\inspectors\view.py", line 32, in get_operation
    body = self.get_request_body_parameters(consumes)
  File "C:\Users\phara\OneDrive\Desktop\Django_project\dictionary_project\venv\Lib\site-packages\drf_yasg\inspectors\view.py", line 71, in get_request_body_parameters
    serializer = self.get_request_serializer()
  File "C:\Users\phara\OneDrive\Desktop\Django_project\dictionary_project\venv\Lib\site-packages\drf_yasg\inspectors\view.py", line 118, in get_request_serializer
    body_override = self._get_request_body_override()
  File "C:\Users\phara\OneDrive\Desktop\Django_project\dictionary_project\venv\Lib\site-packages\drf_yasg\inspectors\view.py", line 104, in _get_request_body_override
    raise SwaggerGenerationError("request_body can only be applied to (" + ','.join(self.body_methods) +
                                 "); are you looking for query_serializer or manual_parameters?")
drf_yasg.errors.SwaggerGenerationError: request_body can only be applied to (PUT,PATCH,POST,DELETE); are you looking for query_serializer or manual_parameters?
"GET /swagger/?format=openapi HTTP/1.1" 500 157710
Internal Server Error: /api/token/
Traceback (most recent call last):
  File "C:\Users\phara\OneDrive\Desktop\Django_project\dictionary_project\venv\Lib\site-packages\django\core\handlers\exception.py", line 55, in inner
    response = get_response(request)
  File "C:\Users\phara\OneDrive\Desktop\Django_project\dictionary_project\venv\Lib\site-packages\django\core\handlers\base.py", line 197, in _get_response
    response = wrapped_callback(request, *callback_args, **callback_kwargs)
  File "C:\Users\phara\OneDrive\Desktop\Django_project\dictionary_project\venv\Lib\site-packages\django\views\decorators\csrf.py", line 65, in _view_wrapper
    return view_func(request, *args, **kwargs)
  File "C:\Users\phara\OneDrive\Desktop\Django_project\dictionary_project\venv\Lib\site-packages\django\views\generic\base.py", line 104, in view
    return self.dispatch(request, *args, **kwargs)
           ~~~~~~~~~~~~~^^^^^^^^^^^^^^^^^^^^^^^^^^
  File "C:\Users\phara\OneDrive\Desktop\Django_project\dictionary_project\venv\Lib\site-packages\rest_framework\views.py", line 509, in dispatch
    response = self.handle_exception(exc)
  File "C:\Users\phara\OneDrive\Desktop\Django_project\dictionary_project\venv\Lib\site-packages\rest_framework\views.py", line 469, in handle_exception
    self.raise_uncaught_exception(exc)
    ~~~~~~~~~~~~~~~~~~~~~~~~~~~~~^^^^^
  File "C:\Users\phara\OneDrive\Desktop\Django_project\dictionary_project\venv\Lib\site-packages\rest_framework\views.py", line 480, in raise_uncaught_exception
    raise exc
  File "C:\Users\phara\OneDrive\Desktop\Django_project\dictionary_project\venv\Lib\site-packages\rest_framework\views.py", line 506, in dispatch
    response = handler(request, *args, **kwargs)
  File "C:\Users\phara\OneDrive\Desktop\Django_project\dictionary_project\venv\Lib\site-packages\rest_framework_simplejwt\views.py", line 41, in post
    serializer = self.get_serializer(data=request.data)
  File "C:\Users\phara\OneDrive\Desktop\Django_project\dictionary_project\venv\Lib\site-packages\rest_framework\generics.py", line 114, in get_serializer
    return serializer_class(*args, **kwargs)
  File "C:\Users\phara\OneDrive\Desktop\Django_project\dictionary_project\users\views.py", line 511, in __init__
    self.fields.pop('username')
    ~~~~~~~~~~~~~~~^^^^^^^^^^^^
  File "<frozen _collections_abc>", line 950, in pop
  File "C:\Users\phara\OneDrive\Desktop\Django_project\dictionary_project\venv\Lib\site-packages\rest_framework\utils\serializer_helpers.py", line 170, in __getitem__
    return self.fields[key]
           ~~~~~~~~~~~^^^^^
KeyError: 'username'
"POST /api/token/ HTTP/1.1" 500 114602
Internal Server Error: /api/token/
Traceback (most recent call last):
  File "C:\Users\phara\OneDrive\Desktop\Django_project\dictionary_project\venv\Lib\site-packages\django\core\handlers\exception.py", line 55, in inner
    response = get_response(request)
  File "C:\Users\phara\OneDrive\Desktop\Django_project\dictionary_project\venv\Lib\site-packages\django\core\handlers\base.py", line 197, in _get_response
    response = wrapped_callback(request, *callback_args, **callback_kwargs)
  File "C:\Users\phara\OneDrive\Desktop\Django_project\dictionary_project\venv\Lib\site-packages\django\views\decorators\csrf.py", line 65, in _view_wrapper
    return view_func(request, *args, **kwargs)
  File "C:\Users\phara\OneDrive\Desktop\Django_project\dictionary_project\venv\Lib\site-packages\django\views\generic\base.py", line 104, in view
    return self.dispatch(request, *args, **kwargs)
           ~~~~~~~~~~~~~^^^^^^^^^^^^^^^^^^^^^^^^^^
  File "C:\Users\phara\OneDrive\Desktop\Django_project\dictionary_project\venv\Lib\site-packages\rest_framework\views.py", line 509, in dispatch
    response = self.handle_exception(exc)
  File "C:\Users\phara\OneDrive\Desktop\Django_project\dictionary_project\venv\Lib\site-packages\rest_framework\views.py", line 469, in handle_exception
    self.raise_uncaught_exception(exc)
    ~~~~~~~~~~~~~~~~~~~~~~~~~~~~~^^^^^
  File "C:\Users\phara\OneDrive\Desktop\Django_project\dictionary_project\venv\Lib\site-packages\rest_framework\views.py", line 480, in raise_uncaught_exception
    raise exc
  File "C:\Users\phara\OneDrive\Desktop\Django_project\dictionary_project\venv\Lib\site-packages\rest_framework\views.py", line 506, in dispatch
    response = handler(request, *args, **kwargs)
  File "C:\Users\phara\OneDrive\Desktop\Django_project\dictionary_project\venv\Lib\site-packages\rest_framework_simplejwt\views.py", line 41, in post
    serializer = self.get_serializer(data=request.data)
  File "C:\Users\phara\OneDrive\Desktop\Django_project\dictionary_project\venv\Lib\site-packages\rest_framework\generics.py", line 114, in get_serializer
    return serializer_class(*args, **kwargs)
  File "C:\Users\phara\OneDrive\Desktop\Django_project\dictionary_project\users\views.py", line 533, in __init__
    self.fields.pop('username')
    ~~~~~~~~~~~~~~~^^^^^^^^^^^^
  File "<frozen _collections_abc>", line 950, in pop
  File "C:\Users\phara\OneDrive\Desktop\Django_project\dictionary_project\venv\Lib\site-packages\rest_framework\utils\serializer_helpers.py", line 170, in __getitem__
    return self.fields[key]
           ~~~~~~~~~~~^^^^^
KeyError: 'username'
"POST /api/token/ HTTP/1.1" 500 114566
Internal Server Error: /swagger/
Traceback (most recent call last):
  File "C:\Users\phara\OneDrive\Desktop\Django_project\dictionary_project\venv\Lib\site-packages\django\core\handlers\exception.py", line 55, in inner
    response = get_response(request)
  File "C:\Users\phara\OneDrive\Desktop\Django_project\dictionary_project\venv\Lib\site-packages\django\core\handlers\base.py", line 197, in _get_response
    response = wrapped_callback(request, *callback_args, **callback_kwargs)
  File "C:\Users\phara\OneDrive\Desktop\Django_project\dictionary_project\venv\Lib\site-packages\django\views\decorators\csrf.py", line 65, in _view_wrapper
    return view_func(request, *args, **kwargs)
  File "C:\Users\phara\OneDrive\Desktop\Django_project\dictionary_project\venv\Lib\site-packages\django\views\generic\base.py", line 104, in view
    return self.dispatch(request, *args, **kwargs)
           ~~~~~~~~~~~~~^^^^^^^^^^^^^^^^^^^^^^^^^^
  File "C:\Users\phara\OneDrive\Desktop\Django_project\dictionary_project\venv\Lib\site-packages\rest_framework\views.py", line 509, in dispatch
    response = self.handle_exception(exc)
  File "C:\Users\phara\OneDrive\Desktop\Django_project\dictionary_project\venv\Lib\site-packages\rest_framework\views.py", line 469, in handle_exception
    self.raise_uncaught_exception(exc)
    ~~~~~~~~~~~~~~~~~~~~~~~~~~~~~^^^^^
  File "C:\Users\phara\OneDrive\Desktop\Django_project\dictionary_project\venv\Lib\site-packages\rest_framework\views.py", line 480, in raise_uncaught_exception
    raise exc
  File "C:\Users\phara\OneDrive\Desktop\Django_project\dictionary_project\venv\Lib\site-packages\rest_framework\views.py", line 506, in dispatch
    response = handler(request, *args, **kwargs)
  File "C:\Users\phara\OneDrive\Desktop\Django_project\dictionary_project\venv\Lib\site-packages\drf_yasg\views.py", line 112, in get
    schema = generator.get_schema(request, self.public)
  File "C:\Users\phara\OneDrive\Desktop\Django_project\dictionary_project\venv\Lib\site-packages\drf_yasg\generators.py", line 276, in get_schema
    paths, prefix = self.get_paths(endpoints, components, request, public)
                    ~~~~~~~~~~~~~~^^^^^^^^^^^^^^^^^^^^^^^^^^^^^^^^^^^^^^^^
  File "C:\Users\phara\OneDrive\Desktop\Django_project\dictionary_project\venv\Lib\site-packages\drf_yasg\generators.py", line 482, in get_paths
    operation = self.get_operation(view, path, prefix, method, components, request)
  File "C:\Users\phara\OneDrive\Desktop\Django_project\dictionary_project\venv\Lib\site-packages\drf_yasg\generators.py", line 524, in get_operation
    operation = view_inspector.get_operation(operation_keys)
  File "C:\Users\phara\OneDrive\Desktop\Django_project\dictionary_project\venv\Lib\site-packages\drf_yasg\inspectors\view.py", line 32, in get_operation
    body = self.get_request_body_parameters(consumes)
  File "C:\Users\phara\OneDrive\Desktop\Django_project\dictionary_project\venv\Lib\site-packages\drf_yasg\inspectors\view.py", line 71, in get_request_body_parameters
    serializer = self.get_request_serializer()
  File "C:\Users\phara\OneDrive\Desktop\Django_project\dictionary_project\venv\Lib\site-packages\drf_yasg\inspectors\view.py", line 118, in get_request_serializer
    body_override = self._get_request_body_override()
  File "C:\Users\phara\OneDrive\Desktop\Django_project\dictionary_project\venv\Lib\site-packages\drf_yasg\inspectors\view.py", line 104, in _get_request_body_override
    raise SwaggerGenerationError("request_body can only be applied to (" + ','.join(self.body_methods) +
                                 "); are you looking for query_serializer or manual_parameters?")
drf_yasg.errors.SwaggerGenerationError: request_body can only be applied to (PUT,PATCH,POST,DELETE); are you looking for query_serializer or manual_parameters?
"GET /swagger/?format=openapi HTTP/1.1" 500 157710
Internal Server Error: /swagger/
Traceback (most recent call last):
  File "C:\Users\phara\OneDrive\Desktop\Django_project\dictionary_project\venv\Lib\site-packages\django\core\handlers\exception.py", line 55, in inner
    response = get_response(request)
  File "C:\Users\phara\OneDrive\Desktop\Django_project\dictionary_project\venv\Lib\site-packages\django\core\handlers\base.py", line 197, in _get_response
    response = wrapped_callback(request, *callback_args, **callback_kwargs)
  File "C:\Users\phara\OneDrive\Desktop\Django_project\dictionary_project\venv\Lib\site-packages\django\views\decorators\csrf.py", line 65, in _view_wrapper
    return view_func(request, *args, **kwargs)
  File "C:\Users\phara\OneDrive\Desktop\Django_project\dictionary_project\venv\Lib\site-packages\django\views\generic\base.py", line 104, in view
    return self.dispatch(request, *args, **kwargs)
           ~~~~~~~~~~~~~^^^^^^^^^^^^^^^^^^^^^^^^^^
  File "C:\Users\phara\OneDrive\Desktop\Django_project\dictionary_project\venv\Lib\site-packages\rest_framework\views.py", line 509, in dispatch
    response = self.handle_exception(exc)
  File "C:\Users\phara\OneDrive\Desktop\Django_project\dictionary_project\venv\Lib\site-packages\rest_framework\views.py", line 469, in handle_exception
    self.raise_uncaught_exception(exc)
    ~~~~~~~~~~~~~~~~~~~~~~~~~~~~~^^^^^
  File "C:\Users\phara\OneDrive\Desktop\Django_project\dictionary_project\venv\Lib\site-packages\rest_framework\views.py", line 480, in raise_uncaught_exception
    raise exc
  File "C:\Users\phara\OneDrive\Desktop\Django_project\dictionary_project\venv\Lib\site-packages\rest_framework\views.py", line 506, in dispatch
    response = handler(request, *args, **kwargs)
  File "C:\Users\phara\OneDrive\Desktop\Django_project\dictionary_project\venv\Lib\site-packages\drf_yasg\views.py", line 112, in get
    schema = generator.get_schema(request, self.public)
  File "C:\Users\phara\OneDrive\Desktop\Django_project\dictionary_project\venv\Lib\site-packages\drf_yasg\generators.py", line 276, in get_schema
    paths, prefix = self.get_paths(endpoints, components, request, public)
                    ~~~~~~~~~~~~~~^^^^^^^^^^^^^^^^^^^^^^^^^^^^^^^^^^^^^^^^
  File "C:\Users\phara\OneDrive\Desktop\Django_project\dictionary_project\venv\Lib\site-packages\drf_yasg\generators.py", line 482, in get_paths
    operation = self.get_operation(view, path, prefix, method, components, request)
  File "C:\Users\phara\OneDrive\Desktop\Django_project\dictionary_project\venv\Lib\site-packages\drf_yasg\generators.py", line 524, in get_operation
    operation = view_inspector.get_operation(operation_keys)
  File "C:\Users\phara\OneDrive\Desktop\Django_project\dictionary_project\venv\Lib\site-packages\drf_yasg\inspectors\view.py", line 32, in get_operation
    body = self.get_request_body_parameters(consumes)
  File "C:\Users\phara\OneDrive\Desktop\Django_project\dictionary_project\venv\Lib\site-packages\drf_yasg\inspectors\view.py", line 71, in get_request_body_parameters
    serializer = self.get_request_serializer()
  File "C:\Users\phara\OneDrive\Desktop\Django_project\dictionary_project\venv\Lib\site-packages\drf_yasg\inspectors\view.py", line 118, in get_request_serializer
    body_override = self._get_request_body_override()
  File "C:\Users\phara\OneDrive\Desktop\Django_project\dictionary_project\venv\Lib\site-packages\drf_yasg\inspectors\view.py", line 104, in _get_request_body_override
    raise SwaggerGenerationError("request_body can only be applied to (" + ','.join(self.body_methods) +
                                 "); are you looking for query_serializer or manual_parameters?")
drf_yasg.errors.SwaggerGenerationError: request_body can only be applied to (PUT,PATCH,POST,DELETE); are you looking for query_serializer or manual_parameters?
"GET /swagger/?format=openapi HTTP/1.1" 500 157905
Internal Server Error: /redoc/
Traceback (most recent call last):
  File "C:\Users\phara\OneDrive\Desktop\Django_project\dictionary_project\venv\Lib\site-packages\django\core\handlers\exception.py", line 55, in inner
    response = get_response(request)
  File "C:\Users\phara\OneDrive\Desktop\Django_project\dictionary_project\venv\Lib\site-packages\django\core\handlers\base.py", line 197, in _get_response
    response = wrapped_callback(request, *callback_args, **callback_kwargs)
  File "C:\Users\phara\OneDrive\Desktop\Django_project\dictionary_project\venv\Lib\site-packages\django\views\decorators\csrf.py", line 65, in _view_wrapper
    return view_func(request, *args, **kwargs)
  File "C:\Users\phara\OneDrive\Desktop\Django_project\dictionary_project\venv\Lib\site-packages\django\views\generic\base.py", line 104, in view
    return self.dispatch(request, *args, **kwargs)
           ~~~~~~~~~~~~~^^^^^^^^^^^^^^^^^^^^^^^^^^
  File "C:\Users\phara\OneDrive\Desktop\Django_project\dictionary_project\venv\Lib\site-packages\rest_framework\views.py", line 509, in dispatch
    response = self.handle_exception(exc)
  File "C:\Users\phara\OneDrive\Desktop\Django_project\dictionary_project\venv\Lib\site-packages\rest_framework\views.py", line 469, in handle_exception
    self.raise_uncaught_exception(exc)
    ~~~~~~~~~~~~~~~~~~~~~~~~~~~~~^^^^^
  File "C:\Users\phara\OneDrive\Desktop\Django_project\dictionary_project\venv\Lib\site-packages\rest_framework\views.py", line 480, in raise_uncaught_exception
    raise exc
  File "C:\Users\phara\OneDrive\Desktop\Django_project\dictionary_project\venv\Lib\site-packages\rest_framework\views.py", line 506, in dispatch
    response = handler(request, *args, **kwargs)
  File "C:\Users\phara\OneDrive\Desktop\Django_project\dictionary_project\venv\Lib\site-packages\drf_yasg\views.py", line 112, in get
    schema = generator.get_schema(request, self.public)
  File "C:\Users\phara\OneDrive\Desktop\Django_project\dictionary_project\venv\Lib\site-packages\drf_yasg\generators.py", line 276, in get_schema
    paths, prefix = self.get_paths(endpoints, components, request, public)
                    ~~~~~~~~~~~~~~^^^^^^^^^^^^^^^^^^^^^^^^^^^^^^^^^^^^^^^^
  File "C:\Users\phara\OneDrive\Desktop\Django_project\dictionary_project\venv\Lib\site-packages\drf_yasg\generators.py", line 482, in get_paths
    operation = self.get_operation(view, path, prefix, method, components, request)
  File "C:\Users\phara\OneDrive\Desktop\Django_project\dictionary_project\venv\Lib\site-packages\drf_yasg\generators.py", line 524, in get_operation
    operation = view_inspector.get_operation(operation_keys)
  File "C:\Users\phara\OneDrive\Desktop\Django_project\dictionary_project\venv\Lib\site-packages\drf_yasg\inspectors\view.py", line 32, in get_operation
    body = self.get_request_body_parameters(consumes)
  File "C:\Users\phara\OneDrive\Desktop\Django_project\dictionary_project\venv\Lib\site-packages\drf_yasg\inspectors\view.py", line 71, in get_request_body_parameters
    serializer = self.get_request_serializer()
  File "C:\Users\phara\OneDrive\Desktop\Django_project\dictionary_project\venv\Lib\site-packages\drf_yasg\inspectors\view.py", line 118, in get_request_serializer
    body_override = self._get_request_body_override()
  File "C:\Users\phara\OneDrive\Desktop\Django_project\dictionary_project\venv\Lib\site-packages\drf_yasg\inspectors\view.py", line 104, in _get_request_body_override
    raise SwaggerGenerationError("request_body can only be applied to (" + ','.join(self.body_methods) +
                                 "); are you looking for query_serializer or manual_parameters?")
drf_yasg.errors.SwaggerGenerationError: request_body can only be applied to (PUT,PATCH,POST,DELETE); are you looking for query_serializer or manual_parameters?
"GET /redoc/?format=openapi HTTP/1.1" 500 157702
Internal Server Error: /swagger/
Traceback (most recent call last):
  File "C:\Users\phara\OneDrive\Desktop\Django_project\dictionary_project\venv\Lib\site-packages\django\core\handlers\exception.py", line 55, in inner
    response = get_response(request)
  File "C:\Users\phara\OneDrive\Desktop\Django_project\dictionary_project\venv\Lib\site-packages\django\core\handlers\base.py", line 197, in _get_response
    response = wrapped_callback(request, *callback_args, **callback_kwargs)
  File "C:\Users\phara\OneDrive\Desktop\Django_project\dictionary_project\venv\Lib\site-packages\django\views\decorators\csrf.py", line 65, in _view_wrapper
    return view_func(request, *args, **kwargs)
  File "C:\Users\phara\OneDrive\Desktop\Django_project\dictionary_project\venv\Lib\site-packages\django\views\generic\base.py", line 104, in view
    return self.dispatch(request, *args, **kwargs)
           ~~~~~~~~~~~~~^^^^^^^^^^^^^^^^^^^^^^^^^^
  File "C:\Users\phara\OneDrive\Desktop\Django_project\dictionary_project\venv\Lib\site-packages\rest_framework\views.py", line 509, in dispatch
    response = self.handle_exception(exc)
  File "C:\Users\phara\OneDrive\Desktop\Django_project\dictionary_project\venv\Lib\site-packages\rest_framework\views.py", line 469, in handle_exception
    self.raise_uncaught_exception(exc)
    ~~~~~~~~~~~~~~~~~~~~~~~~~~~~~^^^^^
  File "C:\Users\phara\OneDrive\Desktop\Django_project\dictionary_project\venv\Lib\site-packages\rest_framework\views.py", line 480, in raise_uncaught_exception
    raise exc
  File "C:\Users\phara\OneDrive\Desktop\Django_project\dictionary_project\venv\Lib\site-packages\rest_framework\views.py", line 506, in dispatch
    response = handler(request, *args, **kwargs)
  File "C:\Users\phara\OneDrive\Desktop\Django_project\dictionary_project\venv\Lib\site-packages\drf_yasg\views.py", line 112, in get
    schema = generator.get_schema(request, self.public)
  File "C:\Users\phara\OneDrive\Desktop\Django_project\dictionary_project\venv\Lib\site-packages\drf_yasg\generators.py", line 276, in get_schema
    paths, prefix = self.get_paths(endpoints, components, request, public)
                    ~~~~~~~~~~~~~~^^^^^^^^^^^^^^^^^^^^^^^^^^^^^^^^^^^^^^^^
  File "C:\Users\phara\OneDrive\Desktop\Django_project\dictionary_project\venv\Lib\site-packages\drf_yasg\generators.py", line 482, in get_paths
    operation = self.get_operation(view, path, prefix, method, components, request)
  File "C:\Users\phara\OneDrive\Desktop\Django_project\dictionary_project\venv\Lib\site-packages\drf_yasg\generators.py", line 524, in get_operation
    operation = view_inspector.get_operation(operation_keys)
  File "C:\Users\phara\OneDrive\Desktop\Django_project\dictionary_project\venv\Lib\site-packages\drf_yasg\inspectors\view.py", line 32, in get_operation
    body = self.get_request_body_parameters(consumes)
  File "C:\Users\phara\OneDrive\Desktop\Django_project\dictionary_project\venv\Lib\site-packages\drf_yasg\inspectors\view.py", line 71, in get_request_body_parameters
    serializer = self.get_request_serializer()
  File "C:\Users\phara\OneDrive\Desktop\Django_project\dictionary_project\venv\Lib\site-packages\drf_yasg\inspectors\view.py", line 118, in get_request_serializer
    body_override = self._get_request_body_override()
  File "C:\Users\phara\OneDrive\Desktop\Django_project\dictionary_project\venv\Lib\site-packages\drf_yasg\inspectors\view.py", line 104, in _get_request_body_override
    raise SwaggerGenerationError("request_body can only be applied to (" + ','.join(self.body_methods) +
                                 "); are you looking for query_serializer or manual_parameters?")
drf_yasg.errors.SwaggerGenerationError: request_body can only be applied to (PUT,PATCH,POST,DELETE); are you looking for query_serializer or manual_parameters?
"GET /swagger/?format=openapi HTTP/1.1" 500 157983
Internal Server Error: /swagger/
Traceback (most recent call last):
  File "C:\Users\phara\OneDrive\Desktop\Django_project\dictionary_project\venv\Lib\site-packages\django\core\handlers\exception.py", line 55, in inner
    response = get_response(request)
  File "C:\Users\phara\OneDrive\Desktop\Django_project\dictionary_project\venv\Lib\site-packages\django\core\handlers\base.py", line 197, in _get_response
    response = wrapped_callback(request, *callback_args, **callback_kwargs)
  File "C:\Users\phara\OneDrive\Desktop\Django_project\dictionary_project\venv\Lib\site-packages\django\views\decorators\csrf.py", line 65, in _view_wrapper
    return view_func(request, *args, **kwargs)
  File "C:\Users\phara\OneDrive\Desktop\Django_project\dictionary_project\venv\Lib\site-packages\django\views\generic\base.py", line 104, in view
    return self.dispatch(request, *args, **kwargs)
           ~~~~~~~~~~~~~^^^^^^^^^^^^^^^^^^^^^^^^^^
  File "C:\Users\phara\OneDrive\Desktop\Django_project\dictionary_project\venv\Lib\site-packages\rest_framework\views.py", line 509, in dispatch
    response = self.handle_exception(exc)
  File "C:\Users\phara\OneDrive\Desktop\Django_project\dictionary_project\venv\Lib\site-packages\rest_framework\views.py", line 469, in handle_exception
    self.raise_uncaught_exception(exc)
    ~~~~~~~~~~~~~~~~~~~~~~~~~~~~~^^^^^
  File "C:\Users\phara\OneDrive\Desktop\Django_project\dictionary_project\venv\Lib\site-packages\rest_framework\views.py", line 480, in raise_uncaught_exception
    raise exc
  File "C:\Users\phara\OneDrive\Desktop\Django_project\dictionary_project\venv\Lib\site-packages\rest_framework\views.py", line 506, in dispatch
    response = handler(request, *args, **kwargs)
  File "C:\Users\phara\OneDrive\Desktop\Django_project\dictionary_project\venv\Lib\site-packages\drf_yasg\views.py", line 112, in get
    schema = generator.get_schema(request, self.public)
  File "C:\Users\phara\OneDrive\Desktop\Django_project\dictionary_project\venv\Lib\site-packages\drf_yasg\generators.py", line 276, in get_schema
    paths, prefix = self.get_paths(endpoints, components, request, public)
                    ~~~~~~~~~~~~~~^^^^^^^^^^^^^^^^^^^^^^^^^^^^^^^^^^^^^^^^
  File "C:\Users\phara\OneDrive\Desktop\Django_project\dictionary_project\venv\Lib\site-packages\drf_yasg\generators.py", line 482, in get_paths
    operation = self.get_operation(view, path, prefix, method, components, request)
  File "C:\Users\phara\OneDrive\Desktop\Django_project\dictionary_project\venv\Lib\site-packages\drf_yasg\generators.py", line 524, in get_operation
    operation = view_inspector.get_operation(operation_keys)
  File "C:\Users\phara\OneDrive\Desktop\Django_project\dictionary_project\venv\Lib\site-packages\drf_yasg\inspectors\view.py", line 32, in get_operation
    body = self.get_request_body_parameters(consumes)
  File "C:\Users\phara\OneDrive\Desktop\Django_project\dictionary_project\venv\Lib\site-packages\drf_yasg\inspectors\view.py", line 71, in get_request_body_parameters
    serializer = self.get_request_serializer()
  File "C:\Users\phara\OneDrive\Desktop\Django_project\dictionary_project\venv\Lib\site-packages\drf_yasg\inspectors\view.py", line 118, in get_request_serializer
    body_override = self._get_request_body_override()
  File "C:\Users\phara\OneDrive\Desktop\Django_project\dictionary_project\venv\Lib\site-packages\drf_yasg\inspectors\view.py", line 104, in _get_request_body_override
    raise SwaggerGenerationError("request_body can only be applied to (" + ','.join(self.body_methods) +
                                 "); are you looking for query_serializer or manual_parameters?")
drf_yasg.errors.SwaggerGenerationError: request_body can only be applied to (PUT,PATCH,POST,DELETE); are you looking for query_serializer or manual_parameters?
"GET /swagger/?format=openapi HTTP/1.1" 500 157744
Internal Server Error: /swagger/
Traceback (most recent call last):
  File "C:\Users\phara\OneDrive\Desktop\Django_project\dictionary_project\venv\Lib\site-packages\django\core\handlers\exception.py", line 55, in inner
    response = get_response(request)
  File "C:\Users\phara\OneDrive\Desktop\Django_project\dictionary_project\venv\Lib\site-packages\django\core\handlers\base.py", line 197, in _get_response
    response = wrapped_callback(request, *callback_args, **callback_kwargs)
  File "C:\Users\phara\OneDrive\Desktop\Django_project\dictionary_project\venv\Lib\site-packages\django\views\decorators\csrf.py", line 65, in _view_wrapper
    return view_func(request, *args, **kwargs)
  File "C:\Users\phara\OneDrive\Desktop\Django_project\dictionary_project\venv\Lib\site-packages\django\views\generic\base.py", line 104, in view
    return self.dispatch(request, *args, **kwargs)
           ~~~~~~~~~~~~~^^^^^^^^^^^^^^^^^^^^^^^^^^
  File "C:\Users\phara\OneDrive\Desktop\Django_project\dictionary_project\venv\Lib\site-packages\rest_framework\views.py", line 509, in dispatch
    response = self.handle_exception(exc)
  File "C:\Users\phara\OneDrive\Desktop\Django_project\dictionary_project\venv\Lib\site-packages\rest_framework\views.py", line 469, in handle_exception
    self.raise_uncaught_exception(exc)
    ~~~~~~~~~~~~~~~~~~~~~~~~~~~~~^^^^^
  File "C:\Users\phara\OneDrive\Desktop\Django_project\dictionary_project\venv\Lib\site-packages\rest_framework\views.py", line 480, in raise_uncaught_exception
    raise exc
  File "C:\Users\phara\OneDrive\Desktop\Django_project\dictionary_project\venv\Lib\site-packages\rest_framework\views.py", line 506, in dispatch
    response = handler(request, *args, **kwargs)
  File "C:\Users\phara\OneDrive\Desktop\Django_project\dictionary_project\venv\Lib\site-packages\drf_yasg\views.py", line 112, in get
    schema = generator.get_schema(request, self.public)
  File "C:\Users\phara\OneDrive\Desktop\Django_project\dictionary_project\venv\Lib\site-packages\drf_yasg\generators.py", line 276, in get_schema
    paths, prefix = self.get_paths(endpoints, components, request, public)
                    ~~~~~~~~~~~~~~^^^^^^^^^^^^^^^^^^^^^^^^^^^^^^^^^^^^^^^^
  File "C:\Users\phara\OneDrive\Desktop\Django_project\dictionary_project\venv\Lib\site-packages\drf_yasg\generators.py", line 482, in get_paths
    operation = self.get_operation(view, path, prefix, method, components, request)
  File "C:\Users\phara\OneDrive\Desktop\Django_project\dictionary_project\venv\Lib\site-packages\drf_yasg\generators.py", line 524, in get_operation
    operation = view_inspector.get_operation(operation_keys)
  File "C:\Users\phara\OneDrive\Desktop\Django_project\dictionary_project\venv\Lib\site-packages\drf_yasg\inspectors\view.py", line 32, in get_operation
    body = self.get_request_body_parameters(consumes)
  File "C:\Users\phara\OneDrive\Desktop\Django_project\dictionary_project\venv\Lib\site-packages\drf_yasg\inspectors\view.py", line 71, in get_request_body_parameters
    serializer = self.get_request_serializer()
  File "C:\Users\phara\OneDrive\Desktop\Django_project\dictionary_project\venv\Lib\site-packages\drf_yasg\inspectors\view.py", line 118, in get_request_serializer
    body_override = self._get_request_body_override()
  File "C:\Users\phara\OneDrive\Desktop\Django_project\dictionary_project\venv\Lib\site-packages\drf_yasg\inspectors\view.py", line 104, in _get_request_body_override
    raise SwaggerGenerationError("request_body can only be applied to (" + ','.join(self.body_methods) +
                                 "); are you looking for query_serializer or manual_parameters?")
drf_yasg.errors.SwaggerGenerationError: request_body can only be applied to (PUT,PATCH,POST,DELETE); are you looking for query_serializer or manual_parameters?
"GET /swagger/?format=openapi HTTP/1.1" 500 157744
You're accessing the development server over HTTPS, but it only supports HTTP.
You're accessing the development server over HTTPS, but it only supports HTTP.
Internal Server Error: /api/token/blacklist
Traceback (most recent call last):
  File "C:\Users\phara\OneDrive\Desktop\Django_project\dictionary_project\venv\Lib\site-packages\django\core\handlers\exception.py", line 55, in inner
    response = get_response(request)
  File "C:\Users\phara\OneDrive\Desktop\Django_project\dictionary_project\venv\Lib\site-packages\django\utils\deprecation.py", line 131, in __call__
    response = self.process_response(request, response)
  File "C:\Users\phara\OneDrive\Desktop\Django_project\dictionary_project\venv\Lib\site-packages\django\middleware\common.py", line 108, in process_response
    return self.response_redirect_class(self.get_full_path_with_slash(request))
                                        ~~~~~~~~~~~~~~~~~~~~~~~~~~~~~^^^^^^^^^
  File "C:\Users\phara\OneDrive\Desktop\Django_project\dictionary_project\venv\Lib\site-packages\django\middleware\common.py", line 87, in get_full_path_with_slash
    raise RuntimeError(
    ...<9 lines>...
    )
RuntimeError: You called this URL via POST, but the URL doesn't end in a slash and you have APPEND_SLASH set. Django can't redirect to the slash URL while maintaining POST data. Change your form to point to 127.0.0.1:3050/api/token/blacklist/ (note the trailing slash), or set APPEND_SLASH=False in your Django settings.
"POST /api/token/blacklist HTTP/1.1" 500 81305
Internal Server Error: /api/users/mobile/login/
"POST /api/users/mobile/login/ HTTP/1.1" 500 53
Internal Server Error: /swagger/
Traceback (most recent call last):
  File "C:\Users\phara\OneDrive\Desktop\FMIS\python\dictionary_project\venv\Lib\site-packages\django\core\handlers\exception.py", line 55, in inner
    response = get_response(request)
  File "C:\Users\phara\OneDrive\Desktop\FMIS\python\dictionary_project\venv\Lib\site-packages\django\core\handlers\base.py", line 197, in _get_response
    response = wrapped_callback(request, *callback_args, **callback_kwargs)
  File "C:\Users\phara\OneDrive\Desktop\FMIS\python\dictionary_project\venv\Lib\site-packages\django\views\decorators\csrf.py", line 65, in _view_wrapper
    return view_func(request, *args, **kwargs)
  File "C:\Users\phara\OneDrive\Desktop\FMIS\python\dictionary_project\venv\Lib\site-packages\django\views\generic\base.py", line 104, in view
    return self.dispatch(request, *args, **kwargs)
           ~~~~~~~~~~~~~^^^^^^^^^^^^^^^^^^^^^^^^^^
  File "C:\Users\phara\OneDrive\Desktop\FMIS\python\dictionary_project\venv\Lib\site-packages\rest_framework\views.py", line 509, in dispatch
    response = self.handle_exception(exc)
  File "C:\Users\phara\OneDrive\Desktop\FMIS\python\dictionary_project\venv\Lib\site-packages\rest_framework\views.py", line 469, in handle_exception
    self.raise_uncaught_exception(exc)
    ~~~~~~~~~~~~~~~~~~~~~~~~~~~~~^^^^^
  File "C:\Users\phara\OneDrive\Desktop\FMIS\python\dictionary_project\venv\Lib\site-packages\rest_framework\views.py", line 480, in raise_uncaught_exception
    raise exc
  File "C:\Users\phara\OneDrive\Desktop\FMIS\python\dictionary_project\venv\Lib\site-packages\rest_framework\views.py", line 497, in dispatch
    self.initial(request, *args, **kwargs)
    ~~~~~~~~~~~~^^^^^^^^^^^^^^^^^^^^^^^^^^
  File "C:\Users\phara\OneDrive\Desktop\FMIS\python\dictionary_project\venv\Lib\site-packages\rest_framework\views.py", line 416, in initial
    self.check_throttles(request)
    ~~~~~~~~~~~~~~~~~~~~^^^^^^^^^
  File "C:\Users\phara\OneDrive\Desktop\FMIS\python\dictionary_project\venv\Lib\site-packages\rest_framework\views.py", line 359, in check_throttles
    if not throttle.allow_request(request, self):
           ~~~~~~~~~~~~~~~~~~~~~~^^^^^^^^^^^^^^^
  File "C:\Users\phara\OneDrive\Desktop\FMIS\python\dictionary_project\venv\Lib\site-packages\rest_framework\throttling.py", line 123, in allow_request
    self.history = self.cache.get(self.key, [])
                   ~~~~~~~~~~~~~~^^^^^^^^^^^^^^
  File "C:\Users\phara\OneDrive\Desktop\FMIS\python\dictionary_project\venv\Lib\site-packages\django\core\cache\backends\redis.py", line 187, in get
    return self._cache.get(key, default)
           ^^^^^^^^^^^
  File "C:\Users\phara\OneDrive\Desktop\FMIS\python\dictionary_project\venv\Lib\site-packages\django\utils\functional.py", line 47, in __get__
    res = instance.__dict__[self.name] = self.func(instance)
                                         ~~~~~~~~~^^^^^^^^^^
  File "C:\Users\phara\OneDrive\Desktop\FMIS\python\dictionary_project\venv\Lib\site-packages\django\core\cache\backends\redis.py", line 172, in _cache
    return self._class(self._servers, **self._options)
           ~~~~~~~~~~~^^^^^^^^^^^^^^^^^^^^^^^^^^^^^^^^
  File "C:\Users\phara\OneDrive\Desktop\FMIS\python\dictionary_project\venv\Lib\site-packages\django\core\cache\backends\redis.py", line 39, in __init__
    import redis
ModuleNotFoundError: No module named 'redis'
"GET /swagger/ HTTP/1.1" 500 132580
Internal Server Error: /api/users/mobile/login/
Traceback (most recent call last):
  File "C:\Users\phara\OneDrive\Desktop\FMIS\python\dictionary_project\users\views.py", line 594, in post
    user = User.objects.get(username='mobile_default_user')
  File "C:\Users\phara\OneDrive\Desktop\FMIS\python\dictionary_project\venv\Lib\site-packages\django\db\models\manager.py", line 87, in manager_method
    return getattr(self.get_queryset(), name)(*args, **kwargs)
           ~~~~~~~~~~~~~~~~~~~~~~~~~~~~~~~~~~^^^^^^^^^^^^^^^^^
  File "C:\Users\phara\OneDrive\Desktop\FMIS\python\dictionary_project\venv\Lib\site-packages\django\db\models\query.py", line 649, in get
    raise self.model.DoesNotExist(
        "%s matching query does not exist." % self.model._meta.object_name
    )
users.models.User.DoesNotExist: User matching query does not exist.

During handling of the above exception, another exception occurred:

Traceback (most recent call last):
  File "C:\Users\phara\OneDrive\Desktop\FMIS\python\dictionary_project\venv\Lib\site-packages\django\core\handlers\exception.py", line 55, in inner
    response = get_response(request)
  File "C:\Users\phara\OneDrive\Desktop\FMIS\python\dictionary_project\venv\Lib\site-packages\django\core\handlers\base.py", line 197, in _get_response
    response = wrapped_callback(request, *callback_args, **callback_kwargs)
  File "C:\Users\phara\OneDrive\Desktop\FMIS\python\dictionary_project\venv\Lib\site-packages\django\views\decorators\csrf.py", line 65, in _view_wrapper
    return view_func(request, *args, **kwargs)
  File "C:\Users\phara\OneDrive\Desktop\FMIS\python\dictionary_project\venv\Lib\site-packages\django\views\generic\base.py", line 104, in view
    return self.dispatch(request, *args, **kwargs)
           ~~~~~~~~~~~~~^^^^^^^^^^^^^^^^^^^^^^^^^^
  File "C:\Users\phara\OneDrive\Desktop\FMIS\python\dictionary_project\venv\Lib\site-packages\rest_framework\views.py", line 509, in dispatch
    response = self.handle_exception(exc)
  File "C:\Users\phara\OneDrive\Desktop\FMIS\python\dictionary_project\venv\Lib\site-packages\rest_framework\views.py", line 469, in handle_exception
    self.raise_uncaught_exception(exc)
    ~~~~~~~~~~~~~~~~~~~~~~~~~~~~~^^^^^
  File "C:\Users\phara\OneDrive\Desktop\FMIS\python\dictionary_project\venv\Lib\site-packages\rest_framework\views.py", line 480, in raise_uncaught_exception
    raise exc
  File "C:\Users\phara\OneDrive\Desktop\FMIS\python\dictionary_project\venv\Lib\site-packages\rest_framework\views.py", line 506, in dispatch
    response = handler(request, *args, **kwargs)
  File "C:\Users\phara\OneDrive\Desktop\FMIS\python\dictionary_project\users\views.py", line 597, in post
    user = User.objects.create_user(
        username='mobile_default_user',
        email='mobile_default@dictionary.app',
        password='SecureDefaultMobilePassword123!'
    )
  File "C:\Users\phara\OneDrive\Desktop\FMIS\python\dictionary_project\users\models.py", line 21, in create_user
    validate_fmis_email(email)
    ~~~~~~~~~~~~~~~~~~~^^^^^^^
  File "C:\Users\phara\OneDrive\Desktop\FMIS\python\dictionary_project\users\models.py", line 13, in validate_fmis_email
    raise ValidationError('Only FMIS email address is acceptant.')
django.core.exceptions.ValidationError: ['Only FMIS email address is acceptant.']
"POST /api/users/mobile/login/ HTTP/1.1" 500 126398
Internal Server Error: /api/dictionary/staging/4/approve/
Traceback (most recent call last):
  File "C:\Users\phara\OneDrive\Desktop\FMIS\python\dictionary_project\venv\Lib\site-packages\django\core\handlers\exception.py", line 55, in inner
    response = get_response(request)
  File "C:\Users\phara\OneDrive\Desktop\FMIS\python\dictionary_project\venv\Lib\site-packages\django\core\handlers\base.py", line 197, in _get_response
    response = wrapped_callback(request, *callback_args, **callback_kwargs)
  File "C:\Users\phara\OneDrive\Desktop\FMIS\python\dictionary_project\venv\Lib\site-packages\django\views\decorators\csrf.py", line 65, in _view_wrapper
    return view_func(request, *args, **kwargs)
  File "C:\Users\phara\OneDrive\Desktop\FMIS\python\dictionary_project\venv\Lib\site-packages\django\views\generic\base.py", line 104, in view
    return self.dispatch(request, *args, **kwargs)
           ~~~~~~~~~~~~~^^^^^^^^^^^^^^^^^^^^^^^^^^
  File "C:\Users\phara\OneDrive\Desktop\FMIS\python\dictionary_project\venv\Lib\site-packages\rest_framework\views.py", line 509, in dispatch
    response = self.handle_exception(exc)
  File "C:\Users\phara\OneDrive\Desktop\FMIS\python\dictionary_project\venv\Lib\site-packages\rest_framework\views.py", line 469, in handle_exception
    self.raise_uncaught_exception(exc)
    ~~~~~~~~~~~~~~~~~~~~~~~~~~~~~^^^^^
  File "C:\Users\phara\OneDrive\Desktop\FMIS\python\dictionary_project\venv\Lib\site-packages\rest_framework\views.py", line 480, in raise_uncaught_exception
    raise exc
  File "C:\Users\phara\OneDrive\Desktop\FMIS\python\dictionary_project\venv\Lib\site-packages\rest_framework\views.py", line 506, in dispatch
    response = handler(request, *args, **kwargs)
  File "C:\Users\phara\OneDrive\Desktop\FMIS\python\dictionary_project\dictionary\views.py", line 280, in post
    word=staging_entry.word,
         ^^^^^^^^^^^^^^^^^^
AttributeError: 'Staging' object has no attribute 'word'
"POST /api/dictionary/staging/4/approve/ HTTP/1.1" 500 104990
Internal Server Error: /api/dictionary/staging/4/approve/
Traceback (most recent call last):
  File "C:\Users\phara\OneDrive\Desktop\FMIS\python\dictionary_project\venv\Lib\site-packages\django\core\handlers\exception.py", line 55, in inner
    response = get_response(request)
  File "C:\Users\phara\OneDrive\Desktop\FMIS\python\dictionary_project\venv\Lib\site-packages\django\core\handlers\base.py", line 197, in _get_response
    response = wrapped_callback(request, *callback_args, **callback_kwargs)
  File "C:\Users\phara\OneDrive\Desktop\FMIS\python\dictionary_project\venv\Lib\site-packages\django\views\decorators\csrf.py", line 65, in _view_wrapper
    return view_func(request, *args, **kwargs)
  File "C:\Users\phara\OneDrive\Desktop\FMIS\python\dictionary_project\venv\Lib\site-packages\django\views\generic\base.py", line 104, in view
    return self.dispatch(request, *args, **kwargs)
           ~~~~~~~~~~~~~^^^^^^^^^^^^^^^^^^^^^^^^^^
  File "C:\Users\phara\OneDrive\Desktop\FMIS\python\dictionary_project\venv\Lib\site-packages\rest_framework\views.py", line 509, in dispatch
    response = self.handle_exception(exc)
  File "C:\Users\phara\OneDrive\Desktop\FMIS\python\dictionary_project\venv\Lib\site-packages\rest_framework\views.py", line 469, in handle_exception
    self.raise_uncaught_exception(exc)
    ~~~~~~~~~~~~~~~~~~~~~~~~~~~~~^^^^^
  File "C:\Users\phara\OneDrive\Desktop\FMIS\python\dictionary_project\venv\Lib\site-packages\rest_framework\views.py", line 480, in raise_uncaught_exception
    raise exc
  File "C:\Users\phara\OneDrive\Desktop\FMIS\python\dictionary_project\venv\Lib\site-packages\rest_framework\views.py", line 506, in dispatch
    response = handler(request, *args, **kwargs)
  File "C:\Users\phara\OneDrive\Desktop\FMIS\python\dictionary_project\dictionary\views.py", line 280, in post
    word=staging_entry.word,
         ^^^^^^^^^^^^^^^^^^
AttributeError: 'Staging' object has no attribute 'word'
"POST /api/dictionary/staging/4/approve/ HTTP/1.1" 500 104990
Internal Server Error: /api/dictionary/staging/4/approve/
Traceback (most recent call last):
  File "C:\Users\phara\OneDrive\Desktop\FMIS\python\dictionary_project\venv\Lib\site-packages\django\core\handlers\exception.py", line 55, in inner
    response = get_response(request)
  File "C:\Users\phara\OneDrive\Desktop\FMIS\python\dictionary_project\venv\Lib\site-packages\django\core\handlers\base.py", line 197, in _get_response
    response = wrapped_callback(request, *callback_args, **callback_kwargs)
  File "C:\Users\phara\OneDrive\Desktop\FMIS\python\dictionary_project\venv\Lib\site-packages\django\views\decorators\csrf.py", line 65, in _view_wrapper
    return view_func(request, *args, **kwargs)
  File "C:\Users\phara\OneDrive\Desktop\FMIS\python\dictionary_project\venv\Lib\site-packages\django\views\generic\base.py", line 104, in view
    return self.dispatch(request, *args, **kwargs)
           ~~~~~~~~~~~~~^^^^^^^^^^^^^^^^^^^^^^^^^^
  File "C:\Users\phara\OneDrive\Desktop\FMIS\python\dictionary_project\venv\Lib\site-packages\rest_framework\views.py", line 509, in dispatch
    response = self.handle_exception(exc)
  File "C:\Users\phara\OneDrive\Desktop\FMIS\python\dictionary_project\venv\Lib\site-packages\rest_framework\views.py", line 469, in handle_exception
    self.raise_uncaught_exception(exc)
    ~~~~~~~~~~~~~~~~~~~~~~~~~~~~~^^^^^
  File "C:\Users\phara\OneDrive\Desktop\FMIS\python\dictionary_project\venv\Lib\site-packages\rest_framework\views.py", line 480, in raise_uncaught_exception
    raise exc
  File "C:\Users\phara\OneDrive\Desktop\FMIS\python\dictionary_project\venv\Lib\site-packages\rest_framework\views.py", line 506, in dispatch
    response = handler(request, *args, **kwargs)
  File "C:\Users\phara\OneDrive\Desktop\FMIS\python\dictionary_project\dictionary\views.py", line 280, in post
    word=staging_entry.word,
         ^^^^^^^^^^^^^^^^^^
AttributeError: 'Staging' object has no attribute 'word'
"POST /api/dictionary/staging/4/approve/ HTTP/1.1" 500 105295
Internal Server Error: /api/dictionary/search/
Traceback (most recent call last):
  File "C:\Users\phara\OneDrive\Desktop\FMIS\python\dictionary_project\venv\Lib\site-packages\rest_framework\throttling.py", line 92, in get_rate
    return self.THROTTLE_RATES[self.scope]
           ~~~~~~~~~~~~~~~~~~~^^^^^^^^^^^^
KeyError: 'search'

During handling of the above exception, another exception occurred:

Traceback (most recent call last):
  File "C:\Users\phara\OneDrive\Desktop\FMIS\python\dictionary_project\venv\Lib\site-packages\django\core\handlers\exception.py", line 55, in inner
    response = get_response(request)
  File "C:\Users\phara\OneDrive\Desktop\FMIS\python\dictionary_project\venv\Lib\site-packages\django\core\handlers\base.py", line 197, in _get_response
    response = wrapped_callback(request, *callback_args, **callback_kwargs)
  File "C:\Users\phara\OneDrive\Desktop\FMIS\python\dictionary_project\venv\Lib\site-packages\django\views\decorators\csrf.py", line 65, in _view_wrapper
    return view_func(request, *args, **kwargs)
  File "C:\Users\phara\OneDrive\Desktop\FMIS\python\dictionary_project\venv\Lib\site-packages\django\views\generic\base.py", line 104, in view
    return self.dispatch(request, *args, **kwargs)
           ~~~~~~~~~~~~~^^^^^^^^^^^^^^^^^^^^^^^^^^
  File "C:\Users\phara\OneDrive\Desktop\FMIS\python\dictionary_project\venv\Lib\site-packages\rest_framework\views.py", line 509, in dispatch
    response = self.handle_exception(exc)
  File "C:\Users\phara\OneDrive\Desktop\FMIS\python\dictionary_project\venv\Lib\site-packages\rest_framework\views.py", line 469, in handle_exception
    self.raise_uncaught_exception(exc)
    ~~~~~~~~~~~~~~~~~~~~~~~~~~~~~^^^^^
  File "C:\Users\phara\OneDrive\Desktop\FMIS\python\dictionary_project\venv\Lib\site-packages\rest_framework\views.py", line 480, in raise_uncaught_exception
    raise exc
  File "C:\Users\phara\OneDrive\Desktop\FMIS\python\dictionary_project\venv\Lib\site-packages\rest_framework\views.py", line 497, in dispatch
    self.initial(request, *args, **kwargs)
    ~~~~~~~~~~~~^^^^^^^^^^^^^^^^^^^^^^^^^^
  File "C:\Users\phara\OneDrive\Desktop\FMIS\python\dictionary_project\venv\Lib\site-packages\rest_framework\views.py", line 416, in initial
    self.check_throttles(request)
    ~~~~~~~~~~~~~~~~~~~~^^^^^^^^^
  File "C:\Users\phara\OneDrive\Desktop\FMIS\python\dictionary_project\venv\Lib\site-packages\rest_framework\views.py", line 358, in check_throttles
    for throttle in self.get_throttles():
                    ~~~~~~~~~~~~~~~~~~^^
  File "C:\Users\phara\OneDrive\Desktop\FMIS\python\dictionary_project\venv\Lib\site-packages\rest_framework\views.py", line 284, in get_throttles
    return [throttle() for throttle in self.throttle_classes]
            ~~~~~~~~^^
  File "C:\Users\phara\OneDrive\Desktop\FMIS\python\dictionary_project\venv\Lib\site-packages\rest_framework\throttling.py", line 70, in __init__
    self.rate = self.get_rate()
                ~~~~~~~~~~~~~^^
  File "C:\Users\phara\OneDrive\Desktop\FMIS\python\dictionary_project\venv\Lib\site-packages\rest_framework\throttling.py", line 95, in get_rate
    raise ImproperlyConfigured(msg)
django.core.exceptions.ImproperlyConfigured: No default throttle rate set for 'search' scope
"GET /api/dictionary/search/?query=hello HTTP/1.1" 500 125928
Internal Server Error: /api/dictionary/search/
Traceback (most recent call last):
  File "C:\Users\phara\OneDrive\Desktop\FMIS\python\dictionary_project\venv\Lib\site-packages\rest_framework\throttling.py", line 92, in get_rate
    return self.THROTTLE_RATES[self.scope]
           ~~~~~~~~~~~~~~~~~~~^^^^^^^^^^^^
KeyError: 'search'

During handling of the above exception, another exception occurred:

Traceback (most recent call last):
  File "C:\Users\phara\OneDrive\Desktop\FMIS\python\dictionary_project\venv\Lib\site-packages\django\core\handlers\exception.py", line 55, in inner
    response = get_response(request)
  File "C:\Users\phara\OneDrive\Desktop\FMIS\python\dictionary_project\venv\Lib\site-packages\django\core\handlers\base.py", line 197, in _get_response
    response = wrapped_callback(request, *callback_args, **callback_kwargs)
  File "C:\Users\phara\OneDrive\Desktop\FMIS\python\dictionary_project\venv\Lib\site-packages\django\views\decorators\csrf.py", line 65, in _view_wrapper
    return view_func(request, *args, **kwargs)
  File "C:\Users\phara\OneDrive\Desktop\FMIS\python\dictionary_project\venv\Lib\site-packages\django\views\generic\base.py", line 104, in view
    return self.dispatch(request, *args, **kwargs)
           ~~~~~~~~~~~~~^^^^^^^^^^^^^^^^^^^^^^^^^^
  File "C:\Users\phara\OneDrive\Desktop\FMIS\python\dictionary_project\venv\Lib\site-packages\rest_framework\views.py", line 509, in dispatch
    response = self.handle_exception(exc)
  File "C:\Users\phara\OneDrive\Desktop\FMIS\python\dictionary_project\venv\Lib\site-packages\rest_framework\views.py", line 469, in handle_exception
    self.raise_uncaught_exception(exc)
    ~~~~~~~~~~~~~~~~~~~~~~~~~~~~~^^^^^
  File "C:\Users\phara\OneDrive\Desktop\FMIS\python\dictionary_project\venv\Lib\site-packages\rest_framework\views.py", line 480, in raise_uncaught_exception
    raise exc
  File "C:\Users\phara\OneDrive\Desktop\FMIS\python\dictionary_project\venv\Lib\site-packages\rest_framework\views.py", line 497, in dispatch
    self.initial(request, *args, **kwargs)
    ~~~~~~~~~~~~^^^^^^^^^^^^^^^^^^^^^^^^^^
  File "C:\Users\phara\OneDrive\Desktop\FMIS\python\dictionary_project\venv\Lib\site-packages\rest_framework\views.py", line 416, in initial
    self.check_throttles(request)
    ~~~~~~~~~~~~~~~~~~~~^^^^^^^^^
  File "C:\Users\phara\OneDrive\Desktop\FMIS\python\dictionary_project\venv\Lib\site-packages\rest_framework\views.py", line 358, in check_throttles
    for throttle in self.get_throttles():
                    ~~~~~~~~~~~~~~~~~~^^
  File "C:\Users\phara\OneDrive\Desktop\FMIS\python\dictionary_project\venv\Lib\site-packages\rest_framework\views.py", line 284, in get_throttles
    return [throttle() for throttle in self.throttle_classes]
            ~~~~~~~~^^
  File "C:\Users\phara\OneDrive\Desktop\FMIS\python\dictionary_project\venv\Lib\site-packages\rest_framework\throttling.py", line 70, in __init__
    self.rate = self.get_rate()
                ~~~~~~~~~~~~~^^
  File "C:\Users\phara\OneDrive\Desktop\FMIS\python\dictionary_project\venv\Lib\site-packages\rest_framework\throttling.py", line 95, in get_rate
    raise ImproperlyConfigured(msg)
django.core.exceptions.ImproperlyConfigured: No default throttle rate set for 'search' scope
"GET /api/dictionary/search/?query=hello HTTP/1.1" 500 125921
Internal Server Error: /api/dictionary/search/
Traceback (most recent call last):
  File "C:\Users\phara\OneDrive\Desktop\FMIS\python\dictionary_project\venv\Lib\site-packages\rest_framework\throttling.py", line 92, in get_rate
    return self.THROTTLE_RATES[self.scope]
           ~~~~~~~~~~~~~~~~~~~^^^^^^^^^^^^
KeyError: 'search'

During handling of the above exception, another exception occurred:

Traceback (most recent call last):
  File "C:\Users\phara\OneDrive\Desktop\FMIS\python\dictionary_project\venv\Lib\site-packages\django\core\handlers\exception.py", line 55, in inner
    response = get_response(request)
  File "C:\Users\phara\OneDrive\Desktop\FMIS\python\dictionary_project\venv\Lib\site-packages\django\core\handlers\base.py", line 197, in _get_response
    response = wrapped_callback(request, *callback_args, **callback_kwargs)
  File "C:\Users\phara\OneDrive\Desktop\FMIS\python\dictionary_project\venv\Lib\site-packages\django\views\decorators\csrf.py", line 65, in _view_wrapper
    return view_func(request, *args, **kwargs)
  File "C:\Users\phara\OneDrive\Desktop\FMIS\python\dictionary_project\venv\Lib\site-packages\django\views\generic\base.py", line 104, in view
    return self.dispatch(request, *args, **kwargs)
           ~~~~~~~~~~~~~^^^^^^^^^^^^^^^^^^^^^^^^^^
  File "C:\Users\phara\OneDrive\Desktop\FMIS\python\dictionary_project\venv\Lib\site-packages\rest_framework\views.py", line 509, in dispatch
    response = self.handle_exception(exc)
  File "C:\Users\phara\OneDrive\Desktop\FMIS\python\dictionary_project\venv\Lib\site-packages\rest_framework\views.py", line 469, in handle_exception
    self.raise_uncaught_exception(exc)
    ~~~~~~~~~~~~~~~~~~~~~~~~~~~~~^^^^^
  File "C:\Users\phara\OneDrive\Desktop\FMIS\python\dictionary_project\venv\Lib\site-packages\rest_framework\views.py", line 480, in raise_uncaught_exception
    raise exc
  File "C:\Users\phara\OneDrive\Desktop\FMIS\python\dictionary_project\venv\Lib\site-packages\rest_framework\views.py", line 497, in dispatch
    self.initial(request, *args, **kwargs)
    ~~~~~~~~~~~~^^^^^^^^^^^^^^^^^^^^^^^^^^
  File "C:\Users\phara\OneDrive\Desktop\FMIS\python\dictionary_project\venv\Lib\site-packages\rest_framework\views.py", line 416, in initial
    self.check_throttles(request)
    ~~~~~~~~~~~~~~~~~~~~^^^^^^^^^
  File "C:\Users\phara\OneDrive\Desktop\FMIS\python\dictionary_project\venv\Lib\site-packages\rest_framework\views.py", line 358, in check_throttles
    for throttle in self.get_throttles():
                    ~~~~~~~~~~~~~~~~~~^^
  File "C:\Users\phara\OneDrive\Desktop\FMIS\python\dictionary_project\venv\Lib\site-packages\rest_framework\views.py", line 284, in get_throttles
    return [throttle() for throttle in self.throttle_classes]
            ~~~~~~~~^^
  File "C:\Users\phara\OneDrive\Desktop\FMIS\python\dictionary_project\venv\Lib\site-packages\rest_framework\throttling.py", line 70, in __init__
    self.rate = self.get_rate()
                ~~~~~~~~~~~~~^^
  File "C:\Users\phara\OneDrive\Desktop\FMIS\python\dictionary_project\venv\Lib\site-packages\rest_framework\throttling.py", line 95, in get_rate
    raise ImproperlyConfigured(msg)
django.core.exceptions.ImproperlyConfigured: No default throttle rate set for 'search' scope
"GET /api/dictionary/search/?query=life HTTP/1.1" 500 125907
Internal Server Error: /api/dictionary/staging/10/approve/
Traceback (most recent call last):
  File "C:\Users\phara\OneDrive\Desktop\FMIS\python\dictionary_project\venv\Lib\site-packages\django\core\handlers\exception.py", line 55, in inner
    response = get_response(request)
  File "C:\Users\phara\OneDrive\Desktop\FMIS\python\dictionary_project\venv\Lib\site-packages\django\core\handlers\base.py", line 197, in _get_response
    response = wrapped_callback(request, *callback_args, **callback_kwargs)
  File "C:\Users\phara\OneDrive\Desktop\FMIS\python\dictionary_project\venv\Lib\site-packages\django\views\decorators\csrf.py", line 65, in _view_wrapper
    return view_func(request, *args, **kwargs)
  File "C:\Users\phara\OneDrive\Desktop\FMIS\python\dictionary_project\venv\Lib\site-packages\django\views\generic\base.py", line 104, in view
    return self.dispatch(request, *args, **kwargs)
           ~~~~~~~~~~~~~^^^^^^^^^^^^^^^^^^^^^^^^^^
  File "C:\Users\phara\OneDrive\Desktop\FMIS\python\dictionary_project\venv\Lib\site-packages\rest_framework\views.py", line 509, in dispatch
    response = self.handle_exception(exc)
  File "C:\Users\phara\OneDrive\Desktop\FMIS\python\dictionary_project\venv\Lib\site-packages\rest_framework\views.py", line 469, in handle_exception
    self.raise_uncaught_exception(exc)
    ~~~~~~~~~~~~~~~~~~~~~~~~~~~~~^^^^^
  File "C:\Users\phara\OneDrive\Desktop\FMIS\python\dictionary_project\venv\Lib\site-packages\rest_framework\views.py", line 480, in raise_uncaught_exception
    raise exc
  File "C:\Users\phara\OneDrive\Desktop\FMIS\python\dictionary_project\venv\Lib\site-packages\rest_framework\views.py", line 506, in dispatch
    response = handler(request, *args, **kwargs)
  File "C:\Users\phara\OneDrive\Desktop\FMIS\python\dictionary_project\dictionary\views.py", line 280, in post
    word=staging_entry.word,
         ^^^^^^^^^^^^^^^^^^
AttributeError: 'Staging' object has no attribute 'word'
"POST /api/dictionary/staging/10/approve/ HTTP/1.1" 500 105411
Internal Server Error: /api/dictionary/staging/10/approve/
Traceback (most recent call last):
  File "C:\Users\phara\OneDrive\Desktop\FMIS\python\dictionary_project\venv\Lib\site-packages\django\core\handlers\exception.py", line 55, in inner
    response = get_response(request)
  File "C:\Users\phara\OneDrive\Desktop\FMIS\python\dictionary_project\venv\Lib\site-packages\django\core\handlers\base.py", line 197, in _get_response
    response = wrapped_callback(request, *callback_args, **callback_kwargs)
  File "C:\Users\phara\OneDrive\Desktop\FMIS\python\dictionary_project\venv\Lib\site-packages\django\views\decorators\csrf.py", line 65, in _view_wrapper
    return view_func(request, *args, **kwargs)
  File "C:\Users\phara\OneDrive\Desktop\FMIS\python\dictionary_project\venv\Lib\site-packages\django\views\generic\base.py", line 104, in view
    return self.dispatch(request, *args, **kwargs)
           ~~~~~~~~~~~~~^^^^^^^^^^^^^^^^^^^^^^^^^^
  File "C:\Users\phara\OneDrive\Desktop\FMIS\python\dictionary_project\venv\Lib\site-packages\rest_framework\views.py", line 509, in dispatch
    response = self.handle_exception(exc)
  File "C:\Users\phara\OneDrive\Desktop\FMIS\python\dictionary_project\venv\Lib\site-packages\rest_framework\views.py", line 469, in handle_exception
    self.raise_uncaught_exception(exc)
    ~~~~~~~~~~~~~~~~~~~~~~~~~~~~~^^^^^
  File "C:\Users\phara\OneDrive\Desktop\FMIS\python\dictionary_project\venv\Lib\site-packages\rest_framework\views.py", line 480, in raise_uncaught_exception
    raise exc
  File "C:\Users\phara\OneDrive\Desktop\FMIS\python\dictionary_project\venv\Lib\site-packages\rest_framework\views.py", line 506, in dispatch
    response = handler(request, *args, **kwargs)
  File "C:\Users\phara\OneDrive\Desktop\FMIS\python\dictionary_project\dictionary\views.py", line 279, in post
    dictionary_entry = Dictionary.objects.create(
        word=staging_entry.word,
    ...<2 lines>...
        examples=staging_entry.examples
    )
  File "C:\Users\phara\OneDrive\Desktop\FMIS\python\dictionary_project\venv\Lib\site-packages\django\db\models\manager.py", line 87, in manager_method
    return getattr(self.get_queryset(), name)(*args, **kwargs)
           ~~~~~~~~~~~~~~~~~~~~~~~~~~~~~~~~~~^^^^^^^^^^^^^^^^^
  File "C:\Users\phara\OneDrive\Desktop\FMIS\python\dictionary_project\venv\Lib\site-packages\django\db\models\query.py", line 677, in create
    obj = self.model(**kwargs)
  File "C:\Users\phara\OneDrive\Desktop\FMIS\python\dictionary_project\venv\Lib\site-packages\django\db\models\base.py", line 567, in __init__
    raise TypeError(
    ...<2 lines>...
    )
TypeError: Dictionary() got unexpected keyword arguments: 'word', 'definition', 'language', 'examples'
"POST /api/dictionary/staging/10/approve/ HTTP/1.1" 500 121462
Internal Server Error: /api/dictionary/staging/10/approve/
Traceback (most recent call last):
  File "C:\Users\phara\OneDrive\Desktop\FMIS\python\dictionary_project\venv\Lib\site-packages\django\core\handlers\exception.py", line 55, in inner
    response = get_response(request)
  File "C:\Users\phara\OneDrive\Desktop\FMIS\python\dictionary_project\venv\Lib\site-packages\django\core\handlers\base.py", line 197, in _get_response
    response = wrapped_callback(request, *callback_args, **callback_kwargs)
  File "C:\Users\phara\OneDrive\Desktop\FMIS\python\dictionary_project\venv\Lib\site-packages\django\views\decorators\csrf.py", line 65, in _view_wrapper
    return view_func(request, *args, **kwargs)
  File "C:\Users\phara\OneDrive\Desktop\FMIS\python\dictionary_project\venv\Lib\site-packages\django\views\generic\base.py", line 104, in view
    return self.dispatch(request, *args, **kwargs)
           ~~~~~~~~~~~~~^^^^^^^^^^^^^^^^^^^^^^^^^^
  File "C:\Users\phara\OneDrive\Desktop\FMIS\python\dictionary_project\venv\Lib\site-packages\rest_framework\views.py", line 509, in dispatch
    response = self.handle_exception(exc)
  File "C:\Users\phara\OneDrive\Desktop\FMIS\python\dictionary_project\venv\Lib\site-packages\rest_framework\views.py", line 469, in handle_exception
    self.raise_uncaught_exception(exc)
    ~~~~~~~~~~~~~~~~~~~~~~~~~~~~~^^^^^
  File "C:\Users\phara\OneDrive\Desktop\FMIS\python\dictionary_project\venv\Lib\site-packages\rest_framework\views.py", line 480, in raise_uncaught_exception
    raise exc
  File "C:\Users\phara\OneDrive\Desktop\FMIS\python\dictionary_project\venv\Lib\site-packages\rest_framework\views.py", line 506, in dispatch
    response = handler(request, *args, **kwargs)
  File "C:\Users\phara\OneDrive\Desktop\FMIS\python\dictionary_project\dictionary\views.py", line 279, in post
    dictionary_entry = Dictionary.objects.create(
        word_kh=staging_entry.word_kh,
    ...<8 lines>...
        example_sentence_en=staging_entry.example_sentence_en,
    )
  File "C:\Users\phara\OneDrive\Desktop\FMIS\python\dictionary_project\venv\Lib\site-packages\django\db\models\manager.py", line 87, in manager_method
    return getattr(self.get_queryset(), name)(*args, **kwargs)
           ~~~~~~~~~~~~~~~~~~~~~~~~~~~~~~~~~~^^^^^^^^^^^^^^^^^
  File "C:\Users\phara\OneDrive\Desktop\FMIS\python\dictionary_project\venv\Lib\site-packages\django\db\models\query.py", line 677, in create
    obj = self.model(**kwargs)
  File "C:\Users\phara\OneDrive\Desktop\FMIS\python\dictionary_project\venv\Lib\site-packages\django\db\models\base.py", line 567, in __init__
    raise TypeError(
    ...<2 lines>...
    )
TypeError: Dictionary() got unexpected keyword arguments: 'pronunciation_kh', 'pronunciation_en'
"POST /api/dictionary/staging/10/approve/ HTTP/1.1" 500 122261
Internal Server Error: /api/dictionary/staging/10/approve/
Traceback (most recent call last):
  File "C:\Users\phara\OneDrive\Desktop\FMIS\python\dictionary_project\venv\Lib\site-packages\django\core\handlers\exception.py", line 55, in inner
    response = get_response(request)
  File "C:\Users\phara\OneDrive\Desktop\FMIS\python\dictionary_project\venv\Lib\site-packages\django\core\handlers\base.py", line 197, in _get_response
    response = wrapped_callback(request, *callback_args, **callback_kwargs)
  File "C:\Users\phara\OneDrive\Desktop\FMIS\python\dictionary_project\venv\Lib\site-packages\django\views\decorators\csrf.py", line 65, in _view_wrapper
    return view_func(request, *args, **kwargs)
  File "C:\Users\phara\OneDrive\Desktop\FMIS\python\dictionary_project\venv\Lib\site-packages\django\views\generic\base.py", line 104, in view
    return self.dispatch(request, *args, **kwargs)
           ~~~~~~~~~~~~~^^^^^^^^^^^^^^^^^^^^^^^^^^
  File "C:\Users\phara\OneDrive\Desktop\FMIS\python\dictionary_project\venv\Lib\site-packages\rest_framework\views.py", line 509, in dispatch
    response = self.handle_exception(exc)
  File "C:\Users\phara\OneDrive\Desktop\FMIS\python\dictionary_project\venv\Lib\site-packages\rest_framework\views.py", line 469, in handle_exception
    self.raise_uncaught_exception(exc)
    ~~~~~~~~~~~~~~~~~~~~~~~~~~~~~^^^^^
  File "C:\Users\phara\OneDrive\Desktop\FMIS\python\dictionary_project\venv\Lib\site-packages\rest_framework\views.py", line 480, in raise_uncaught_exception
    raise exc
  File "C:\Users\phara\OneDrive\Desktop\FMIS\python\dictionary_project\venv\Lib\site-packages\rest_framework\views.py", line 506, in dispatch
    response = handler(request, *args, **kwargs)
  File "C:\Users\phara\OneDrive\Desktop\FMIS\python\dictionary_project\dictionary\views.py", line 279, in post
    dictionary_entry = Dictionary.objects.create(
        word_kh=staging_entry.word_kh,
    ...<8 lines>...
        example_sentence_en=staging_entry.example_sentence_en,
    )
  File "C:\Users\phara\OneDrive\Desktop\FMIS\python\dictionary_project\venv\Lib\site-packages\django\db\models\manager.py", line 87, in manager_method
    return getattr(self.get_queryset(), name)(*args, **kwargs)
           ~~~~~~~~~~~~~~~~~~~~~~~~~~~~~~~~~~^^^^^^^^^^^^^^^^^
  File "C:\Users\phara\OneDrive\Desktop\FMIS\python\dictionary_project\venv\Lib\site-packages\django\db\models\query.py", line 677, in create
    obj = self.model(**kwargs)
  File "C:\Users\phara\OneDrive\Desktop\FMIS\python\dictionary_project\venv\Lib\site-packages\django\db\models\base.py", line 567, in __init__
    raise TypeError(
    ...<2 lines>...
    )
TypeError: Dictionary() got unexpected keyword arguments: 'pronunciation_kh', 'pronunciation_en'
"POST /api/dictionary/staging/10/approve/ HTTP/1.1" 500 122261
Internal Server Error: /api/dictionary/staging/10/approve/
Traceback (most recent call last):
  File "C:\Users\phara\OneDrive\Desktop\FMIS\python\dictionary_project\venv\Lib\site-packages\django\core\handlers\exception.py", line 55, in inner
    response = get_response(request)
  File "C:\Users\phara\OneDrive\Desktop\FMIS\python\dictionary_project\venv\Lib\site-packages\django\core\handlers\base.py", line 197, in _get_response
    response = wrapped_callback(request, *callback_args, **callback_kwargs)
  File "C:\Users\phara\OneDrive\Desktop\FMIS\python\dictionary_project\venv\Lib\site-packages\django\views\decorators\csrf.py", line 65, in _view_wrapper
    return view_func(request, *args, **kwargs)
  File "C:\Users\phara\OneDrive\Desktop\FMIS\python\dictionary_project\venv\Lib\site-packages\django\views\generic\base.py", line 104, in view
    return self.dispatch(request, *args, **kwargs)
           ~~~~~~~~~~~~~^^^^^^^^^^^^^^^^^^^^^^^^^^
  File "C:\Users\phara\OneDrive\Desktop\FMIS\python\dictionary_project\venv\Lib\site-packages\rest_framework\views.py", line 509, in dispatch
    response = self.handle_exception(exc)
  File "C:\Users\phara\OneDrive\Desktop\FMIS\python\dictionary_project\venv\Lib\site-packages\rest_framework\views.py", line 469, in handle_exception
    self.raise_uncaught_exception(exc)
    ~~~~~~~~~~~~~~~~~~~~~~~~~~~~~^^^^^
  File "C:\Users\phara\OneDrive\Desktop\FMIS\python\dictionary_project\venv\Lib\site-packages\rest_framework\views.py", line 480, in raise_uncaught_exception
    raise exc
  File "C:\Users\phara\OneDrive\Desktop\FMIS\python\dictionary_project\venv\Lib\site-packages\rest_framework\views.py", line 506, in dispatch
    response = handler(request, *args, **kwargs)
  File "C:\Users\phara\OneDrive\Desktop\FMIS\python\dictionary_project\dictionary\views.py", line 279, in post
    dictionary_entry = Dictionary.objects.create(
        word_kh=staging_entry.word_kh,
    ...<8 lines>...
        example_sentence_en=staging_entry.example_sentence_en,
    )
  File "C:\Users\phara\OneDrive\Desktop\FMIS\python\dictionary_project\venv\Lib\site-packages\django\db\models\manager.py", line 87, in manager_method
    return getattr(self.get_queryset(), name)(*args, **kwargs)
           ~~~~~~~~~~~~~~~~~~~~~~~~~~~~~~~~~~^^^^^^^^^^^^^^^^^
  File "C:\Users\phara\OneDrive\Desktop\FMIS\python\dictionary_project\venv\Lib\site-packages\django\db\models\query.py", line 677, in create
    obj = self.model(**kwargs)
  File "C:\Users\phara\OneDrive\Desktop\FMIS\python\dictionary_project\venv\Lib\site-packages\django\db\models\base.py", line 567, in __init__
    raise TypeError(
    ...<2 lines>...
    )
TypeError: Dictionary() got unexpected keyword arguments: 'pronunciation_kh', 'pronunciation_en'
"POST /api/dictionary/staging/10/approve/ HTTP/1.1" 500 122261
Internal Server Error: /api/dictionary/staging/10/approve/
Traceback (most recent call last):
  File "C:\Users\phara\OneDrive\Desktop\FMIS\python\dictionary_project\venv\Lib\site-packages\django\db\backends\utils.py", line 105, in _execute
    return self.cursor.execute(sql, params)
           ~~~~~~~~~~~~~~~~~~~^^^^^^^^^^^^^
  File "C:\Users\phara\OneDrive\Desktop\FMIS\python\dictionary_project\venv\Lib\site-packages\django\db\backends\mysql\base.py", line 76, in execute
    return self.cursor.execute(query, args)
           ~~~~~~~~~~~~~~~~~~~^^^^^^^^^^^^^
  File "C:\Users\phara\OneDrive\Desktop\FMIS\python\dictionary_project\venv\Lib\site-packages\MySQLdb\cursors.py", line 179, in execute
    res = self._query(mogrified_query)
  File "C:\Users\phara\OneDrive\Desktop\FMIS\python\dictionary_project\venv\Lib\site-packages\MySQLdb\cursors.py", line 330, in _query
    db.query(q)
    ~~~~~~~~^^^
  File "C:\Users\phara\OneDrive\Desktop\FMIS\python\dictionary_project\venv\Lib\site-packages\MySQLdb\connections.py", line 280, in query
    _mysql.connection.query(self, query)
    ~~~~~~~~~~~~~~~~~~~~~~~^^^^^^^^^^^^^
MySQLdb.IntegrityError: (1364, "Field 'index' doesn't have a default value")

The above exception was the direct cause of the following exception:

Traceback (most recent call last):
  File "C:\Users\phara\OneDrive\Desktop\FMIS\python\dictionary_project\venv\Lib\site-packages\django\core\handlers\exception.py", line 55, in inner
    response = get_response(request)
  File "C:\Users\phara\OneDrive\Desktop\FMIS\python\dictionary_project\venv\Lib\site-packages\django\core\handlers\base.py", line 197, in _get_response
    response = wrapped_callback(request, *callback_args, **callback_kwargs)
  File "C:\Users\phara\OneDrive\Desktop\FMIS\python\dictionary_project\venv\Lib\site-packages\django\views\decorators\csrf.py", line 65, in _view_wrapper
    return view_func(request, *args, **kwargs)
  File "C:\Users\phara\OneDrive\Desktop\FMIS\python\dictionary_project\venv\Lib\site-packages\django\views\generic\base.py", line 104, in view
    return self.dispatch(request, *args, **kwargs)
           ~~~~~~~~~~~~~^^^^^^^^^^^^^^^^^^^^^^^^^^
  File "C:\Users\phara\OneDrive\Desktop\FMIS\python\dictionary_project\venv\Lib\site-packages\rest_framework\views.py", line 509, in dispatch
    response = self.handle_exception(exc)
  File "C:\Users\phara\OneDrive\Desktop\FMIS\python\dictionary_project\venv\Lib\site-packages\rest_framework\views.py", line 469, in handle_exception
    self.raise_uncaught_exception(exc)
    ~~~~~~~~~~~~~~~~~~~~~~~~~~~~~^^^^^
  File "C:\Users\phara\OneDrive\Desktop\FMIS\python\dictionary_project\venv\Lib\site-packages\rest_framework\views.py", line 480, in raise_uncaught_exception
    raise exc
  File "C:\Users\phara\OneDrive\Desktop\FMIS\python\dictionary_project\venv\Lib\site-packages\rest_framework\views.py", line 506, in dispatch
    response = handler(request, *args, **kwargs)
  File "C:\Users\phara\OneDrive\Desktop\FMIS\python\dictionary_project\dictionary\views.py", line 279, in post
    dictionary_entry = Dictionary.objects.create(
        word_kh=staging_entry.word_kh,
    ...<9 lines>...
        created_by=request.user
    )
  File "C:\Users\phara\OneDrive\Desktop\FMIS\python\dictionary_project\venv\Lib\site-packages\django\db\models\manager.py", line 87, in manager_method
    return getattr(self.get_queryset(), name)(*args, **kwargs)
           ~~~~~~~~~~~~~~~~~~~~~~~~~~~~~~~~~~^^^^^^^^^^^^^^^^^
  File "C:\Users\phara\OneDrive\Desktop\FMIS\python\dictionary_project\venv\Lib\site-packages\django\db\models\query.py", line 679, in create
    obj.save(force_insert=True, using=self.db)
    ~~~~~~~~^^^^^^^^^^^^^^^^^^^^^^^^^^^^^^^^^^
  File "C:\Users\phara\OneDrive\Desktop\FMIS\python\dictionary_project\venv\Lib\site-packages\django\db\models\base.py", line 892, in save
    self.save_base(
    ~~~~~~~~~~~~~~^
        using=using,
        ^^^^^^^^^^^^
    ...<2 lines>...
        update_fields=update_fields,
        ^^^^^^^^^^^^^^^^^^^^^^^^^^^^
    )
    ^
  File "C:\Users\phara\OneDrive\Desktop\FMIS\python\dictionary_project\venv\Lib\site-packages\django\db\models\base.py", line 998, in save_base
    updated = self._save_table(
        raw,
    ...<4 lines>...
        update_fields,
    )
  File "C:\Users\phara\OneDrive\Desktop\FMIS\python\dictionary_project\venv\Lib\site-packages\django\db\models\base.py", line 1161, in _save_table
    results = self._do_insert(
        cls._base_manager, using, fields, returning_fields, raw
    )
  File "C:\Users\phara\OneDrive\Desktop\FMIS\python\dictionary_project\venv\Lib\site-packages\django\db\models\base.py", line 1202, in _do_insert
    return manager._insert(
           ~~~~~~~~~~~~~~~^
        [self],
        ^^^^^^^
    ...<3 lines>...
        raw=raw,
        ^^^^^^^^
    )
    ^
  File "C:\Users\phara\OneDrive\Desktop\FMIS\python\dictionary_project\venv\Lib\site-packages\django\db\models\manager.py", line 87, in manager_method
    return getattr(self.get_queryset(), name)(*args, **kwargs)
           ~~~~~~~~~~~~~~~~~~~~~~~~~~~~~~~~~~^^^^^^^^^^^^^^^^^
  File "C:\Users\phara\OneDrive\Desktop\FMIS\python\dictionary_project\venv\Lib\site-packages\django\db\models\query.py", line 1847, in _insert
    return query.get_compiler(using=using).execute_sql(returning_fields)
           ~~~~~~~~~~~~~~~~~~~~~~~~~~~~~~~~~~~~~~~~~~~^^^^^^^^^^^^^^^^^^
  File "C:\Users\phara\OneDrive\Desktop\FMIS\python\dictionary_project\venv\Lib\site-packages\django\db\models\sql\compiler.py", line 1836, in execute_sql
    cursor.execute(sql, params)
    ~~~~~~~~~~~~~~^^^^^^^^^^^^^
  File "C:\Users\phara\OneDrive\Desktop\FMIS\python\dictionary_project\venv\Lib\site-packages\django\db\backends\utils.py", line 122, in execute
    return super().execute(sql, params)
           ~~~~~~~~~~~~~~~^^^^^^^^^^^^^
  File "C:\Users\phara\OneDrive\Desktop\FMIS\python\dictionary_project\venv\Lib\site-packages\django\db\backends\utils.py", line 79, in execute
    return self._execute_with_wrappers(
           ~~~~~~~~~~~~~~~~~~~~~~~~~~~^
        sql, params, many=False, executor=self._execute
        ^^^^^^^^^^^^^^^^^^^^^^^^^^^^^^^^^^^^^^^^^^^^^^^
    )
    ^
  File "C:\Users\phara\OneDrive\Desktop\FMIS\python\dictionary_project\venv\Lib\site-packages\django\db\backends\utils.py", line 92, in _execute_with_wrappers
    return executor(sql, params, many, context)
  File "C:\Users\phara\OneDrive\Desktop\FMIS\python\dictionary_project\venv\Lib\site-packages\django\db\backends\utils.py", line 100, in _execute
    with self.db.wrap_database_errors:
         ^^^^^^^^^^^^^^^^^^^^^^^^^^^^
  File "C:\Users\phara\OneDrive\Desktop\FMIS\python\dictionary_project\venv\Lib\site-packages\django\db\utils.py", line 91, in __exit__
    raise dj_exc_value.with_traceback(traceback) from exc_value
  File "C:\Users\phara\OneDrive\Desktop\FMIS\python\dictionary_project\venv\Lib\site-packages\django\db\backends\utils.py", line 105, in _execute
    return self.cursor.execute(sql, params)
           ~~~~~~~~~~~~~~~~~~~^^^^^^^^^^^^^
  File "C:\Users\phara\OneDrive\Desktop\FMIS\python\dictionary_project\venv\Lib\site-packages\django\db\backends\mysql\base.py", line 76, in execute
    return self.cursor.execute(query, args)
           ~~~~~~~~~~~~~~~~~~~^^^^^^^^^^^^^
  File "C:\Users\phara\OneDrive\Desktop\FMIS\python\dictionary_project\venv\Lib\site-packages\MySQLdb\cursors.py", line 179, in execute
    res = self._query(mogrified_query)
  File "C:\Users\phara\OneDrive\Desktop\FMIS\python\dictionary_project\venv\Lib\site-packages\MySQLdb\cursors.py", line 330, in _query
    db.query(q)
    ~~~~~~~~^^^
  File "C:\Users\phara\OneDrive\Desktop\FMIS\python\dictionary_project\venv\Lib\site-packages\MySQLdb\connections.py", line 280, in query
    _mysql.connection.query(self, query)
    ~~~~~~~~~~~~~~~~~~~~~~~^^^^^^^^^^^^^
django.db.utils.IntegrityError: (1364, "Field 'index' doesn't have a default value")
"POST /api/dictionary/staging/10/approve/ HTTP/1.1" 500 236838
Internal Server Error: /api/dictionary/staging/1/approve/
Traceback (most recent call last):
  File "C:\Users\phara\OneDrive\Desktop\FMIS\python\dictionary_project\venv\Lib\site-packages\django\db\backends\utils.py", line 105, in _execute
    return self.cursor.execute(sql, params)
           ~~~~~~~~~~~~~~~~~~~^^^^^^^^^^^^^
  File "C:\Users\phara\OneDrive\Desktop\FMIS\python\dictionary_project\venv\Lib\site-packages\django\db\backends\mysql\base.py", line 76, in execute
    return self.cursor.execute(query, args)
           ~~~~~~~~~~~~~~~~~~~^^^^^^^^^^^^^
  File "C:\Users\phara\OneDrive\Desktop\FMIS\python\dictionary_project\venv\Lib\site-packages\MySQLdb\cursors.py", line 179, in execute
    res = self._query(mogrified_query)
  File "C:\Users\phara\OneDrive\Desktop\FMIS\python\dictionary_project\venv\Lib\site-packages\MySQLdb\cursors.py", line 330, in _query
    db.query(q)
    ~~~~~~~~^^^
  File "C:\Users\phara\OneDrive\Desktop\FMIS\python\dictionary_project\venv\Lib\site-packages\MySQLdb\connections.py", line 280, in query
    _mysql.connection.query(self, query)
    ~~~~~~~~~~~~~~~~~~~~~~~^^^^^^^^^^^^^
MySQLdb.IntegrityError: (1364, "Field 'index' doesn't have a default value")

The above exception was the direct cause of the following exception:

Traceback (most recent call last):
  File "C:\Users\phara\OneDrive\Desktop\FMIS\python\dictionary_project\venv\Lib\site-packages\django\core\handlers\exception.py", line 55, in inner
    response = get_response(request)
  File "C:\Users\phara\OneDrive\Desktop\FMIS\python\dictionary_project\venv\Lib\site-packages\django\core\handlers\base.py", line 197, in _get_response
    response = wrapped_callback(request, *callback_args, **callback_kwargs)
  File "C:\Users\phara\OneDrive\Desktop\FMIS\python\dictionary_project\venv\Lib\site-packages\django\views\decorators\csrf.py", line 65, in _view_wrapper
    return view_func(request, *args, **kwargs)
  File "C:\Users\phara\OneDrive\Desktop\FMIS\python\dictionary_project\venv\Lib\site-packages\django\views\generic\base.py", line 104, in view
    return self.dispatch(request, *args, **kwargs)
           ~~~~~~~~~~~~~^^^^^^^^^^^^^^^^^^^^^^^^^^
  File "C:\Users\phara\OneDrive\Desktop\FMIS\python\dictionary_project\venv\Lib\site-packages\rest_framework\views.py", line 509, in dispatch
    response = self.handle_exception(exc)
  File "C:\Users\phara\OneDrive\Desktop\FMIS\python\dictionary_project\venv\Lib\site-packages\rest_framework\views.py", line 469, in handle_exception
    self.raise_uncaught_exception(exc)
    ~~~~~~~~~~~~~~~~~~~~~~~~~~~~~^^^^^
  File "C:\Users\phara\OneDrive\Desktop\FMIS\python\dictionary_project\venv\Lib\site-packages\rest_framework\views.py", line 480, in raise_uncaught_exception
    raise exc
  File "C:\Users\phara\OneDrive\Desktop\FMIS\python\dictionary_project\venv\Lib\site-packages\rest_framework\views.py", line 506, in dispatch
    response = handler(request, *args, **kwargs)
  File "C:\Users\phara\OneDrive\Desktop\FMIS\python\dictionary_project\dictionary\views.py", line 279, in post
    dictionary_entry = Dictionary.objects.create(
        word_kh=staging_entry.word_kh,
    ...<9 lines>...
        created_by=request.user
    )
  File "C:\Users\phara\OneDrive\Desktop\FMIS\python\dictionary_project\venv\Lib\site-packages\django\db\models\manager.py", line 87, in manager_method
    return getattr(self.get_queryset(), name)(*args, **kwargs)
           ~~~~~~~~~~~~~~~~~~~~~~~~~~~~~~~~~~^^^^^^^^^^^^^^^^^
  File "C:\Users\phara\OneDrive\Desktop\FMIS\python\dictionary_project\venv\Lib\site-packages\django\db\models\query.py", line 679, in create
    obj.save(force_insert=True, using=self.db)
    ~~~~~~~~^^^^^^^^^^^^^^^^^^^^^^^^^^^^^^^^^^
  File "C:\Users\phara\OneDrive\Desktop\FMIS\python\dictionary_project\venv\Lib\site-packages\django\db\models\base.py", line 892, in save
    self.save_base(
    ~~~~~~~~~~~~~~^
        using=using,
        ^^^^^^^^^^^^
    ...<2 lines>...
        update_fields=update_fields,
        ^^^^^^^^^^^^^^^^^^^^^^^^^^^^
    )
    ^
  File "C:\Users\phara\OneDrive\Desktop\FMIS\python\dictionary_project\venv\Lib\site-packages\django\db\models\base.py", line 998, in save_base
    updated = self._save_table(
        raw,
    ...<4 lines>...
        update_fields,
    )
  File "C:\Users\phara\OneDrive\Desktop\FMIS\python\dictionary_project\venv\Lib\site-packages\django\db\models\base.py", line 1161, in _save_table
    results = self._do_insert(
        cls._base_manager, using, fields, returning_fields, raw
    )
  File "C:\Users\phara\OneDrive\Desktop\FMIS\python\dictionary_project\venv\Lib\site-packages\django\db\models\base.py", line 1202, in _do_insert
    return manager._insert(
           ~~~~~~~~~~~~~~~^
        [self],
        ^^^^^^^
    ...<3 lines>...
        raw=raw,
        ^^^^^^^^
    )
    ^
  File "C:\Users\phara\OneDrive\Desktop\FMIS\python\dictionary_project\venv\Lib\site-packages\django\db\models\manager.py", line 87, in manager_method
    return getattr(self.get_queryset(), name)(*args, **kwargs)
           ~~~~~~~~~~~~~~~~~~~~~~~~~~~~~~~~~~^^^^^^^^^^^^^^^^^
  File "C:\Users\phara\OneDrive\Desktop\FMIS\python\dictionary_project\venv\Lib\site-packages\django\db\models\query.py", line 1847, in _insert
    return query.get_compiler(using=using).execute_sql(returning_fields)
           ~~~~~~~~~~~~~~~~~~~~~~~~~~~~~~~~~~~~~~~~~~~^^^^^^^^^^^^^^^^^^
  File "C:\Users\phara\OneDrive\Desktop\FMIS\python\dictionary_project\venv\Lib\site-packages\django\db\models\sql\compiler.py", line 1836, in execute_sql
    cursor.execute(sql, params)
    ~~~~~~~~~~~~~~^^^^^^^^^^^^^
  File "C:\Users\phara\OneDrive\Desktop\FMIS\python\dictionary_project\venv\Lib\site-packages\django\db\backends\utils.py", line 122, in execute
    return super().execute(sql, params)
           ~~~~~~~~~~~~~~~^^^^^^^^^^^^^
  File "C:\Users\phara\OneDrive\Desktop\FMIS\python\dictionary_project\venv\Lib\site-packages\django\db\backends\utils.py", line 79, in execute
    return self._execute_with_wrappers(
           ~~~~~~~~~~~~~~~~~~~~~~~~~~~^
        sql, params, many=False, executor=self._execute
        ^^^^^^^^^^^^^^^^^^^^^^^^^^^^^^^^^^^^^^^^^^^^^^^
    )
    ^
  File "C:\Users\phara\OneDrive\Desktop\FMIS\python\dictionary_project\venv\Lib\site-packages\django\db\backends\utils.py", line 92, in _execute_with_wrappers
    return executor(sql, params, many, context)
  File "C:\Users\phara\OneDrive\Desktop\FMIS\python\dictionary_project\venv\Lib\site-packages\django\db\backends\utils.py", line 100, in _execute
    with self.db.wrap_database_errors:
         ^^^^^^^^^^^^^^^^^^^^^^^^^^^^
  File "C:\Users\phara\OneDrive\Desktop\FMIS\python\dictionary_project\venv\Lib\site-packages\django\db\utils.py", line 91, in __exit__
    raise dj_exc_value.with_traceback(traceback) from exc_value
  File "C:\Users\phara\OneDrive\Desktop\FMIS\python\dictionary_project\venv\Lib\site-packages\django\db\backends\utils.py", line 105, in _execute
    return self.cursor.execute(sql, params)
           ~~~~~~~~~~~~~~~~~~~^^^^^^^^^^^^^
  File "C:\Users\phara\OneDrive\Desktop\FMIS\python\dictionary_project\venv\Lib\site-packages\django\db\backends\mysql\base.py", line 76, in execute
    return self.cursor.execute(query, args)
           ~~~~~~~~~~~~~~~~~~~^^^^^^^^^^^^^
  File "C:\Users\phara\OneDrive\Desktop\FMIS\python\dictionary_project\venv\Lib\site-packages\MySQLdb\cursors.py", line 179, in execute
    res = self._query(mogrified_query)
  File "C:\Users\phara\OneDrive\Desktop\FMIS\python\dictionary_project\venv\Lib\site-packages\MySQLdb\cursors.py", line 330, in _query
    db.query(q)
    ~~~~~~~~^^^
  File "C:\Users\phara\OneDrive\Desktop\FMIS\python\dictionary_project\venv\Lib\site-packages\MySQLdb\connections.py", line 280, in query
    _mysql.connection.query(self, query)
    ~~~~~~~~~~~~~~~~~~~~~~~^^^^^^^^^^^^^
django.db.utils.IntegrityError: (1364, "Field 'index' doesn't have a default value")
"POST /api/dictionary/staging/1/approve/ HTTP/1.1" 500 241106
Internal Server Error: /api/dictionary/staging/1/approve/
Traceback (most recent call last):
  File "C:\Users\phara\OneDrive\Desktop\FMIS\python\dictionary_project\venv\Lib\site-packages\django\db\backends\utils.py", line 105, in _execute
    return self.cursor.execute(sql, params)
           ~~~~~~~~~~~~~~~~~~~^^^^^^^^^^^^^
  File "C:\Users\phara\OneDrive\Desktop\FMIS\python\dictionary_project\venv\Lib\site-packages\django\db\backends\mysql\base.py", line 76, in execute
    return self.cursor.execute(query, args)
           ~~~~~~~~~~~~~~~~~~~^^^^^^^^^^^^^
  File "C:\Users\phara\OneDrive\Desktop\FMIS\python\dictionary_project\venv\Lib\site-packages\MySQLdb\cursors.py", line 179, in execute
    res = self._query(mogrified_query)
  File "C:\Users\phara\OneDrive\Desktop\FMIS\python\dictionary_project\venv\Lib\site-packages\MySQLdb\cursors.py", line 330, in _query
    db.query(q)
    ~~~~~~~~^^^
  File "C:\Users\phara\OneDrive\Desktop\FMIS\python\dictionary_project\venv\Lib\site-packages\MySQLdb\connections.py", line 280, in query
    _mysql.connection.query(self, query)
    ~~~~~~~~~~~~~~~~~~~~~~~^^^^^^^^^^^^^
MySQLdb.IntegrityError: (1364, "Field 'index' doesn't have a default value")

The above exception was the direct cause of the following exception:

Traceback (most recent call last):
  File "C:\Users\phara\OneDrive\Desktop\FMIS\python\dictionary_project\venv\Lib\site-packages\django\core\handlers\exception.py", line 55, in inner
    response = get_response(request)
  File "C:\Users\phara\OneDrive\Desktop\FMIS\python\dictionary_project\venv\Lib\site-packages\django\core\handlers\base.py", line 197, in _get_response
    response = wrapped_callback(request, *callback_args, **callback_kwargs)
  File "C:\Users\phara\OneDrive\Desktop\FMIS\python\dictionary_project\venv\Lib\site-packages\django\views\decorators\csrf.py", line 65, in _view_wrapper
    return view_func(request, *args, **kwargs)
  File "C:\Users\phara\OneDrive\Desktop\FMIS\python\dictionary_project\venv\Lib\site-packages\django\views\generic\base.py", line 104, in view
    return self.dispatch(request, *args, **kwargs)
           ~~~~~~~~~~~~~^^^^^^^^^^^^^^^^^^^^^^^^^^
  File "C:\Users\phara\OneDrive\Desktop\FMIS\python\dictionary_project\venv\Lib\site-packages\rest_framework\views.py", line 509, in dispatch
    response = self.handle_exception(exc)
  File "C:\Users\phara\OneDrive\Desktop\FMIS\python\dictionary_project\venv\Lib\site-packages\rest_framework\views.py", line 469, in handle_exception
    self.raise_uncaught_exception(exc)
    ~~~~~~~~~~~~~~~~~~~~~~~~~~~~~^^^^^
  File "C:\Users\phara\OneDrive\Desktop\FMIS\python\dictionary_project\venv\Lib\site-packages\rest_framework\views.py", line 480, in raise_uncaught_exception
    raise exc
  File "C:\Users\phara\OneDrive\Desktop\FMIS\python\dictionary_project\venv\Lib\site-packages\rest_framework\views.py", line 506, in dispatch
    response = handler(request, *args, **kwargs)
  File "C:\Users\phara\OneDrive\Desktop\FMIS\python\dictionary_project\dictionary\views.py", line 279, in post
    dictionary_entry = Dictionary.objects.create(
        word_kh=staging_entry.word_kh,
    ...<9 lines>...
        created_by=request.user
    )
  File "C:\Users\phara\OneDrive\Desktop\FMIS\python\dictionary_project\venv\Lib\site-packages\django\db\models\manager.py", line 87, in manager_method
    return getattr(self.get_queryset(), name)(*args, **kwargs)
           ~~~~~~~~~~~~~~~~~~~~~~~~~~~~~~~~~~^^^^^^^^^^^^^^^^^
  File "C:\Users\phara\OneDrive\Desktop\FMIS\python\dictionary_project\venv\Lib\site-packages\django\db\models\query.py", line 679, in create
    obj.save(force_insert=True, using=self.db)
    ~~~~~~~~^^^^^^^^^^^^^^^^^^^^^^^^^^^^^^^^^^
  File "C:\Users\phara\OneDrive\Desktop\FMIS\python\dictionary_project\venv\Lib\site-packages\django\db\models\base.py", line 892, in save
    self.save_base(
    ~~~~~~~~~~~~~~^
        using=using,
        ^^^^^^^^^^^^
    ...<2 lines>...
        update_fields=update_fields,
        ^^^^^^^^^^^^^^^^^^^^^^^^^^^^
    )
    ^
  File "C:\Users\phara\OneDrive\Desktop\FMIS\python\dictionary_project\venv\Lib\site-packages\django\db\models\base.py", line 998, in save_base
    updated = self._save_table(
        raw,
    ...<4 lines>...
        update_fields,
    )
  File "C:\Users\phara\OneDrive\Desktop\FMIS\python\dictionary_project\venv\Lib\site-packages\django\db\models\base.py", line 1161, in _save_table
    results = self._do_insert(
        cls._base_manager, using, fields, returning_fields, raw
    )
  File "C:\Users\phara\OneDrive\Desktop\FMIS\python\dictionary_project\venv\Lib\site-packages\django\db\models\base.py", line 1202, in _do_insert
    return manager._insert(
           ~~~~~~~~~~~~~~~^
        [self],
        ^^^^^^^
    ...<3 lines>...
        raw=raw,
        ^^^^^^^^
    )
    ^
  File "C:\Users\phara\OneDrive\Desktop\FMIS\python\dictionary_project\venv\Lib\site-packages\django\db\models\manager.py", line 87, in manager_method
    return getattr(self.get_queryset(), name)(*args, **kwargs)
           ~~~~~~~~~~~~~~~~~~~~~~~~~~~~~~~~~~^^^^^^^^^^^^^^^^^
  File "C:\Users\phara\OneDrive\Desktop\FMIS\python\dictionary_project\venv\Lib\site-packages\django\db\models\query.py", line 1847, in _insert
    return query.get_compiler(using=using).execute_sql(returning_fields)
           ~~~~~~~~~~~~~~~~~~~~~~~~~~~~~~~~~~~~~~~~~~~^^^^^^^^^^^^^^^^^^
  File "C:\Users\phara\OneDrive\Desktop\FMIS\python\dictionary_project\venv\Lib\site-packages\django\db\models\sql\compiler.py", line 1836, in execute_sql
    cursor.execute(sql, params)
    ~~~~~~~~~~~~~~^^^^^^^^^^^^^
  File "C:\Users\phara\OneDrive\Desktop\FMIS\python\dictionary_project\venv\Lib\site-packages\django\db\backends\utils.py", line 122, in execute
    return super().execute(sql, params)
           ~~~~~~~~~~~~~~~^^^^^^^^^^^^^
  File "C:\Users\phara\OneDrive\Desktop\FMIS\python\dictionary_project\venv\Lib\site-packages\django\db\backends\utils.py", line 79, in execute
    return self._execute_with_wrappers(
           ~~~~~~~~~~~~~~~~~~~~~~~~~~~^
        sql, params, many=False, executor=self._execute
        ^^^^^^^^^^^^^^^^^^^^^^^^^^^^^^^^^^^^^^^^^^^^^^^
    )
    ^
  File "C:\Users\phara\OneDrive\Desktop\FMIS\python\dictionary_project\venv\Lib\site-packages\django\db\backends\utils.py", line 92, in _execute_with_wrappers
    return executor(sql, params, many, context)
  File "C:\Users\phara\OneDrive\Desktop\FMIS\python\dictionary_project\venv\Lib\site-packages\django\db\backends\utils.py", line 100, in _execute
    with self.db.wrap_database_errors:
         ^^^^^^^^^^^^^^^^^^^^^^^^^^^^
  File "C:\Users\phara\OneDrive\Desktop\FMIS\python\dictionary_project\venv\Lib\site-packages\django\db\utils.py", line 91, in __exit__
    raise dj_exc_value.with_traceback(traceback) from exc_value
  File "C:\Users\phara\OneDrive\Desktop\FMIS\python\dictionary_project\venv\Lib\site-packages\django\db\backends\utils.py", line 105, in _execute
    return self.cursor.execute(sql, params)
           ~~~~~~~~~~~~~~~~~~~^^^^^^^^^^^^^
  File "C:\Users\phara\OneDrive\Desktop\FMIS\python\dictionary_project\venv\Lib\site-packages\django\db\backends\mysql\base.py", line 76, in execute
    return self.cursor.execute(query, args)
           ~~~~~~~~~~~~~~~~~~~^^^^^^^^^^^^^
  File "C:\Users\phara\OneDrive\Desktop\FMIS\python\dictionary_project\venv\Lib\site-packages\MySQLdb\cursors.py", line 179, in execute
    res = self._query(mogrified_query)
  File "C:\Users\phara\OneDrive\Desktop\FMIS\python\dictionary_project\venv\Lib\site-packages\MySQLdb\cursors.py", line 330, in _query
    db.query(q)
    ~~~~~~~~^^^
  File "C:\Users\phara\OneDrive\Desktop\FMIS\python\dictionary_project\venv\Lib\site-packages\MySQLdb\connections.py", line 280, in query
    _mysql.connection.query(self, query)
    ~~~~~~~~~~~~~~~~~~~~~~~^^^^^^^^^^^^^
django.db.utils.IntegrityError: (1364, "Field 'index' doesn't have a default value")
"POST /api/dictionary/staging/1/approve/ HTTP/1.1" 500 241121
Internal Server Error: /api/dictionary/staging/1/approve/
"POST /api/dictionary/staging/1/approve/ HTTP/1.1" 500 55
Internal Server Error: /api/dictionary/staging/1/approve/
"POST /api/dictionary/staging/1/approve/ HTTP/1.1" 500 55
Internal Server Error: /api/dictionary/staging/1/approve/
"POST /api/dictionary/staging/1/approve/ HTTP/1.1" 500 55
Internal Server Error: /api/dictionary/staging/1/approve/
"POST /api/dictionary/staging/1/approve/ HTTP/1.1" 500 55
Internal Server Error: /api/dictionary/staging/1/approve/
"POST /api/dictionary/staging/1/approve/ HTTP/1.1" 500 55
Internal Server Error: /api/dictionary/staging/1/approve/
"POST /api/dictionary/staging/1/approve/ HTTP/1.1" 500 55
Internal Server Error: /api/dictionary/staging/1/approve/
"POST /api/dictionary/staging/1/approve/ HTTP/1.1" 500 55
Internal Server Error: /api/dictionary/staging/1/approve/
"POST /api/dictionary/staging/1/approve/ HTTP/1.1" 500 55
Internal Server Error: /api/dictionary/staging/1/approve/
"POST /api/dictionary/staging/1/approve/ HTTP/1.1" 500 55
Internal Server Error: /api/dictionary/staging/1/approve/
"POST /api/dictionary/staging/1/approve/ HTTP/1.1" 500 55
Internal Server Error: /api/dictionary/staging/1/approve/
"POST /api/dictionary/staging/1/approve/ HTTP/1.1" 500 55
Internal Server Error: /api/dictionary/staging/1/approve/
"POST /api/dictionary/staging/1/approve/ HTTP/1.1" 500 55
Internal Server Error: /api/dictionary/staging/1/approve/
"POST /api/dictionary/staging/1/approve/ HTTP/1.1" 500 55
Internal Server Error: /api/dictionary/staging/2/approve/
"POST /api/dictionary/staging/2/approve/ HTTP/1.1" 500 55
Internal Server Error: /api/dictionary/staging/2/approve/
"POST /api/dictionary/staging/2/approve/ HTTP/1.1" 500 55
Internal Server Error: /api/dictionary/staging/2/approve/
"POST /api/dictionary/staging/2/approve/ HTTP/1.1" 500 55
Internal Server Error: /api/dictionary/staging/2/approve/
"POST /api/dictionary/staging/2/approve/ HTTP/1.1" 500 55
Internal Server Error: /api/dictionary/staging/2/approve/
"POST /api/dictionary/staging/2/approve/ HTTP/1.1" 500 55
Internal Server Error: /api/dictionary/staging/2/approve/
"POST /api/dictionary/staging/2/approve/ HTTP/1.1" 500 55
Internal Server Error: /api/dictionary/staging/2/approve/
"POST /api/dictionary/staging/2/approve/ HTTP/1.1" 500 55
Internal Server Error: /api/dictionary/staging/2/approve/
"POST /api/dictionary/staging/2/approve/ HTTP/1.1" 500 55
Internal Server Error: /api/dictionary/staging/2/approve/
"POST /api/dictionary/staging/2/approve/ HTTP/1.1" 500 55
Internal Server Error: /api/dictionary/staging/3/approve/
"POST /api/dictionary/staging/3/approve/ HTTP/1.1" 500 55
Internal Server Error: /api/dictionary/staging/3/approve/
"POST /api/dictionary/staging/3/approve/ HTTP/1.1" 500 55
Internal Server Error: /api/dictionary/staging/3/approve/
"POST /api/dictionary/staging/3/approve/ HTTP/1.1" 500 55
Internal Server Error: /api/dictionary/staging/3/approve/
"POST /api/dictionary/staging/3/approve/ HTTP/1.1" 500 55
Internal Server Error: /api/dictionary/staging/3/approve/
"POST /api/dictionary/staging/3/approve/ HTTP/1.1" 500 55
Internal Server Error: /api/dictionary/staging/3/approve/
"POST /api/dictionary/staging/3/approve/ HTTP/1.1" 500 55
Internal Server Error: /api/dictionary/staging/4/approve/
"POST /api/dictionary/staging/4/approve/ HTTP/1.1" 500 55
Internal Server Error: /api/dictionary/staging/4/approve/
"POST /api/dictionary/staging/4/approve/ HTTP/1.1" 500 55
Internal Server Error: /api/dictionary/staging/4/approve/
"POST /api/dictionary/staging/4/approve/ HTTP/1.1" 500 55
Internal Server Error: /api/dictionary/staging/4/approve/
"POST /api/dictionary/staging/4/approve/ HTTP/1.1" 500 55
Internal Server Error: /api/dictionary/staging/4/approve/
"POST /api/dictionary/staging/4/approve/ HTTP/1.1" 500 55
Internal Server Error: /api/dictionary/list/
Traceback (most recent call last):
  File "C:\Users\phara\OneDrive\Desktop\FMIS\python\dictionary_project\venv\Lib\site-packages\django\core\handlers\exception.py", line 55, in inner
    response = get_response(request)
  File "C:\Users\phara\OneDrive\Desktop\FMIS\python\dictionary_project\venv\Lib\site-packages\django\core\handlers\base.py", line 197, in _get_response
    response = wrapped_callback(request, *callback_args, **callback_kwargs)
  File "C:\Users\phara\OneDrive\Desktop\FMIS\python\dictionary_project\venv\Lib\site-packages\django\views\decorators\csrf.py", line 65, in _view_wrapper
    return view_func(request, *args, **kwargs)
  File "C:\Users\phara\OneDrive\Desktop\FMIS\python\dictionary_project\venv\Lib\site-packages\django\views\generic\base.py", line 104, in view
    return self.dispatch(request, *args, **kwargs)
           ~~~~~~~~~~~~~^^^^^^^^^^^^^^^^^^^^^^^^^^
  File "C:\Users\phara\OneDrive\Desktop\FMIS\python\dictionary_project\venv\Lib\site-packages\rest_framework\views.py", line 509, in dispatch
    response = self.handle_exception(exc)
  File "C:\Users\phara\OneDrive\Desktop\FMIS\python\dictionary_project\venv\Lib\site-packages\rest_framework\views.py", line 469, in handle_exception
    self.raise_uncaught_exception(exc)
    ~~~~~~~~~~~~~~~~~~~~~~~~~~~~~^^^^^
  File "C:\Users\phara\OneDrive\Desktop\FMIS\python\dictionary_project\venv\Lib\site-packages\rest_framework\views.py", line 480, in raise_uncaught_exception
    raise exc
  File "C:\Users\phara\OneDrive\Desktop\FMIS\python\dictionary_project\venv\Lib\site-packages\rest_framework\views.py", line 506, in dispatch
    response = handler(request, *args, **kwargs)
  File "C:\Users\phara\OneDrive\Desktop\FMIS\python\dictionary_project\dictionary\views.py", line 85, in get
    return Response(serializer.data)
                    ^^^^^^^^^^^^^^^
  File "C:\Users\phara\OneDrive\Desktop\FMIS\python\dictionary_project\venv\Lib\site-packages\rest_framework\serializers.py", line 795, in data
    ret = super().data
          ^^^^^^^^^^^^
  File "C:\Users\phara\OneDrive\Desktop\FMIS\python\dictionary_project\venv\Lib\site-packages\rest_framework\serializers.py", line 249, in data
    self._data = self.to_representation(self.instance)
                 ~~~~~~~~~~~~~~~~~~~~~~^^^^^^^^^^^^^^^
  File "C:\Users\phara\OneDrive\Desktop\FMIS\python\dictionary_project\venv\Lib\site-packages\rest_framework\serializers.py", line 714, in to_representation
    self.child.to_representation(item) for item in iterable
    ~~~~~~~~~~~~~~~~~~~~~~~~~~~~^^^^^^
  File "C:\Users\phara\OneDrive\Desktop\FMIS\python\dictionary_project\venv\Lib\site-packages\rest_framework\serializers.py", line 523, in to_representation
    for field in fields:
                 ^^^^^^
  File "C:\Users\phara\OneDrive\Desktop\FMIS\python\dictionary_project\venv\Lib\site-packages\rest_framework\serializers.py", line 384, in _readable_fields
    for field in self.fields.values():
                 ^^^^^^^^^^^
  File "C:\Users\phara\OneDrive\Desktop\FMIS\python\dictionary_project\venv\Lib\site-packages\django\utils\functional.py", line 47, in __get__
    res = instance.__dict__[self.name] = self.func(instance)
                                         ~~~~~~~~~^^^^^^^^^^
  File "C:\Users\phara\OneDrive\Desktop\FMIS\python\dictionary_project\venv\Lib\site-packages\rest_framework\serializers.py", line 372, in fields
    for key, value in self.get_fields().items():
                      ~~~~~~~~~~~~~~~^^
  File "C:\Users\phara\OneDrive\Desktop\FMIS\python\dictionary_project\venv\Lib\site-packages\rest_framework\serializers.py", line 1103, in get_fields
    field_class, field_kwargs = self.build_field(
                                ~~~~~~~~~~~~~~~~^
        source, info, model, depth
        ^^^^^^^^^^^^^^^^^^^^^^^^^^
    )
    ^
  File "C:\Users\phara\OneDrive\Desktop\FMIS\python\dictionary_project\venv\Lib\site-packages\rest_framework\serializers.py", line 1249, in build_field
    return self.build_unknown_field(field_name, model_class)
           ~~~~~~~~~~~~~~~~~~~~~~~~^^^^^^^^^^^^^^^^^^^^^^^^^
  File "C:\Users\phara\OneDrive\Desktop\FMIS\python\dictionary_project\venv\Lib\site-packages\rest_framework\serializers.py", line 1367, in build_unknown_field
    raise ImproperlyConfigured(
    ...<2 lines>...
    )
django.core.exceptions.ImproperlyConfigured: Field name `id` is not valid for model `Dictionary` in `dictionary.serializers.DictionaryEntrySerializer`.
"GET /api/dictionary/list/ HTTP/1.1" 500 157360
Internal Server Error: /api/dictionary/bookmarks/
"POST /api/dictionary/bookmarks/ HTTP/1.1" 500 40
Internal Server Error: /api/dictionary/bookmarks/
"POST /api/dictionary/bookmarks/ HTTP/1.1" 500 40
Internal Server Error: /api/dictionary/bookmarks/
"POST /api/dictionary/bookmarks/ HTTP/1.1" 500 40
Internal Server Error: /api/dictionary/bookmarks/
"POST /api/dictionary/bookmarks/ HTTP/1.1" 500 40
Internal Server Error: /api/dictionary/bookmarks/
"POST /api/dictionary/bookmarks/ HTTP/1.1" 500 40
Internal Server Error: /api/dictionary/bookmarks/
"POST /api/dictionary/bookmarks/ HTTP/1.1" 500 40
Internal Server Error: /api/dictionary/bookmarks/
"POST /api/dictionary/bookmarks/ HTTP/1.1" 500 40
Internal Server Error: /api/dictionary/bookmarks/
"POST /api/dictionary/bookmarks/ HTTP/1.1" 500 40
Internal Server Error: /api/dictionary/bookmarks/
"POST /api/dictionary/bookmarks/ HTTP/1.1" 500 40
Internal Server Error: /api/dictionary/bookmarks/
"POST /api/dictionary/bookmarks/ HTTP/1.1" 500 40
Internal Server Error: /api/dictionary/bookmarks/
"POST /api/dictionary/bookmarks/ HTTP/1.1" 500 40
Internal Server Error: /api/dictionary/bookmarks/
"POST /api/dictionary/bookmarks/ HTTP/1.1" 500 40
Internal Server Error: /api/dictionary/bookmarks/
"POST /api/dictionary/bookmarks/ HTTP/1.1" 500 40
Internal Server Error: /api/dictionary/bookmarks/
"POST /api/dictionary/bookmarks/ HTTP/1.1" 500 337
Internal Server Error: /api/dictionary/bookmarks/
"POST /api/dictionary/bookmarks/ HTTP/1.1" 500 40
