[2025-04-02 09:38:24,732] ERROR views 2320 13916 - Unexpected token blacklist error: {'detail': ErrorDetail(string='Token is blacklisted', code='token_not_valid'), 'code': ErrorDetail(string='token_not_valid', code='token_not_valid')}
[2025-04-02 09:38:24,733] ERROR log 2320 13916 - Internal Server Error: /api/token/blacklist/
[2025-04-02 09:38:24,733] ERROR basehttp 2320 13916 - "POST /api/token/blacklist/ HTTP/1.1" 500 67
[2025-04-02 10:34:46,124] ERROR views 15168 1716 - Bulk import error: [WinError 10061] No connection could be made because the target machine actively refused it
Traceback (most recent call last):
  File "C:\Users\phara\OneDrive\Desktop\FMIS\python\dictionary_project\venv\Lib\site-packages\kombu\utils\functional.py", line 32, in __call__
    return self.__value__
           ^^^^^^^^^^^^^^
AttributeError: 'ChannelPromise' object has no attribute '__value__'. Did you mean: '__call__'?

During handling of the above exception, another exception occurred:

Traceback (most recent call last):
  File "C:\Users\phara\OneDrive\Desktop\FMIS\python\dictionary_project\venv\Lib\site-packages\kombu\connection.py", line 472, in _reraise_as_library_errors
    yield
  File "C:\Users\phara\OneDrive\Desktop\FMIS\python\dictionary_project\venv\Lib\site-packages\kombu\connection.py", line 459, in _ensure_connection
    return retry_over_time(
        self._connection_factory, self.recoverable_connection_errors,
    ...<2 lines>...
        callback, timeout=timeout
    )
  File "C:\Users\phara\OneDrive\Desktop\FMIS\python\dictionary_project\venv\Lib\site-packages\kombu\utils\functional.py", line 318, in retry_over_time
    return fun(*args, **kwargs)
  File "C:\Users\phara\OneDrive\Desktop\FMIS\python\dictionary_project\venv\Lib\site-packages\kombu\connection.py", line 938, in _connection_factory
    self._connection = self._establish_connection()
                       ~~~~~~~~~~~~~~~~~~~~~~~~~~^^
  File "C:\Users\phara\OneDrive\Desktop\FMIS\python\dictionary_project\venv\Lib\site-packages\kombu\connection.py", line 860, in _establish_connection
    conn = self.transport.establish_connection()
  File "C:\Users\phara\OneDrive\Desktop\FMIS\python\dictionary_project\venv\Lib\site-packages\kombu\transport\pyamqp.py", line 203, in establish_connection
    conn.connect()
    ~~~~~~~~~~~~^^
  File "C:\Users\phara\OneDrive\Desktop\FMIS\python\dictionary_project\venv\Lib\site-packages\amqp\connection.py", line 324, in connect
    self.transport.connect()
    ~~~~~~~~~~~~~~~~~~~~~~^^
  File "C:\Users\phara\OneDrive\Desktop\FMIS\python\dictionary_project\venv\Lib\site-packages\amqp\transport.py", line 132, in connect
    self._connect(self.host, self.port, self.connect_timeout)
    ~~~~~~~~~~~~~^^^^^^^^^^^^^^^^^^^^^^^^^^^^^^^^^^^^^^^^^^^^
  File "C:\Users\phara\OneDrive\Desktop\FMIS\python\dictionary_project\venv\Lib\site-packages\amqp\transport.py", line 187, in _connect
    self.sock.connect(sa)
    ~~~~~~~~~~~~~~~~~^^^^
ConnectionRefusedError: [WinError 10061] No connection could be made because the target machine actively refused it

The above exception was the direct cause of the following exception:

Traceback (most recent call last):
  File "C:\Users\phara\OneDrive\Desktop\FMIS\python\dictionary_project\dictionary\views.py", line 980, in post
    process_staging_bulk_import.delay(
    ~~~~~~~~~~~~~~~~~~~~~~~~~~~~~~~~~^
        file_path=self.save_temporary_file(excel_file),
        ^^^^^^^^^^^^^^^^^^^^^^^^^^^^^^^^^^^^^^^^^^^^^^^
        user_id=request.user.id,
        ^^^^^^^^^^^^^^^^^^^^^^^^
        task_id=task_id
        ^^^^^^^^^^^^^^^
    )
    ^
  File "C:\Users\phara\OneDrive\Desktop\FMIS\python\dictionary_project\venv\Lib\site-packages\celery\app\task.py", line 444, in delay
    return self.apply_async(args, kwargs)
           ~~~~~~~~~~~~~~~~^^^^^^^^^^^^^^
  File "C:\Users\phara\OneDrive\Desktop\FMIS\python\dictionary_project\venv\Lib\site-packages\celery\app\task.py", line 601, in apply_async
    return app.send_task(
           ~~~~~~~~~~~~~^
        self.name, args, kwargs, task_id=task_id, producer=producer,
        ^^^^^^^^^^^^^^^^^^^^^^^^^^^^^^^^^^^^^^^^^^^^^^^^^^^^^^^^^^^^
    ...<2 lines>...
        **options
        ^^^^^^^^^
    )
    ^
  File "C:\Users\phara\OneDrive\Desktop\FMIS\python\dictionary_project\venv\Lib\site-packages\celery\app\base.py", line 922, in send_task
    amqp.send_task_message(P, name, message, **options)
    ~~~~~~~~~~~~~~~~~~~~~~^^^^^^^^^^^^^^^^^^^^^^^^^^^^^
  File "C:\Users\phara\OneDrive\Desktop\FMIS\python\dictionary_project\venv\Lib\site-packages\celery\app\amqp.py", line 523, in send_task_message
    ret = producer.publish(
        body,
    ...<8 lines>...
        **properties
    )
  File "C:\Users\phara\OneDrive\Desktop\FMIS\python\dictionary_project\venv\Lib\site-packages\kombu\messaging.py", line 190, in publish
    return _publish(
        body, priority, content_type, content_encoding,
        headers, properties, routing_key, mandatory, immediate,
        exchange_name, declare, timeout, confirm_timeout, retry, retry_policy
    )
  File "C:\Users\phara\OneDrive\Desktop\FMIS\python\dictionary_project\venv\Lib\site-packages\kombu\connection.py", line 556, in _ensured
    return fun(*args, **kwargs)
  File "C:\Users\phara\OneDrive\Desktop\FMIS\python\dictionary_project\venv\Lib\site-packages\kombu\messaging.py", line 200, in _publish
    channel = self.channel
              ^^^^^^^^^^^^
  File "C:\Users\phara\OneDrive\Desktop\FMIS\python\dictionary_project\venv\Lib\site-packages\kombu\messaging.py", line 224, in _get_channel
    channel = self._channel = channel()
                              ~~~~~~~^^
  File "C:\Users\phara\OneDrive\Desktop\FMIS\python\dictionary_project\venv\Lib\site-packages\kombu\utils\functional.py", line 34, in __call__
    value = self.__value__ = self.__contract__()
                             ~~~~~~~~~~~~~~~~~^^
  File "C:\Users\phara\OneDrive\Desktop\FMIS\python\dictionary_project\venv\Lib\site-packages\kombu\messaging.py", line 240, in <lambda>
    channel = ChannelPromise(lambda: connection.default_channel)
                                     ^^^^^^^^^^^^^^^^^^^^^^^^^^
  File "C:\Users\phara\OneDrive\Desktop\FMIS\python\dictionary_project\venv\Lib\site-packages\kombu\connection.py", line 957, in default_channel
    self._ensure_connection(**conn_opts)
    ~~~~~~~~~~~~~~~~~~~~~~~^^^^^^^^^^^^^
  File "C:\Users\phara\OneDrive\Desktop\FMIS\python\dictionary_project\venv\Lib\site-packages\kombu\connection.py", line 458, in _ensure_connection
    with ctx():
         ~~~^^
  File "C:\Users\phara\AppData\Local\Programs\Python\Python313\Lib\contextlib.py", line 162, in __exit__
    self.gen.throw(value)
    ~~~~~~~~~~~~~~^^^^^^^
  File "C:\Users\phara\OneDrive\Desktop\FMIS\python\dictionary_project\venv\Lib\site-packages\kombu\connection.py", line 476, in _reraise_as_library_errors
    raise ConnectionError(str(exc)) from exc
kombu.exceptions.OperationalError: [WinError 10061] No connection could be made because the target machine actively refused it
[2025-04-02 10:34:46,277] ERROR log 15168 1716 - Internal Server Error: /api/dictionary/staging/bulk_import/
[2025-04-02 10:34:46,278] ERROR basehttp 15168 1716 - "POST /api/dictionary/staging/bulk_import/ HTTP/1.1" 500 139
[2025-04-02 10:34:59,270] ERROR views 15168 1716 - Bulk import error: [WinError 10061] No connection could be made because the target machine actively refused it
Traceback (most recent call last):
  File "C:\Users\phara\OneDrive\Desktop\FMIS\python\dictionary_project\venv\Lib\site-packages\kombu\utils\functional.py", line 32, in __call__
    return self.__value__
           ^^^^^^^^^^^^^^
AttributeError: 'ChannelPromise' object has no attribute '__value__'. Did you mean: '__call__'?

During handling of the above exception, another exception occurred:

Traceback (most recent call last):
  File "C:\Users\phara\OneDrive\Desktop\FMIS\python\dictionary_project\venv\Lib\site-packages\kombu\connection.py", line 472, in _reraise_as_library_errors
    yield
  File "C:\Users\phara\OneDrive\Desktop\FMIS\python\dictionary_project\venv\Lib\site-packages\kombu\connection.py", line 459, in _ensure_connection
    return retry_over_time(
        self._connection_factory, self.recoverable_connection_errors,
    ...<2 lines>...
        callback, timeout=timeout
    )
  File "C:\Users\phara\OneDrive\Desktop\FMIS\python\dictionary_project\venv\Lib\site-packages\kombu\utils\functional.py", line 318, in retry_over_time
    return fun(*args, **kwargs)
  File "C:\Users\phara\OneDrive\Desktop\FMIS\python\dictionary_project\venv\Lib\site-packages\kombu\connection.py", line 938, in _connection_factory
    self._connection = self._establish_connection()
                       ~~~~~~~~~~~~~~~~~~~~~~~~~~^^
  File "C:\Users\phara\OneDrive\Desktop\FMIS\python\dictionary_project\venv\Lib\site-packages\kombu\connection.py", line 860, in _establish_connection
    conn = self.transport.establish_connection()
  File "C:\Users\phara\OneDrive\Desktop\FMIS\python\dictionary_project\venv\Lib\site-packages\kombu\transport\pyamqp.py", line 203, in establish_connection
    conn.connect()
    ~~~~~~~~~~~~^^
  File "C:\Users\phara\OneDrive\Desktop\FMIS\python\dictionary_project\venv\Lib\site-packages\amqp\connection.py", line 324, in connect
    self.transport.connect()
    ~~~~~~~~~~~~~~~~~~~~~~^^
  File "C:\Users\phara\OneDrive\Desktop\FMIS\python\dictionary_project\venv\Lib\site-packages\amqp\transport.py", line 132, in connect
    self._connect(self.host, self.port, self.connect_timeout)
    ~~~~~~~~~~~~~^^^^^^^^^^^^^^^^^^^^^^^^^^^^^^^^^^^^^^^^^^^^
  File "C:\Users\phara\OneDrive\Desktop\FMIS\python\dictionary_project\venv\Lib\site-packages\amqp\transport.py", line 187, in _connect
    self.sock.connect(sa)
    ~~~~~~~~~~~~~~~~~^^^^
ConnectionRefusedError: [WinError 10061] No connection could be made because the target machine actively refused it

The above exception was the direct cause of the following exception:

Traceback (most recent call last):
  File "C:\Users\phara\OneDrive\Desktop\FMIS\python\dictionary_project\dictionary\views.py", line 980, in post
    process_staging_bulk_import.delay(
    ~~~~~~~~~~~~~~~~~~~~~~~~~~~~~~~~~^
        file_path=self.save_temporary_file(excel_file),
        ^^^^^^^^^^^^^^^^^^^^^^^^^^^^^^^^^^^^^^^^^^^^^^^
        user_id=request.user.id,
        ^^^^^^^^^^^^^^^^^^^^^^^^
        task_id=task_id
        ^^^^^^^^^^^^^^^
    )
    ^
  File "C:\Users\phara\OneDrive\Desktop\FMIS\python\dictionary_project\venv\Lib\site-packages\celery\app\task.py", line 444, in delay
    return self.apply_async(args, kwargs)
           ~~~~~~~~~~~~~~~~^^^^^^^^^^^^^^
  File "C:\Users\phara\OneDrive\Desktop\FMIS\python\dictionary_project\venv\Lib\site-packages\celery\app\task.py", line 601, in apply_async
    return app.send_task(
           ~~~~~~~~~~~~~^
        self.name, args, kwargs, task_id=task_id, producer=producer,
        ^^^^^^^^^^^^^^^^^^^^^^^^^^^^^^^^^^^^^^^^^^^^^^^^^^^^^^^^^^^^
    ...<2 lines>...
        **options
        ^^^^^^^^^
    )
    ^
  File "C:\Users\phara\OneDrive\Desktop\FMIS\python\dictionary_project\venv\Lib\site-packages\celery\app\base.py", line 922, in send_task
    amqp.send_task_message(P, name, message, **options)
    ~~~~~~~~~~~~~~~~~~~~~~^^^^^^^^^^^^^^^^^^^^^^^^^^^^^
  File "C:\Users\phara\OneDrive\Desktop\FMIS\python\dictionary_project\venv\Lib\site-packages\celery\app\amqp.py", line 523, in send_task_message
    ret = producer.publish(
        body,
    ...<8 lines>...
        **properties
    )
  File "C:\Users\phara\OneDrive\Desktop\FMIS\python\dictionary_project\venv\Lib\site-packages\kombu\messaging.py", line 190, in publish
    return _publish(
        body, priority, content_type, content_encoding,
        headers, properties, routing_key, mandatory, immediate,
        exchange_name, declare, timeout, confirm_timeout, retry, retry_policy
    )
  File "C:\Users\phara\OneDrive\Desktop\FMIS\python\dictionary_project\venv\Lib\site-packages\kombu\connection.py", line 556, in _ensured
    return fun(*args, **kwargs)
  File "C:\Users\phara\OneDrive\Desktop\FMIS\python\dictionary_project\venv\Lib\site-packages\kombu\messaging.py", line 200, in _publish
    channel = self.channel
              ^^^^^^^^^^^^
  File "C:\Users\phara\OneDrive\Desktop\FMIS\python\dictionary_project\venv\Lib\site-packages\kombu\messaging.py", line 224, in _get_channel
    channel = self._channel = channel()
                              ~~~~~~~^^
  File "C:\Users\phara\OneDrive\Desktop\FMIS\python\dictionary_project\venv\Lib\site-packages\kombu\utils\functional.py", line 34, in __call__
    value = self.__value__ = self.__contract__()
                             ~~~~~~~~~~~~~~~~~^^
  File "C:\Users\phara\OneDrive\Desktop\FMIS\python\dictionary_project\venv\Lib\site-packages\kombu\messaging.py", line 240, in <lambda>
    channel = ChannelPromise(lambda: connection.default_channel)
                                     ^^^^^^^^^^^^^^^^^^^^^^^^^^
  File "C:\Users\phara\OneDrive\Desktop\FMIS\python\dictionary_project\venv\Lib\site-packages\kombu\connection.py", line 957, in default_channel
    self._ensure_connection(**conn_opts)
    ~~~~~~~~~~~~~~~~~~~~~~~^^^^^^^^^^^^^
  File "C:\Users\phara\OneDrive\Desktop\FMIS\python\dictionary_project\venv\Lib\site-packages\kombu\connection.py", line 458, in _ensure_connection
    with ctx():
         ~~~^^
  File "C:\Users\phara\AppData\Local\Programs\Python\Python313\Lib\contextlib.py", line 162, in __exit__
    self.gen.throw(value)
    ~~~~~~~~~~~~~~^^^^^^^
  File "C:\Users\phara\OneDrive\Desktop\FMIS\python\dictionary_project\venv\Lib\site-packages\kombu\connection.py", line 476, in _reraise_as_library_errors
    raise ConnectionError(str(exc)) from exc
kombu.exceptions.OperationalError: [WinError 10061] No connection could be made because the target machine actively refused it
[2025-04-02 10:34:59,311] ERROR log 15168 1716 - Internal Server Error: /api/dictionary/staging/bulk_import/
[2025-04-02 10:34:59,311] ERROR basehttp 15168 1716 - "POST /api/dictionary/staging/bulk_import/ HTTP/1.1" 500 139
[2025-04-02 10:37:42,501] ERROR log 19252 2360 - Internal Server Error: /swagger/
Traceback (most recent call last):
  File "C:\Users\phara\OneDrive\Desktop\FMIS\python\dictionary_project\venv\Lib\site-packages\django\core\handlers\exception.py", line 55, in inner
    response = get_response(request)
  File "C:\Users\phara\OneDrive\Desktop\FMIS\python\dictionary_project\venv\Lib\site-packages\django\core\handlers\base.py", line 197, in _get_response
    response = wrapped_callback(request, *callback_args, **callback_kwargs)
  File "C:\Users\phara\OneDrive\Desktop\FMIS\python\dictionary_project\venv\Lib\site-packages\django\views\decorators\csrf.py", line 65, in _view_wrapper
    return view_func(request, *args, **kwargs)
  File "C:\Users\phara\OneDrive\Desktop\FMIS\python\dictionary_project\venv\Lib\site-packages\django\views\generic\base.py", line 104, in view
    return self.dispatch(request, *args, **kwargs)
           ~~~~~~~~~~~~~^^^^^^^^^^^^^^^^^^^^^^^^^^
  File "C:\Users\phara\OneDrive\Desktop\FMIS\python\dictionary_project\venv\Lib\site-packages\rest_framework\views.py", line 509, in dispatch
    response = self.handle_exception(exc)
  File "C:\Users\phara\OneDrive\Desktop\FMIS\python\dictionary_project\venv\Lib\site-packages\rest_framework\views.py", line 469, in handle_exception
    self.raise_uncaught_exception(exc)
    ~~~~~~~~~~~~~~~~~~~~~~~~~~~~~^^^^^
  File "C:\Users\phara\OneDrive\Desktop\FMIS\python\dictionary_project\venv\Lib\site-packages\rest_framework\views.py", line 480, in raise_uncaught_exception
    raise exc
  File "C:\Users\phara\OneDrive\Desktop\FMIS\python\dictionary_project\venv\Lib\site-packages\rest_framework\views.py", line 506, in dispatch
    response = handler(request, *args, **kwargs)
  File "C:\Users\phara\OneDrive\Desktop\FMIS\python\dictionary_project\venv\Lib\site-packages\drf_yasg\views.py", line 112, in get
    schema = generator.get_schema(request, self.public)
  File "C:\Users\phara\OneDrive\Desktop\FMIS\python\dictionary_project\venv\Lib\site-packages\drf_yasg\generators.py", line 276, in get_schema
    paths, prefix = self.get_paths(endpoints, components, request, public)
                    ~~~~~~~~~~~~~~^^^^^^^^^^^^^^^^^^^^^^^^^^^^^^^^^^^^^^^^
  File "C:\Users\phara\OneDrive\Desktop\FMIS\python\dictionary_project\venv\Lib\site-packages\drf_yasg\generators.py", line 482, in get_paths
    operation = self.get_operation(view, path, prefix, method, components, request)
  File "C:\Users\phara\OneDrive\Desktop\FMIS\python\dictionary_project\venv\Lib\site-packages\drf_yasg\generators.py", line 524, in get_operation
    operation = view_inspector.get_operation(operation_keys)
  File "C:\Users\phara\OneDrive\Desktop\FMIS\python\dictionary_project\venv\Lib\site-packages\drf_yasg\inspectors\view.py", line 36, in get_operation
    parameters = self.add_manual_parameters(parameters)
  File "C:\Users\phara\OneDrive\Desktop\FMIS\python\dictionary_project\venv\Lib\site-packages\drf_yasg\inspectors\view.py", line 166, in add_manual_parameters
    raise SwaggerGenerationError("cannot add form parameters when the request has a request body; "
                                 "did you forget to set an appropriate parser class on the view?")
drf_yasg.errors.SwaggerGenerationError: cannot add form parameters when the request has a request body; did you forget to set an appropriate parser class on the view?
[2025-04-02 10:37:42,514] ERROR basehttp 19252 2360 - "GET /swagger/?format=openapi HTTP/1.1" 500 161204
[2025-04-02 10:56:19,713] ERROR views 4384 19180 - Error approving staging entry: Dictionary() got unexpected keyword arguments: 'index'
[2025-04-02 10:56:19,714] ERROR log 4384 19180 - Internal Server Error: /api/dictionary/staging/8/approve/
[2025-04-02 10:56:19,715] ERROR basehttp 4384 19180 - "POST /api/dictionary/staging/8/approve/ HTTP/1.1" 500 55
[2025-04-02 11:01:56,135] ERROR views 12492 10576 - Error approving staging entry: (1364, "Field 'index' doesn't have a default value")
[2025-04-02 11:01:56,136] ERROR log 12492 10576 - Internal Server Error: /api/dictionary/staging/8/approve/
[2025-04-02 11:01:56,137] ERROR basehttp 12492 10576 - "POST /api/dictionary/staging/8/approve/ HTTP/1.1" 500 55
[2025-04-02 11:03:21,432] ERROR views 2788 8472 - Error approving staging entry: (1054, "Unknown column 'dictionary_staging.index' in 'field list'")
[2025-04-02 11:03:21,433] ERROR log 2788 8472 - Internal Server Error: /api/dictionary/staging/8/approve/
[2025-04-02 11:03:21,434] ERROR basehttp 2788 8472 - "POST /api/dictionary/staging/8/approve/ HTTP/1.1" 500 55
[2025-04-02 11:11:58,459] ERROR views 10620 1716 - Search Error: Field name `id` is not valid for model `Dictionary` in `dictionary.serializers.DictionaryEntrySerializer`.
[2025-04-02 11:11:58,486] ERROR log 10620 1716 - Internal Server Error: /api/dictionary/search/
[2025-04-02 11:11:58,487] ERROR basehttp 10620 1716 - "GET /api/dictionary/search/?query=hello HTTP/1.1" 500 3756
[2025-04-02 11:18:09,054] ERROR views 956 8716 - Search Error: Field name `id` is not valid for model `Dictionary` in `dictionary.serializers.DictionaryEntrySerializer`.
[2025-04-02 11:18:09,085] ERROR log 956 8716 - Internal Server Error: /api/dictionary/search/
[2025-04-02 11:18:09,087] ERROR basehttp 956 8716 - "GET /api/dictionary/search/?query=hello HTTP/1.1" 500 3756
[2025-04-02 11:18:52,427] ERROR views 2828 17052 - Search Error: Field name `id` is not valid for model `Dictionary` in `dictionary.serializers.DictionaryEntrySerializer`.
[2025-04-02 11:18:52,458] ERROR log 2828 17052 - Internal Server Error: /api/dictionary/search/
[2025-04-02 11:18:52,459] ERROR basehttp 2828 17052 - "GET /api/dictionary/search/?query=hello HTTP/1.1" 500 3756
[2025-04-03 09:30:48,647] ERROR exception 18128 4504 - Invalid HTTP_HOST header: '127.0.0.1:8000'. You may need to add '127.0.0.1' to ALLOWED_HOSTS.
Traceback (most recent call last):
  File "C:\Users\phara\OneDrive\Desktop\FMIS\python\dictionary_project\venv\Lib\site-packages\django\core\handlers\exception.py", line 55, in inner
    response = get_response(request)
  File "C:\Users\phara\OneDrive\Desktop\FMIS\python\dictionary_project\venv\Lib\site-packages\django\utils\deprecation.py", line 128, in __call__
    response = self.process_request(request)
  File "C:\Users\phara\OneDrive\Desktop\FMIS\python\dictionary_project\venv\Lib\site-packages\django\middleware\common.py", line 48, in process_request
    host = request.get_host()
  File "C:\Users\phara\OneDrive\Desktop\FMIS\python\dictionary_project\venv\Lib\site-packages\django\http\request.py", line 151, in get_host
    raise DisallowedHost(msg)
django.core.exceptions.DisallowedHost: Invalid HTTP_HOST header: '127.0.0.1:8000'. You may need to add '127.0.0.1' to ALLOWED_HOSTS.
[2025-04-03 09:30:49,269] ERROR exception 18128 16224 - Invalid HTTP_HOST header: '127.0.0.1:8000'. You may need to add '127.0.0.1' to ALLOWED_HOSTS.
Traceback (most recent call last):
  File "C:\Users\phara\OneDrive\Desktop\FMIS\python\dictionary_project\venv\Lib\site-packages\django\core\handlers\exception.py", line 55, in inner
    response = get_response(request)
  File "C:\Users\phara\OneDrive\Desktop\FMIS\python\dictionary_project\venv\Lib\site-packages\django\utils\deprecation.py", line 128, in __call__
    response = self.process_request(request)
  File "C:\Users\phara\OneDrive\Desktop\FMIS\python\dictionary_project\venv\Lib\site-packages\django\middleware\common.py", line 48, in process_request
    host = request.get_host()
  File "C:\Users\phara\OneDrive\Desktop\FMIS\python\dictionary_project\venv\Lib\site-packages\django\http\request.py", line 151, in get_host
    raise DisallowedHost(msg)
django.core.exceptions.DisallowedHost: Invalid HTTP_HOST header: '127.0.0.1:8000'. You may need to add '127.0.0.1' to ALLOWED_HOSTS.
[2025-04-03 11:19:17,961] ERROR log 12376 2564 - Internal Server Error: /api/users/mobile/login/
Traceback (most recent call last):
  File "C:\Users\phara\OneDrive\Desktop\FMIS\python\dictionary_project\venv\Lib\site-packages\django\core\handlers\exception.py", line 55, in inner
    response = get_response(request)
  File "C:\Users\phara\OneDrive\Desktop\FMIS\python\dictionary_project\venv\Lib\site-packages\django\core\handlers\base.py", line 197, in _get_response
    response = wrapped_callback(request, *callback_args, **callback_kwargs)
  File "C:\Users\phara\OneDrive\Desktop\FMIS\python\dictionary_project\venv\Lib\site-packages\django\views\decorators\csrf.py", line 65, in _view_wrapper
    return view_func(request, *args, **kwargs)
  File "C:\Users\phara\OneDrive\Desktop\FMIS\python\dictionary_project\venv\Lib\site-packages\django\views\generic\base.py", line 104, in view
    return self.dispatch(request, *args, **kwargs)
           ~~~~~~~~~~~~~^^^^^^^^^^^^^^^^^^^^^^^^^^
  File "C:\Users\phara\OneDrive\Desktop\FMIS\python\dictionary_project\venv\Lib\site-packages\rest_framework\views.py", line 509, in dispatch
    response = self.handle_exception(exc)
  File "C:\Users\phara\OneDrive\Desktop\FMIS\python\dictionary_project\venv\Lib\site-packages\rest_framework\views.py", line 469, in handle_exception
    self.raise_uncaught_exception(exc)
    ~~~~~~~~~~~~~~~~~~~~~~~~~~~~~^^^^^
  File "C:\Users\phara\OneDrive\Desktop\FMIS\python\dictionary_project\venv\Lib\site-packages\rest_framework\views.py", line 480, in raise_uncaught_exception
    raise exc
  File "C:\Users\phara\OneDrive\Desktop\FMIS\python\dictionary_project\venv\Lib\site-packages\rest_framework\views.py", line 497, in dispatch
    self.initial(request, *args, **kwargs)
    ~~~~~~~~~~~~^^^^^^^^^^^^^^^^^^^^^^^^^^
  File "C:\Users\phara\OneDrive\Desktop\FMIS\python\dictionary_project\venv\Lib\site-packages\rest_framework\views.py", line 414, in initial
    self.perform_authentication(request)
    ~~~~~~~~~~~~~~~~~~~~~~~~~~~^^^^^^^^^
  File "C:\Users\phara\OneDrive\Desktop\FMIS\python\dictionary_project\venv\Lib\site-packages\rest_framework\views.py", line 324, in perform_authentication
    request.user
  File "C:\Users\phara\OneDrive\Desktop\FMIS\python\dictionary_project\venv\Lib\site-packages\rest_framework\request.py", line 231, in user
    self._authenticate()
    ~~~~~~~~~~~~~~~~~~^^
  File "C:\Users\phara\OneDrive\Desktop\FMIS\python\dictionary_project\venv\Lib\site-packages\rest_framework\request.py", line 384, in _authenticate
    user_auth_tuple = authenticator.authenticate(self)
  File "C:\Users\phara\OneDrive\Desktop\FMIS\python\dictionary_project\users\custom_auth.py", line 85, in authenticate
    raw_token = get_authorization_header(request).decode('utf-8').split()[1]
                ~~~~~~~~~~~~~~~~~~~~~~~~~~~~~~~~~~~~~~~~~~~~~~~~~~~~~~~~~^^^
IndexError: list index out of range
[2025-04-03 11:19:17,968] ERROR basehttp 12376 2564 - "POST /api/users/mobile/login/ HTTP/1.1" 500 122395
[2025-04-03 11:22:10,508] ERROR log 15476 6428 - Internal Server Error: /api/users/mobile/login/
Traceback (most recent call last):
  File "C:\Users\phara\OneDrive\Desktop\FMIS\python\dictionary_project\venv\Lib\site-packages\django\core\handlers\exception.py", line 55, in inner
    response = get_response(request)
  File "C:\Users\phara\OneDrive\Desktop\FMIS\python\dictionary_project\venv\Lib\site-packages\django\core\handlers\base.py", line 197, in _get_response
    response = wrapped_callback(request, *callback_args, **callback_kwargs)
  File "C:\Users\phara\OneDrive\Desktop\FMIS\python\dictionary_project\venv\Lib\site-packages\django\views\decorators\csrf.py", line 65, in _view_wrapper
    return view_func(request, *args, **kwargs)
  File "C:\Users\phara\OneDrive\Desktop\FMIS\python\dictionary_project\venv\Lib\site-packages\django\views\generic\base.py", line 104, in view
    return self.dispatch(request, *args, **kwargs)
           ~~~~~~~~~~~~~^^^^^^^^^^^^^^^^^^^^^^^^^^
  File "C:\Users\phara\OneDrive\Desktop\FMIS\python\dictionary_project\venv\Lib\site-packages\rest_framework\views.py", line 509, in dispatch
    response = self.handle_exception(exc)
  File "C:\Users\phara\OneDrive\Desktop\FMIS\python\dictionary_project\venv\Lib\site-packages\rest_framework\views.py", line 469, in handle_exception
    self.raise_uncaught_exception(exc)
    ~~~~~~~~~~~~~~~~~~~~~~~~~~~~~^^^^^
  File "C:\Users\phara\OneDrive\Desktop\FMIS\python\dictionary_project\venv\Lib\site-packages\rest_framework\views.py", line 480, in raise_uncaught_exception
    raise exc
  File "C:\Users\phara\OneDrive\Desktop\FMIS\python\dictionary_project\venv\Lib\site-packages\rest_framework\views.py", line 497, in dispatch
    self.initial(request, *args, **kwargs)
    ~~~~~~~~~~~~^^^^^^^^^^^^^^^^^^^^^^^^^^
  File "C:\Users\phara\OneDrive\Desktop\FMIS\python\dictionary_project\venv\Lib\site-packages\rest_framework\views.py", line 414, in initial
    self.perform_authentication(request)
    ~~~~~~~~~~~~~~~~~~~~~~~~~~~^^^^^^^^^
  File "C:\Users\phara\OneDrive\Desktop\FMIS\python\dictionary_project\venv\Lib\site-packages\rest_framework\views.py", line 324, in perform_authentication
    request.user
  File "C:\Users\phara\OneDrive\Desktop\FMIS\python\dictionary_project\venv\Lib\site-packages\rest_framework\request.py", line 231, in user
    self._authenticate()
    ~~~~~~~~~~~~~~~~~~^^
  File "C:\Users\phara\OneDrive\Desktop\FMIS\python\dictionary_project\venv\Lib\site-packages\rest_framework\request.py", line 384, in _authenticate
    user_auth_tuple = authenticator.authenticate(self)
  File "C:\Users\phara\OneDrive\Desktop\FMIS\python\dictionary_project\users\custom_auth.py", line 85, in authenticate
    raw_token = get_authorization_header(request).decode('utf-8').split()[1]
                ~~~~~~~~~~~~~~~~~~~~~~~~~~~~~~~~~~~~~~~~~~~~~~~~~~~~~~~~~^^^
IndexError: list index out of range
[2025-04-03 11:22:10,518] ERROR basehttp 15476 6428 - "POST /api/users/mobile/login/ HTTP/1.1" 500 122395
[2025-04-04 11:46:08,743] ERROR log 20764 21140 - Internal Server Error: /api/dictionary/bookmarks/
[2025-04-04 11:46:08,746] ERROR basehttp 20764 21140 - "GET /api/dictionary/bookmarks/ HTTP/1.1" 500 192
[2025-04-04 15:28:59,994] ERROR log 20920 1212 - Internal Server Error: /api/dictionary/staging/89/approve/
Traceback (most recent call last):
  File "C:\Users\phara\OneDrive\Desktop\FMIS\python\dictionary_project - Copy\venv\Lib\site-packages\django\core\handlers\exception.py", line 55, in inner
    response = get_response(request)
  File "C:\Users\phara\OneDrive\Desktop\FMIS\python\dictionary_project - Copy\venv\Lib\site-packages\django\core\handlers\base.py", line 197, in _get_response
    response = wrapped_callback(request, *callback_args, **callback_kwargs)
  File "C:\Users\phara\OneDrive\Desktop\FMIS\python\dictionary_project - Copy\venv\Lib\site-packages\django\views\decorators\csrf.py", line 65, in _view_wrapper
    return view_func(request, *args, **kwargs)
  File "C:\Users\phara\OneDrive\Desktop\FMIS\python\dictionary_project - Copy\venv\Lib\site-packages\django\views\generic\base.py", line 104, in view
    return self.dispatch(request, *args, **kwargs)
           ~~~~~~~~~~~~~^^^^^^^^^^^^^^^^^^^^^^^^^^
  File "C:\Users\phara\OneDrive\Desktop\FMIS\python\dictionary_project - Copy\venv\Lib\site-packages\rest_framework\views.py", line 509, in dispatch
    response = self.handle_exception(exc)
  File "C:\Users\phara\OneDrive\Desktop\FMIS\python\dictionary_project - Copy\venv\Lib\site-packages\rest_framework\views.py", line 469, in handle_exception
    self.raise_uncaught_exception(exc)
    ~~~~~~~~~~~~~~~~~~~~~~~~~~~~~^^^^^
  File "C:\Users\phara\OneDrive\Desktop\FMIS\python\dictionary_project - Copy\venv\Lib\site-packages\rest_framework\views.py", line 480, in raise_uncaught_exception
    raise exc
  File "C:\Users\phara\OneDrive\Desktop\FMIS\python\dictionary_project - Copy\venv\Lib\site-packages\rest_framework\views.py", line 506, in dispatch
    response = handler(request, *args, **kwargs)
TypeError: StagingEntryApproveView.post() got an unexpected keyword argument 'pk'
[2025-04-04 15:29:00,001] ERROR basehttp 20920 1212 - "POST /api/dictionary/staging/89/approve/ HTTP/1.1" 500 104032
[2025-04-04 15:35:32,809] ERROR log 20776 9600 - Internal Server Error: /api/dictionary/staging/89/approve/
Traceback (most recent call last):
  File "C:\Users\phara\OneDrive\Desktop\FMIS\python\dictionary_project - Copy\venv\Lib\site-packages\django\core\handlers\exception.py", line 55, in inner
    response = get_response(request)
  File "C:\Users\phara\OneDrive\Desktop\FMIS\python\dictionary_project - Copy\venv\Lib\site-packages\django\core\handlers\base.py", line 197, in _get_response
    response = wrapped_callback(request, *callback_args, **callback_kwargs)
  File "C:\Users\phara\OneDrive\Desktop\FMIS\python\dictionary_project - Copy\venv\Lib\site-packages\django\views\decorators\csrf.py", line 65, in _view_wrapper
    return view_func(request, *args, **kwargs)
  File "C:\Users\phara\OneDrive\Desktop\FMIS\python\dictionary_project - Copy\venv\Lib\site-packages\django\views\generic\base.py", line 104, in view
    return self.dispatch(request, *args, **kwargs)
           ~~~~~~~~~~~~~^^^^^^^^^^^^^^^^^^^^^^^^^^
  File "C:\Users\phara\OneDrive\Desktop\FMIS\python\dictionary_project - Copy\venv\Lib\site-packages\rest_framework\views.py", line 509, in dispatch
    response = self.handle_exception(exc)
  File "C:\Users\phara\OneDrive\Desktop\FMIS\python\dictionary_project - Copy\venv\Lib\site-packages\rest_framework\views.py", line 469, in handle_exception
    self.raise_uncaught_exception(exc)
    ~~~~~~~~~~~~~~~~~~~~~~~~~~~~~^^^^^
  File "C:\Users\phara\OneDrive\Desktop\FMIS\python\dictionary_project - Copy\venv\Lib\site-packages\rest_framework\views.py", line 480, in raise_uncaught_exception
    raise exc
  File "C:\Users\phara\OneDrive\Desktop\FMIS\python\dictionary_project - Copy\venv\Lib\site-packages\rest_framework\views.py", line 506, in dispatch
    response = handler(request, *args, **kwargs)
TypeError: StagingEntryApproveView.post() got an unexpected keyword argument 'pk'
[2025-04-04 15:35:32,816] ERROR basehttp 20776 9600 - "POST /api/dictionary/staging/89/approve/ HTTP/1.1" 500 104032
[2025-04-04 15:36:33,992] ERROR log 9628 12816 - Internal Server Error: /api/dictionary/staging/89/approve/
Traceback (most recent call last):
  File "C:\Users\phara\OneDrive\Desktop\FMIS\python\dictionary_project - Copy\venv\Lib\site-packages\django\core\handlers\exception.py", line 55, in inner
    response = get_response(request)
  File "C:\Users\phara\OneDrive\Desktop\FMIS\python\dictionary_project - Copy\venv\Lib\site-packages\django\core\handlers\base.py", line 197, in _get_response
    response = wrapped_callback(request, *callback_args, **callback_kwargs)
  File "C:\Users\phara\OneDrive\Desktop\FMIS\python\dictionary_project - Copy\venv\Lib\site-packages\django\views\decorators\csrf.py", line 65, in _view_wrapper
    return view_func(request, *args, **kwargs)
  File "C:\Users\phara\OneDrive\Desktop\FMIS\python\dictionary_project - Copy\venv\Lib\site-packages\django\views\generic\base.py", line 104, in view
    return self.dispatch(request, *args, **kwargs)
           ~~~~~~~~~~~~~^^^^^^^^^^^^^^^^^^^^^^^^^^
  File "C:\Users\phara\OneDrive\Desktop\FMIS\python\dictionary_project - Copy\venv\Lib\site-packages\rest_framework\views.py", line 509, in dispatch
    response = self.handle_exception(exc)
  File "C:\Users\phara\OneDrive\Desktop\FMIS\python\dictionary_project - Copy\venv\Lib\site-packages\rest_framework\views.py", line 469, in handle_exception
    self.raise_uncaught_exception(exc)
    ~~~~~~~~~~~~~~~~~~~~~~~~~~~~~^^^^^
  File "C:\Users\phara\OneDrive\Desktop\FMIS\python\dictionary_project - Copy\venv\Lib\site-packages\rest_framework\views.py", line 480, in raise_uncaught_exception
    raise exc
  File "C:\Users\phara\OneDrive\Desktop\FMIS\python\dictionary_project - Copy\venv\Lib\site-packages\rest_framework\views.py", line 506, in dispatch
    response = handler(request, *args, **kwargs)
TypeError: StagingEntryApproveView.post() got an unexpected keyword argument 'pk'
[2025-04-04 15:36:33,999] ERROR basehttp 9628 12816 - "POST /api/dictionary/staging/89/approve/ HTTP/1.1" 500 104032
[2025-04-04 16:15:21,560] ERROR log 22540 7644 - Internal Server Error: /api/dictionary/staging/93/approve/
Traceback (most recent call last):
  File "C:\Users\phara\OneDrive\Desktop\FMIS\python\dictionary_project - Copy\venv\Lib\site-packages\django\core\handlers\exception.py", line 55, in inner
    response = get_response(request)
  File "C:\Users\phara\OneDrive\Desktop\FMIS\python\dictionary_project - Copy\venv\Lib\site-packages\django\core\handlers\base.py", line 197, in _get_response
    response = wrapped_callback(request, *callback_args, **callback_kwargs)
  File "C:\Users\phara\OneDrive\Desktop\FMIS\python\dictionary_project - Copy\venv\Lib\site-packages\django\views\decorators\csrf.py", line 65, in _view_wrapper
    return view_func(request, *args, **kwargs)
  File "C:\Users\phara\OneDrive\Desktop\FMIS\python\dictionary_project - Copy\venv\Lib\site-packages\django\views\generic\base.py", line 104, in view
    return self.dispatch(request, *args, **kwargs)
           ~~~~~~~~~~~~~^^^^^^^^^^^^^^^^^^^^^^^^^^
  File "C:\Users\phara\OneDrive\Desktop\FMIS\python\dictionary_project - Copy\venv\Lib\site-packages\rest_framework\views.py", line 509, in dispatch
    response = self.handle_exception(exc)
  File "C:\Users\phara\OneDrive\Desktop\FMIS\python\dictionary_project - Copy\venv\Lib\site-packages\rest_framework\views.py", line 469, in handle_exception
    self.raise_uncaught_exception(exc)
    ~~~~~~~~~~~~~~~~~~~~~~~~~~~~~^^^^^
  File "C:\Users\phara\OneDrive\Desktop\FMIS\python\dictionary_project - Copy\venv\Lib\site-packages\rest_framework\views.py", line 480, in raise_uncaught_exception
    raise exc
  File "C:\Users\phara\OneDrive\Desktop\FMIS\python\dictionary_project - Copy\venv\Lib\site-packages\rest_framework\views.py", line 506, in dispatch
    response = handler(request, *args, **kwargs)
TypeError: StagingEntryApproveView.post() got an unexpected keyword argument 'pk'
[2025-04-04 16:15:21,569] ERROR basehttp 22540 7644 - "POST /api/dictionary/staging/93/approve/ HTTP/1.1" 500 104032
[2025-04-05 22:53:15,188] ERROR log 11608 5548 - Internal Server Error: /api/dictionary/sync_all/
[2025-04-05 22:53:15,190] ERROR basehttp 11608 5548 - "GET /api/dictionary/sync_all/?per_page=20 HTTP/1.1" 500 179
[2025-04-05 23:28:44,965] ERROR log 17616 23064 - Internal Server Error: /api/dictionary/staging/create/
[2025-04-05 23:28:44,966] ERROR basehttp 17616 23064 - "POST /api/dictionary/staging/create/ HTTP/1.1" 500 7830
[2025-04-05 23:41:48,374] ERROR log 22032 18260 - Internal Server Error: /api/dictionary/staging/create/
[2025-04-05 23:41:48,375] ERROR basehttp 22032 18260 - "POST /api/dictionary/staging/create/ HTTP/1.1" 500 7827
[2025-04-05 23:43:37,386] ERROR log 15056 6620 - Internal Server Error: /api/dictionary/staging/create/
[2025-04-05 23:43:37,387] ERROR basehttp 15056 6620 - "POST /api/dictionary/staging/create/ HTTP/1.1" 500 7788
[2025-04-05 23:44:05,042] ERROR log 15056 6620 - Internal Server Error: /api/dictionary/staging/create/
[2025-04-05 23:44:05,042] ERROR basehttp 15056 6620 - "POST /api/dictionary/staging/create/ HTTP/1.1" 500 7788
[2025-04-05 23:45:10,846] ERROR log 5540 6192 - Internal Server Error: /api/dictionary/staging/create/
[2025-04-05 23:45:10,847] ERROR basehttp 5540 6192 - "POST /api/dictionary/staging/create/ HTTP/1.1" 500 7788
[2025-04-05 23:45:12,536] ERROR log 5540 6192 - Internal Server Error: /api/dictionary/staging/create/
[2025-04-05 23:45:12,537] ERROR basehttp 5540 6192 - "POST /api/dictionary/staging/create/ HTTP/1.1" 500 7788
[2025-04-06 01:26:38,613] ERROR log 14028 17020 - Internal Server Error: /api/dictionary/staging/create/
[2025-04-06 01:26:38,614] ERROR basehttp 14028 17020 - "POST /api/dictionary/staging/create/ HTTP/1.1" 500 1473
[2025-04-06 01:58:16,782] ERROR log 19216 11832 - Internal Server Error: /api/dictionary/staging/7/approve/
Traceback (most recent call last):
  File "C:\Users\phara\OneDrive\Desktop\FMIS\python\dictionary_project\venv\Lib\site-packages\django\core\handlers\exception.py", line 55, in inner
    response = get_response(request)
  File "C:\Users\phara\OneDrive\Desktop\FMIS\python\dictionary_project\venv\Lib\site-packages\django\core\handlers\base.py", line 197, in _get_response
    response = wrapped_callback(request, *callback_args, **callback_kwargs)
  File "C:\Users\phara\OneDrive\Desktop\FMIS\python\dictionary_project\venv\Lib\site-packages\django\views\decorators\csrf.py", line 65, in _view_wrapper
    return view_func(request, *args, **kwargs)
  File "C:\Users\phara\OneDrive\Desktop\FMIS\python\dictionary_project\venv\Lib\site-packages\django\views\generic\base.py", line 104, in view
    return self.dispatch(request, *args, **kwargs)
           ~~~~~~~~~~~~~^^^^^^^^^^^^^^^^^^^^^^^^^^
  File "C:\Users\phara\OneDrive\Desktop\FMIS\python\dictionary_project\venv\Lib\site-packages\rest_framework\views.py", line 509, in dispatch
    response = self.handle_exception(exc)
  File "C:\Users\phara\OneDrive\Desktop\FMIS\python\dictionary_project\venv\Lib\site-packages\rest_framework\views.py", line 469, in handle_exception
    self.raise_uncaught_exception(exc)
    ~~~~~~~~~~~~~~~~~~~~~~~~~~~~~^^^^^
  File "C:\Users\phara\OneDrive\Desktop\FMIS\python\dictionary_project\venv\Lib\site-packages\rest_framework\views.py", line 480, in raise_uncaught_exception
    raise exc
  File "C:\Users\phara\OneDrive\Desktop\FMIS\python\dictionary_project\venv\Lib\site-packages\rest_framework\views.py", line 506, in dispatch
    response = handler(request, *args, **kwargs)
TypeError: StagingEntryApproveView.post() got an unexpected keyword argument 'pk'
[2025-04-06 01:58:16,786] ERROR basehttp 19216 11832 - "POST /api/dictionary/staging/7/approve/ HTTP/1.1" 500 103763
[2025-04-06 02:53:59,157] ERROR log 1596 9736 - Internal Server Error: /api/dictionary/bookmarks/
[2025-04-06 02:53:59,158] ERROR basehttp 1596 9736 - "POST /api/dictionary/bookmarks/ HTTP/1.1" 500 186
[2025-04-08 02:26:40,136] ERROR log 11884 7480 - Internal Server Error: /swagger/
Traceback (most recent call last):
  File "C:\Users\phara\OneDrive\Desktop\FMIS\python\dictionary_project\venv\Lib\site-packages\django\core\handlers\exception.py", line 55, in inner
    response = get_response(request)
  File "C:\Users\phara\OneDrive\Desktop\FMIS\python\dictionary_project\venv\Lib\site-packages\django\core\handlers\base.py", line 197, in _get_response
    response = wrapped_callback(request, *callback_args, **callback_kwargs)
  File "C:\Users\phara\OneDrive\Desktop\FMIS\python\dictionary_project\venv\Lib\site-packages\django\views\decorators\csrf.py", line 65, in _view_wrapper
    return view_func(request, *args, **kwargs)
  File "C:\Users\phara\OneDrive\Desktop\FMIS\python\dictionary_project\venv\Lib\site-packages\django\views\generic\base.py", line 104, in view
    return self.dispatch(request, *args, **kwargs)
           ~~~~~~~~~~~~~^^^^^^^^^^^^^^^^^^^^^^^^^^
  File "C:\Users\phara\OneDrive\Desktop\FMIS\python\dictionary_project\venv\Lib\site-packages\rest_framework\views.py", line 509, in dispatch
    response = self.handle_exception(exc)
  File "C:\Users\phara\OneDrive\Desktop\FMIS\python\dictionary_project\venv\Lib\site-packages\rest_framework\views.py", line 469, in handle_exception
    self.raise_uncaught_exception(exc)
    ~~~~~~~~~~~~~~~~~~~~~~~~~~~~~^^^^^
  File "C:\Users\phara\OneDrive\Desktop\FMIS\python\dictionary_project\venv\Lib\site-packages\rest_framework\views.py", line 480, in raise_uncaught_exception
    raise exc
  File "C:\Users\phara\OneDrive\Desktop\FMIS\python\dictionary_project\venv\Lib\site-packages\rest_framework\views.py", line 506, in dispatch
    response = handler(request, *args, **kwargs)
  File "C:\Users\phara\OneDrive\Desktop\FMIS\python\dictionary_project\venv\Lib\site-packages\drf_yasg\views.py", line 112, in get
    schema = generator.get_schema(request, self.public)
  File "C:\Users\phara\OneDrive\Desktop\FMIS\python\dictionary_project\venv\Lib\site-packages\drf_yasg\generators.py", line 276, in get_schema
    paths, prefix = self.get_paths(endpoints, components, request, public)
                    ~~~~~~~~~~~~~~^^^^^^^^^^^^^^^^^^^^^^^^^^^^^^^^^^^^^^^^
  File "C:\Users\phara\OneDrive\Desktop\FMIS\python\dictionary_project\venv\Lib\site-packages\drf_yasg\generators.py", line 482, in get_paths
    operation = self.get_operation(view, path, prefix, method, components, request)
  File "C:\Users\phara\OneDrive\Desktop\FMIS\python\dictionary_project\venv\Lib\site-packages\drf_yasg\generators.py", line 524, in get_operation
    operation = view_inspector.get_operation(operation_keys)
  File "C:\Users\phara\OneDrive\Desktop\FMIS\python\dictionary_project\venv\Lib\site-packages\drf_yasg\inspectors\view.py", line 32, in get_operation
    body = self.get_request_body_parameters(consumes)
  File "C:\Users\phara\OneDrive\Desktop\FMIS\python\dictionary_project\venv\Lib\site-packages\drf_yasg\inspectors\view.py", line 81, in get_request_body_parameters
    raise SwaggerGenerationError("form request body cannot be a Schema")
drf_yasg.errors.SwaggerGenerationError: form request body cannot be a Schema
[2025-04-08 02:26:40,142] ERROR basehttp 11884 7480 - "GET /swagger/?format=openapi HTTP/1.1" 500 163662
[2025-04-08 02:29:40,811] ERROR log 14132 10556 - Internal Server Error: /swagger/
Traceback (most recent call last):
  File "C:\Users\phara\OneDrive\Desktop\FMIS\python\dictionary_project\venv\Lib\site-packages\django\core\handlers\exception.py", line 55, in inner
    response = get_response(request)
  File "C:\Users\phara\OneDrive\Desktop\FMIS\python\dictionary_project\venv\Lib\site-packages\django\core\handlers\base.py", line 197, in _get_response
    response = wrapped_callback(request, *callback_args, **callback_kwargs)
  File "C:\Users\phara\OneDrive\Desktop\FMIS\python\dictionary_project\venv\Lib\site-packages\django\views\decorators\csrf.py", line 65, in _view_wrapper
    return view_func(request, *args, **kwargs)
  File "C:\Users\phara\OneDrive\Desktop\FMIS\python\dictionary_project\venv\Lib\site-packages\django\views\generic\base.py", line 104, in view
    return self.dispatch(request, *args, **kwargs)
           ~~~~~~~~~~~~~^^^^^^^^^^^^^^^^^^^^^^^^^^
  File "C:\Users\phara\OneDrive\Desktop\FMIS\python\dictionary_project\venv\Lib\site-packages\rest_framework\views.py", line 509, in dispatch
    response = self.handle_exception(exc)
  File "C:\Users\phara\OneDrive\Desktop\FMIS\python\dictionary_project\venv\Lib\site-packages\rest_framework\views.py", line 469, in handle_exception
    self.raise_uncaught_exception(exc)
    ~~~~~~~~~~~~~~~~~~~~~~~~~~~~~^^^^^
  File "C:\Users\phara\OneDrive\Desktop\FMIS\python\dictionary_project\venv\Lib\site-packages\rest_framework\views.py", line 480, in raise_uncaught_exception
    raise exc
  File "C:\Users\phara\OneDrive\Desktop\FMIS\python\dictionary_project\venv\Lib\site-packages\rest_framework\views.py", line 506, in dispatch
    response = handler(request, *args, **kwargs)
  File "C:\Users\phara\OneDrive\Desktop\FMIS\python\dictionary_project\venv\Lib\site-packages\drf_yasg\views.py", line 112, in get
    schema = generator.get_schema(request, self.public)
  File "C:\Users\phara\OneDrive\Desktop\FMIS\python\dictionary_project\venv\Lib\site-packages\drf_yasg\generators.py", line 276, in get_schema
    paths, prefix = self.get_paths(endpoints, components, request, public)
                    ~~~~~~~~~~~~~~^^^^^^^^^^^^^^^^^^^^^^^^^^^^^^^^^^^^^^^^
  File "C:\Users\phara\OneDrive\Desktop\FMIS\python\dictionary_project\venv\Lib\site-packages\drf_yasg\generators.py", line 482, in get_paths
    operation = self.get_operation(view, path, prefix, method, components, request)
  File "C:\Users\phara\OneDrive\Desktop\FMIS\python\dictionary_project\venv\Lib\site-packages\drf_yasg\generators.py", line 524, in get_operation
    operation = view_inspector.get_operation(operation_keys)
  File "C:\Users\phara\OneDrive\Desktop\FMIS\python\dictionary_project\venv\Lib\site-packages\drf_yasg\inspectors\view.py", line 32, in get_operation
    body = self.get_request_body_parameters(consumes)
  File "C:\Users\phara\OneDrive\Desktop\FMIS\python\dictionary_project\venv\Lib\site-packages\drf_yasg\inspectors\view.py", line 81, in get_request_body_parameters
    raise SwaggerGenerationError("form request body cannot be a Schema")
drf_yasg.errors.SwaggerGenerationError: form request body cannot be a Schema
[2025-04-08 02:29:40,820] ERROR basehttp 14132 10556 - "GET /swagger/?format=openapi HTTP/1.1" 500 164595
[2025-04-08 02:33:55,039] ERROR log 9128 2644 - Internal Server Error: /swagger/
Traceback (most recent call last):
  File "C:\Users\phara\OneDrive\Desktop\FMIS\python\dictionary_project\venv\Lib\site-packages\django\core\handlers\exception.py", line 55, in inner
    response = get_response(request)
  File "C:\Users\phara\OneDrive\Desktop\FMIS\python\dictionary_project\venv\Lib\site-packages\django\core\handlers\base.py", line 197, in _get_response
    response = wrapped_callback(request, *callback_args, **callback_kwargs)
  File "C:\Users\phara\OneDrive\Desktop\FMIS\python\dictionary_project\venv\Lib\site-packages\django\views\decorators\csrf.py", line 65, in _view_wrapper
    return view_func(request, *args, **kwargs)
  File "C:\Users\phara\OneDrive\Desktop\FMIS\python\dictionary_project\venv\Lib\site-packages\django\views\generic\base.py", line 104, in view
    return self.dispatch(request, *args, **kwargs)
           ~~~~~~~~~~~~~^^^^^^^^^^^^^^^^^^^^^^^^^^
  File "C:\Users\phara\OneDrive\Desktop\FMIS\python\dictionary_project\venv\Lib\site-packages\rest_framework\views.py", line 509, in dispatch
    response = self.handle_exception(exc)
  File "C:\Users\phara\OneDrive\Desktop\FMIS\python\dictionary_project\venv\Lib\site-packages\rest_framework\views.py", line 469, in handle_exception
    self.raise_uncaught_exception(exc)
    ~~~~~~~~~~~~~~~~~~~~~~~~~~~~~^^^^^
  File "C:\Users\phara\OneDrive\Desktop\FMIS\python\dictionary_project\venv\Lib\site-packages\rest_framework\views.py", line 480, in raise_uncaught_exception
    raise exc
  File "C:\Users\phara\OneDrive\Desktop\FMIS\python\dictionary_project\venv\Lib\site-packages\rest_framework\views.py", line 506, in dispatch
    response = handler(request, *args, **kwargs)
  File "C:\Users\phara\OneDrive\Desktop\FMIS\python\dictionary_project\venv\Lib\site-packages\drf_yasg\views.py", line 112, in get
    schema = generator.get_schema(request, self.public)
  File "C:\Users\phara\OneDrive\Desktop\FMIS\python\dictionary_project\venv\Lib\site-packages\drf_yasg\generators.py", line 276, in get_schema
    paths, prefix = self.get_paths(endpoints, components, request, public)
                    ~~~~~~~~~~~~~~^^^^^^^^^^^^^^^^^^^^^^^^^^^^^^^^^^^^^^^^
  File "C:\Users\phara\OneDrive\Desktop\FMIS\python\dictionary_project\venv\Lib\site-packages\drf_yasg\generators.py", line 482, in get_paths
    operation = self.get_operation(view, path, prefix, method, components, request)
  File "C:\Users\phara\OneDrive\Desktop\FMIS\python\dictionary_project\venv\Lib\site-packages\drf_yasg\generators.py", line 524, in get_operation
    operation = view_inspector.get_operation(operation_keys)
  File "C:\Users\phara\OneDrive\Desktop\FMIS\python\dictionary_project\venv\Lib\site-packages\drf_yasg\inspectors\view.py", line 32, in get_operation
    body = self.get_request_body_parameters(consumes)
  File "C:\Users\phara\OneDrive\Desktop\FMIS\python\dictionary_project\venv\Lib\site-packages\drf_yasg\inspectors\view.py", line 81, in get_request_body_parameters
    raise SwaggerGenerationError("form request body cannot be a Schema")
drf_yasg.errors.SwaggerGenerationError: form request body cannot be a Schema
[2025-04-08 02:33:55,045] ERROR basehttp 9128 2644 - "GET /swagger/?format=openapi HTTP/1.1" 500 164595
[2025-04-08 02:42:10,156] ERROR log 1760 14564 - Internal Server Error: /swagger/
Traceback (most recent call last):
  File "C:\Users\phara\OneDrive\Desktop\FMIS\python\dictionary_project\venv\Lib\site-packages\django\core\handlers\exception.py", line 55, in inner
    response = get_response(request)
  File "C:\Users\phara\OneDrive\Desktop\FMIS\python\dictionary_project\venv\Lib\site-packages\django\core\handlers\base.py", line 197, in _get_response
    response = wrapped_callback(request, *callback_args, **callback_kwargs)
  File "C:\Users\phara\OneDrive\Desktop\FMIS\python\dictionary_project\venv\Lib\site-packages\django\views\decorators\csrf.py", line 65, in _view_wrapper
    return view_func(request, *args, **kwargs)
  File "C:\Users\phara\OneDrive\Desktop\FMIS\python\dictionary_project\venv\Lib\site-packages\django\views\generic\base.py", line 104, in view
    return self.dispatch(request, *args, **kwargs)
           ~~~~~~~~~~~~~^^^^^^^^^^^^^^^^^^^^^^^^^^
  File "C:\Users\phara\OneDrive\Desktop\FMIS\python\dictionary_project\venv\Lib\site-packages\rest_framework\views.py", line 509, in dispatch
    response = self.handle_exception(exc)
  File "C:\Users\phara\OneDrive\Desktop\FMIS\python\dictionary_project\venv\Lib\site-packages\rest_framework\views.py", line 469, in handle_exception
    self.raise_uncaught_exception(exc)
    ~~~~~~~~~~~~~~~~~~~~~~~~~~~~~^^^^^
  File "C:\Users\phara\OneDrive\Desktop\FMIS\python\dictionary_project\venv\Lib\site-packages\rest_framework\views.py", line 480, in raise_uncaught_exception
    raise exc
  File "C:\Users\phara\OneDrive\Desktop\FMIS\python\dictionary_project\venv\Lib\site-packages\rest_framework\views.py", line 506, in dispatch
    response = handler(request, *args, **kwargs)
  File "C:\Users\phara\OneDrive\Desktop\FMIS\python\dictionary_project\venv\Lib\site-packages\drf_yasg\views.py", line 112, in get
    schema = generator.get_schema(request, self.public)
  File "C:\Users\phara\OneDrive\Desktop\FMIS\python\dictionary_project\venv\Lib\site-packages\drf_yasg\generators.py", line 276, in get_schema
    paths, prefix = self.get_paths(endpoints, components, request, public)
                    ~~~~~~~~~~~~~~^^^^^^^^^^^^^^^^^^^^^^^^^^^^^^^^^^^^^^^^
  File "C:\Users\phara\OneDrive\Desktop\FMIS\python\dictionary_project\venv\Lib\site-packages\drf_yasg\generators.py", line 482, in get_paths
    operation = self.get_operation(view, path, prefix, method, components, request)
  File "C:\Users\phara\OneDrive\Desktop\FMIS\python\dictionary_project\venv\Lib\site-packages\drf_yasg\generators.py", line 524, in get_operation
    operation = view_inspector.get_operation(operation_keys)
  File "C:\Users\phara\OneDrive\Desktop\FMIS\python\dictionary_project\venv\Lib\site-packages\drf_yasg\inspectors\view.py", line 32, in get_operation
    body = self.get_request_body_parameters(consumes)
  File "C:\Users\phara\OneDrive\Desktop\FMIS\python\dictionary_project\venv\Lib\site-packages\drf_yasg\inspectors\view.py", line 81, in get_request_body_parameters
    raise SwaggerGenerationError("form request body cannot be a Schema")
drf_yasg.errors.SwaggerGenerationError: form request body cannot be a Schema
[2025-04-08 02:42:10,166] ERROR basehttp 1760 14564 - "GET /swagger/?format=openapi HTTP/1.1" 500 164595
[2025-04-08 02:53:27,634] ERROR log 18480 11500 - Internal Server Error: /api/users/register/
[2025-04-08 02:53:27,635] ERROR basehttp 18480 11500 - "POST /api/users/register/ HTTP/1.1" 500 117
[2025-04-08 03:04:01,484] ERROR log 18480 2636 - Internal Server Error: /api/users/register/
[2025-04-08 03:04:01,485] ERROR basehttp 18480 2636 - "POST /api/users/register/ HTTP/1.1" 500 152
[2025-04-08 03:11:31,746] ERROR log 15180 4412 - Internal Server Error: /api/users/register/
[2025-04-08 03:11:31,747] ERROR basehttp 15180 4412 - "POST /api/users/register/ HTTP/1.1" 500 152
[2025-04-08 03:11:33,400] ERROR log 15180 4412 - Internal Server Error: /api/users/register/
[2025-04-08 03:11:33,400] ERROR basehttp 15180 4412 - "POST /api/users/register/ HTTP/1.1" 500 152
[2025-04-08 03:12:29,275] ERROR log 3360 13344 - Internal Server Error: /api/users/register/
[2025-04-08 03:12:29,275] ERROR basehttp 3360 13344 - "POST /api/users/register/ HTTP/1.1" 500 152
[2025-04-08 03:12:30,521] ERROR log 3360 13344 - Internal Server Error: /api/users/register/
[2025-04-08 03:12:30,522] ERROR basehttp 3360 13344 - "POST /api/users/register/ HTTP/1.1" 500 152
[2025-04-08 03:12:31,295] ERROR log 3360 13344 - Internal Server Error: /api/users/register/
[2025-04-08 03:12:31,295] ERROR basehttp 3360 13344 - "POST /api/users/register/ HTTP/1.1" 500 152
[2025-04-08 03:14:57,651] ERROR log 18700 9984 - Internal Server Error: /api/users/register/
[2025-04-08 03:14:57,652] ERROR basehttp 18700 9984 - "POST /api/users/register/ HTTP/1.1" 500 152
[2025-04-08 03:14:59,457] ERROR log 18700 9984 - Internal Server Error: /api/users/register/
[2025-04-08 03:14:59,458] ERROR basehttp 18700 9984 - "POST /api/users/register/ HTTP/1.1" 500 152
[2025-04-08 03:16:05,010] ERROR log 8000 13868 - Internal Server Error: /api/users/register/
[2025-04-08 03:16:05,012] ERROR basehttp 8000 13868 - "POST /api/users/register/ HTTP/1.1" 500 143
[2025-04-08 03:25:16,589] ERROR log 17256 16888 - Internal Server Error: /api/users/register/
[2025-04-08 03:25:16,590] ERROR basehttp 17256 16888 - "POST /api/users/register/ HTTP/1.1" 500 143
[2025-04-08 03:25:19,124] ERROR log 17256 16888 - Internal Server Error: /api/users/register/
[2025-04-08 03:25:19,125] ERROR basehttp 17256 16888 - "POST /api/users/register/ HTTP/1.1" 500 143
[2025-04-08 03:25:20,080] ERROR log 17256 16888 - Internal Server Error: /api/users/register/
[2025-04-08 03:25:20,081] ERROR basehttp 17256 16888 - "POST /api/users/register/ HTTP/1.1" 500 143
[2025-04-08 04:27:50,348] ERROR log 19220 17300 - Internal Server Error: /api/dictionary/sync_all/
[2025-04-08 04:27:50,349] ERROR basehttp 19220 17300 - "GET /api/dictionary/sync_all/?per_page=20 HTTP/1.1" 500 192
[2025-04-08 04:29:31,821] ERROR log 14612 18764 - Internal Server Error: /api/dictionary/sync_all/
[2025-04-08 04:29:31,822] ERROR basehttp 14612 18764 - "GET /api/dictionary/sync_all/?per_page=20 HTTP/1.1" 500 192
[2025-04-08 04:30:37,587] ERROR log 10728 13132 - Internal Server Error: /api/dictionary/sync_all/
[2025-04-08 04:30:37,588] ERROR basehttp 10728 13132 - "GET /api/dictionary/sync_all/?per_page=20 HTTP/1.1" 500 133
[2025-04-08 04:31:11,612] ERROR log 3280 15668 - Internal Server Error: /api/dictionary/sync_all/
[2025-04-08 04:31:11,613] ERROR basehttp 3280 15668 - "GET /api/dictionary/sync_all/?per_page=20 HTTP/1.1" 500 133
[2025-04-08 04:34:57,050] ERROR log 13640 16304 - Internal Server Error: /api/dictionary/sync_all/
[2025-04-08 04:34:57,051] ERROR basehttp 13640 16304 - "GET /api/dictionary/sync_all/?per_page=20 HTTP/1.1" 500 192
[2025-04-08 04:35:30,896] ERROR log 3524 18212 - Internal Server Error: /api/dictionary/sync_all/
[2025-04-08 04:35:30,896] ERROR basehttp 3524 18212 - "GET /api/dictionary/sync_all/?per_page=20 HTTP/1.1" 500 134
[2025-04-08 04:38:18,320] ERROR log 12968 2184 - Internal Server Error: /api/dictionary/sync_all/
[2025-04-08 04:38:18,321] ERROR basehttp 12968 2184 - "GET /api/dictionary/sync_all/?per_page=20 HTTP/1.1" 500 191
[2025-04-08 08:12:52,806] ERROR log 17736 21176 - Internal Server Error: /api/users/register/
[2025-04-08 08:12:52,806] ERROR basehttp 17736 21176 - "POST /api/users/register/ HTTP/1.1" 500 122
[2025-04-09 08:47:41,111] ERROR log 10916 10008 - Internal Server Error: /api/users/login
Traceback (most recent call last):
  File "C:\Users\phara\OneDrive\Desktop\FMIS\python\dictionary_project\venv\Lib\site-packages\django\core\handlers\exception.py", line 55, in inner
    response = get_response(request)
  File "C:\Users\phara\OneDrive\Desktop\FMIS\python\dictionary_project\venv\Lib\site-packages\django\utils\deprecation.py", line 131, in __call__
    response = self.process_response(request, response)
  File "C:\Users\phara\OneDrive\Desktop\FMIS\python\dictionary_project\venv\Lib\site-packages\django\middleware\common.py", line 108, in process_response
    return self.response_redirect_class(self.get_full_path_with_slash(request))
                                        ~~~~~~~~~~~~~~~~~~~~~~~~~~~~~^^^^^^^^^
  File "C:\Users\phara\OneDrive\Desktop\FMIS\python\dictionary_project\venv\Lib\site-packages\django\middleware\common.py", line 87, in get_full_path_with_slash
    raise RuntimeError(
    ...<9 lines>...
    )
RuntimeError: You called this URL via POST, but the URL doesn't end in a slash and you have APPEND_SLASH set. Django can't redirect to the slash URL while maintaining POST data. Change your form to point to 172.23.23.48:9991/api/users/login/ (note the trailing slash), or set APPEND_SLASH=False in your Django settings.
[2025-04-09 08:47:41,113] ERROR basehttp 10916 10008 - "POST /api/users/login HTTP/1.1" 500 85072
[2025-04-09 08:48:59,212] ERROR log 10916 19544 - Internal Server Error: /api/users/login
Traceback (most recent call last):
  File "C:\Users\phara\OneDrive\Desktop\FMIS\python\dictionary_project\venv\Lib\site-packages\django\core\handlers\exception.py", line 55, in inner
    response = get_response(request)
  File "C:\Users\phara\OneDrive\Desktop\FMIS\python\dictionary_project\venv\Lib\site-packages\django\utils\deprecation.py", line 131, in __call__
    response = self.process_response(request, response)
  File "C:\Users\phara\OneDrive\Desktop\FMIS\python\dictionary_project\venv\Lib\site-packages\django\middleware\common.py", line 108, in process_response
    return self.response_redirect_class(self.get_full_path_with_slash(request))
                                        ~~~~~~~~~~~~~~~~~~~~~~~~~~~~~^^^^^^^^^
  File "C:\Users\phara\OneDrive\Desktop\FMIS\python\dictionary_project\venv\Lib\site-packages\django\middleware\common.py", line 87, in get_full_path_with_slash
    raise RuntimeError(
    ...<9 lines>...
    )
RuntimeError: You called this URL via POST, but the URL doesn't end in a slash and you have APPEND_SLASH set. Django can't redirect to the slash URL while maintaining POST data. Change your form to point to 172.23.23.48:9991/api/users/login/ (note the trailing slash), or set APPEND_SLASH=False in your Django settings.
[2025-04-09 08:48:59,214] ERROR basehttp 10916 19544 - "POST /api/users/login HTTP/1.1" 500 85072
[2025-04-09 09:43:54,616] ERROR views 6608 20592 - Sync error: name 'DictionaryEntrySyncSerializer' is not defined
[2025-04-09 09:43:54,618] ERROR log 6608 20592 - Internal Server Error: /api/dictionary/sync/
[2025-04-09 09:43:54,619] ERROR basehttp 6608 20592 - "GET /api/dictionary/sync/?last_sync_timestamp=2025-04-07T03%3A06%3A47.059983%2B00%3A00 HTTP/1.1" 500 83
[2025-04-09 09:52:35,954] ERROR log 13444 21252 - Internal Server Error: /api/users/login/
[2025-04-09 09:52:35,955] ERROR basehttp 13444 21252 - "POST /api/users/login/ HTTP/1.1" 500 86
[2025-04-09 09:52:41,991] ERROR log 16932 5288 - Internal Server Error: /api/users/login/
[2025-04-09 09:52:41,992] ERROR basehttp 16932 5288 - "POST /api/users/login/ HTTP/1.1" 500 86
[2025-04-09 10:21:20,255] ERROR log 20772 7248 - Internal Server Error: /api/users/register/
[2025-04-09 10:21:20,256] ERROR basehttp 20772 7248 - "POST /api/users/register/ HTTP/1.1" 500 122
