[2025-04-02 09:38:24,732] ERROR views 2320 13916 - Unexpected token blacklist error: {'detail': ErrorDetail(string='Token is blacklisted', code='token_not_valid'), 'code': ErrorDetail(string='token_not_valid', code='token_not_valid')}
[2025-04-02 09:38:24,733] ERROR log 2320 13916 - Internal Server Error: /api/token/blacklist/
[2025-04-02 09:38:24,733] ERROR basehttp 2320 13916 - "POST /api/token/blacklist/ HTTP/1.1" 500 67
[2025-04-02 10:34:46,124] ERROR views 15168 1716 - Bulk import error: [WinError 10061] No connection could be made because the target machine actively refused it
Traceback (most recent call last):
  File "C:\Users\phara\OneDrive\Desktop\FMIS\python\dictionary_project\venv\Lib\site-packages\kombu\utils\functional.py", line 32, in __call__
    return self.__value__
           ^^^^^^^^^^^^^^
AttributeError: 'ChannelPromise' object has no attribute '__value__'. Did you mean: '__call__'?

During handling of the above exception, another exception occurred:

Traceback (most recent call last):
  File "C:\Users\phara\OneDrive\Desktop\FMIS\python\dictionary_project\venv\Lib\site-packages\kombu\connection.py", line 472, in _reraise_as_library_errors
    yield
  File "C:\Users\phara\OneDrive\Desktop\FMIS\python\dictionary_project\venv\Lib\site-packages\kombu\connection.py", line 459, in _ensure_connection
    return retry_over_time(
        self._connection_factory, self.recoverable_connection_errors,
    ...<2 lines>...
        callback, timeout=timeout
    )
  File "C:\Users\phara\OneDrive\Desktop\FMIS\python\dictionary_project\venv\Lib\site-packages\kombu\utils\functional.py", line 318, in retry_over_time
    return fun(*args, **kwargs)
  File "C:\Users\phara\OneDrive\Desktop\FMIS\python\dictionary_project\venv\Lib\site-packages\kombu\connection.py", line 938, in _connection_factory
    self._connection = self._establish_connection()
                       ~~~~~~~~~~~~~~~~~~~~~~~~~~^^
  File "C:\Users\phara\OneDrive\Desktop\FMIS\python\dictionary_project\venv\Lib\site-packages\kombu\connection.py", line 860, in _establish_connection
    conn = self.transport.establish_connection()
  File "C:\Users\phara\OneDrive\Desktop\FMIS\python\dictionary_project\venv\Lib\site-packages\kombu\transport\pyamqp.py", line 203, in establish_connection
    conn.connect()
    ~~~~~~~~~~~~^^
  File "C:\Users\phara\OneDrive\Desktop\FMIS\python\dictionary_project\venv\Lib\site-packages\amqp\connection.py", line 324, in connect
    self.transport.connect()
    ~~~~~~~~~~~~~~~~~~~~~~^^
  File "C:\Users\phara\OneDrive\Desktop\FMIS\python\dictionary_project\venv\Lib\site-packages\amqp\transport.py", line 132, in connect
    self._connect(self.host, self.port, self.connect_timeout)
    ~~~~~~~~~~~~~^^^^^^^^^^^^^^^^^^^^^^^^^^^^^^^^^^^^^^^^^^^^
  File "C:\Users\phara\OneDrive\Desktop\FMIS\python\dictionary_project\venv\Lib\site-packages\amqp\transport.py", line 187, in _connect
    self.sock.connect(sa)
    ~~~~~~~~~~~~~~~~~^^^^
ConnectionRefusedError: [WinError 10061] No connection could be made because the target machine actively refused it

The above exception was the direct cause of the following exception:

Traceback (most recent call last):
  File "C:\Users\phara\OneDrive\Desktop\FMIS\python\dictionary_project\dictionary\views.py", line 980, in post
    process_staging_bulk_import.delay(
    ~~~~~~~~~~~~~~~~~~~~~~~~~~~~~~~~~^
        file_path=self.save_temporary_file(excel_file),
        ^^^^^^^^^^^^^^^^^^^^^^^^^^^^^^^^^^^^^^^^^^^^^^^
        user_id=request.user.id,
        ^^^^^^^^^^^^^^^^^^^^^^^^
        task_id=task_id
        ^^^^^^^^^^^^^^^
    )
    ^
  File "C:\Users\phara\OneDrive\Desktop\FMIS\python\dictionary_project\venv\Lib\site-packages\celery\app\task.py", line 444, in delay
    return self.apply_async(args, kwargs)
           ~~~~~~~~~~~~~~~~^^^^^^^^^^^^^^
  File "C:\Users\phara\OneDrive\Desktop\FMIS\python\dictionary_project\venv\Lib\site-packages\celery\app\task.py", line 601, in apply_async
    return app.send_task(
           ~~~~~~~~~~~~~^
        self.name, args, kwargs, task_id=task_id, producer=producer,
        ^^^^^^^^^^^^^^^^^^^^^^^^^^^^^^^^^^^^^^^^^^^^^^^^^^^^^^^^^^^^
    ...<2 lines>...
        **options
        ^^^^^^^^^
    )
    ^
  File "C:\Users\phara\OneDrive\Desktop\FMIS\python\dictionary_project\venv\Lib\site-packages\celery\app\base.py", line 922, in send_task
    amqp.send_task_message(P, name, message, **options)
    ~~~~~~~~~~~~~~~~~~~~~~^^^^^^^^^^^^^^^^^^^^^^^^^^^^^
  File "C:\Users\phara\OneDrive\Desktop\FMIS\python\dictionary_project\venv\Lib\site-packages\celery\app\amqp.py", line 523, in send_task_message
    ret = producer.publish(
        body,
    ...<8 lines>...
        **properties
    )
  File "C:\Users\phara\OneDrive\Desktop\FMIS\python\dictionary_project\venv\Lib\site-packages\kombu\messaging.py", line 190, in publish
    return _publish(
        body, priority, content_type, content_encoding,
        headers, properties, routing_key, mandatory, immediate,
        exchange_name, declare, timeout, confirm_timeout, retry, retry_policy
    )
  File "C:\Users\phara\OneDrive\Desktop\FMIS\python\dictionary_project\venv\Lib\site-packages\kombu\connection.py", line 556, in _ensured
    return fun(*args, **kwargs)
  File "C:\Users\phara\OneDrive\Desktop\FMIS\python\dictionary_project\venv\Lib\site-packages\kombu\messaging.py", line 200, in _publish
    channel = self.channel
              ^^^^^^^^^^^^
  File "C:\Users\phara\OneDrive\Desktop\FMIS\python\dictionary_project\venv\Lib\site-packages\kombu\messaging.py", line 224, in _get_channel
    channel = self._channel = channel()
                              ~~~~~~~^^
  File "C:\Users\phara\OneDrive\Desktop\FMIS\python\dictionary_project\venv\Lib\site-packages\kombu\utils\functional.py", line 34, in __call__
    value = self.__value__ = self.__contract__()
                             ~~~~~~~~~~~~~~~~~^^
  File "C:\Users\phara\OneDrive\Desktop\FMIS\python\dictionary_project\venv\Lib\site-packages\kombu\messaging.py", line 240, in <lambda>
    channel = ChannelPromise(lambda: connection.default_channel)
                                     ^^^^^^^^^^^^^^^^^^^^^^^^^^
  File "C:\Users\phara\OneDrive\Desktop\FMIS\python\dictionary_project\venv\Lib\site-packages\kombu\connection.py", line 957, in default_channel
    self._ensure_connection(**conn_opts)
    ~~~~~~~~~~~~~~~~~~~~~~~^^^^^^^^^^^^^
  File "C:\Users\phara\OneDrive\Desktop\FMIS\python\dictionary_project\venv\Lib\site-packages\kombu\connection.py", line 458, in _ensure_connection
    with ctx():
         ~~~^^
  File "C:\Users\phara\AppData\Local\Programs\Python\Python313\Lib\contextlib.py", line 162, in __exit__
    self.gen.throw(value)
    ~~~~~~~~~~~~~~^^^^^^^
  File "C:\Users\phara\OneDrive\Desktop\FMIS\python\dictionary_project\venv\Lib\site-packages\kombu\connection.py", line 476, in _reraise_as_library_errors
    raise ConnectionError(str(exc)) from exc
kombu.exceptions.OperationalError: [WinError 10061] No connection could be made because the target machine actively refused it
[2025-04-02 10:34:46,277] ERROR log 15168 1716 - Internal Server Error: /api/dictionary/staging/bulk_import/
[2025-04-02 10:34:46,278] ERROR basehttp 15168 1716 - "POST /api/dictionary/staging/bulk_import/ HTTP/1.1" 500 139
[2025-04-02 10:34:59,270] ERROR views 15168 1716 - Bulk import error: [WinError 10061] No connection could be made because the target machine actively refused it
Traceback (most recent call last):
  File "C:\Users\phara\OneDrive\Desktop\FMIS\python\dictionary_project\venv\Lib\site-packages\kombu\utils\functional.py", line 32, in __call__
    return self.__value__
           ^^^^^^^^^^^^^^
AttributeError: 'ChannelPromise' object has no attribute '__value__'. Did you mean: '__call__'?

During handling of the above exception, another exception occurred:

Traceback (most recent call last):
  File "C:\Users\phara\OneDrive\Desktop\FMIS\python\dictionary_project\venv\Lib\site-packages\kombu\connection.py", line 472, in _reraise_as_library_errors
    yield
  File "C:\Users\phara\OneDrive\Desktop\FMIS\python\dictionary_project\venv\Lib\site-packages\kombu\connection.py", line 459, in _ensure_connection
    return retry_over_time(
        self._connection_factory, self.recoverable_connection_errors,
    ...<2 lines>...
        callback, timeout=timeout
    )
  File "C:\Users\phara\OneDrive\Desktop\FMIS\python\dictionary_project\venv\Lib\site-packages\kombu\utils\functional.py", line 318, in retry_over_time
    return fun(*args, **kwargs)
  File "C:\Users\phara\OneDrive\Desktop\FMIS\python\dictionary_project\venv\Lib\site-packages\kombu\connection.py", line 938, in _connection_factory
    self._connection = self._establish_connection()
                       ~~~~~~~~~~~~~~~~~~~~~~~~~~^^
  File "C:\Users\phara\OneDrive\Desktop\FMIS\python\dictionary_project\venv\Lib\site-packages\kombu\connection.py", line 860, in _establish_connection
    conn = self.transport.establish_connection()
  File "C:\Users\phara\OneDrive\Desktop\FMIS\python\dictionary_project\venv\Lib\site-packages\kombu\transport\pyamqp.py", line 203, in establish_connection
    conn.connect()
    ~~~~~~~~~~~~^^
  File "C:\Users\phara\OneDrive\Desktop\FMIS\python\dictionary_project\venv\Lib\site-packages\amqp\connection.py", line 324, in connect
    self.transport.connect()
    ~~~~~~~~~~~~~~~~~~~~~~^^
  File "C:\Users\phara\OneDrive\Desktop\FMIS\python\dictionary_project\venv\Lib\site-packages\amqp\transport.py", line 132, in connect
    self._connect(self.host, self.port, self.connect_timeout)
    ~~~~~~~~~~~~~^^^^^^^^^^^^^^^^^^^^^^^^^^^^^^^^^^^^^^^^^^^^
  File "C:\Users\phara\OneDrive\Desktop\FMIS\python\dictionary_project\venv\Lib\site-packages\amqp\transport.py", line 187, in _connect
    self.sock.connect(sa)
    ~~~~~~~~~~~~~~~~~^^^^
ConnectionRefusedError: [WinError 10061] No connection could be made because the target machine actively refused it

The above exception was the direct cause of the following exception:

Traceback (most recent call last):
  File "C:\Users\phara\OneDrive\Desktop\FMIS\python\dictionary_project\dictionary\views.py", line 980, in post
    process_staging_bulk_import.delay(
    ~~~~~~~~~~~~~~~~~~~~~~~~~~~~~~~~~^
        file_path=self.save_temporary_file(excel_file),
        ^^^^^^^^^^^^^^^^^^^^^^^^^^^^^^^^^^^^^^^^^^^^^^^
        user_id=request.user.id,
        ^^^^^^^^^^^^^^^^^^^^^^^^
        task_id=task_id
        ^^^^^^^^^^^^^^^
    )
    ^
  File "C:\Users\phara\OneDrive\Desktop\FMIS\python\dictionary_project\venv\Lib\site-packages\celery\app\task.py", line 444, in delay
    return self.apply_async(args, kwargs)
           ~~~~~~~~~~~~~~~~^^^^^^^^^^^^^^
  File "C:\Users\phara\OneDrive\Desktop\FMIS\python\dictionary_project\venv\Lib\site-packages\celery\app\task.py", line 601, in apply_async
    return app.send_task(
           ~~~~~~~~~~~~~^
        self.name, args, kwargs, task_id=task_id, producer=producer,
        ^^^^^^^^^^^^^^^^^^^^^^^^^^^^^^^^^^^^^^^^^^^^^^^^^^^^^^^^^^^^
    ...<2 lines>...
        **options
        ^^^^^^^^^
    )
    ^
  File "C:\Users\phara\OneDrive\Desktop\FMIS\python\dictionary_project\venv\Lib\site-packages\celery\app\base.py", line 922, in send_task
    amqp.send_task_message(P, name, message, **options)
    ~~~~~~~~~~~~~~~~~~~~~~^^^^^^^^^^^^^^^^^^^^^^^^^^^^^
  File "C:\Users\phara\OneDrive\Desktop\FMIS\python\dictionary_project\venv\Lib\site-packages\celery\app\amqp.py", line 523, in send_task_message
    ret = producer.publish(
        body,
    ...<8 lines>...
        **properties
    )
  File "C:\Users\phara\OneDrive\Desktop\FMIS\python\dictionary_project\venv\Lib\site-packages\kombu\messaging.py", line 190, in publish
    return _publish(
        body, priority, content_type, content_encoding,
        headers, properties, routing_key, mandatory, immediate,
        exchange_name, declare, timeout, confirm_timeout, retry, retry_policy
    )
  File "C:\Users\phara\OneDrive\Desktop\FMIS\python\dictionary_project\venv\Lib\site-packages\kombu\connection.py", line 556, in _ensured
    return fun(*args, **kwargs)
  File "C:\Users\phara\OneDrive\Desktop\FMIS\python\dictionary_project\venv\Lib\site-packages\kombu\messaging.py", line 200, in _publish
    channel = self.channel
              ^^^^^^^^^^^^
  File "C:\Users\phara\OneDrive\Desktop\FMIS\python\dictionary_project\venv\Lib\site-packages\kombu\messaging.py", line 224, in _get_channel
    channel = self._channel = channel()
                              ~~~~~~~^^
  File "C:\Users\phara\OneDrive\Desktop\FMIS\python\dictionary_project\venv\Lib\site-packages\kombu\utils\functional.py", line 34, in __call__
    value = self.__value__ = self.__contract__()
                             ~~~~~~~~~~~~~~~~~^^
  File "C:\Users\phara\OneDrive\Desktop\FMIS\python\dictionary_project\venv\Lib\site-packages\kombu\messaging.py", line 240, in <lambda>
    channel = ChannelPromise(lambda: connection.default_channel)
                                     ^^^^^^^^^^^^^^^^^^^^^^^^^^
  File "C:\Users\phara\OneDrive\Desktop\FMIS\python\dictionary_project\venv\Lib\site-packages\kombu\connection.py", line 957, in default_channel
    self._ensure_connection(**conn_opts)
    ~~~~~~~~~~~~~~~~~~~~~~~^^^^^^^^^^^^^
  File "C:\Users\phara\OneDrive\Desktop\FMIS\python\dictionary_project\venv\Lib\site-packages\kombu\connection.py", line 458, in _ensure_connection
    with ctx():
         ~~~^^
  File "C:\Users\phara\AppData\Local\Programs\Python\Python313\Lib\contextlib.py", line 162, in __exit__
    self.gen.throw(value)
    ~~~~~~~~~~~~~~^^^^^^^
  File "C:\Users\phara\OneDrive\Desktop\FMIS\python\dictionary_project\venv\Lib\site-packages\kombu\connection.py", line 476, in _reraise_as_library_errors
    raise ConnectionError(str(exc)) from exc
kombu.exceptions.OperationalError: [WinError 10061] No connection could be made because the target machine actively refused it
[2025-04-02 10:34:59,311] ERROR log 15168 1716 - Internal Server Error: /api/dictionary/staging/bulk_import/
[2025-04-02 10:34:59,311] ERROR basehttp 15168 1716 - "POST /api/dictionary/staging/bulk_import/ HTTP/1.1" 500 139
[2025-04-02 10:37:42,501] ERROR log 19252 2360 - Internal Server Error: /swagger/
Traceback (most recent call last):
  File "C:\Users\phara\OneDrive\Desktop\FMIS\python\dictionary_project\venv\Lib\site-packages\django\core\handlers\exception.py", line 55, in inner
    response = get_response(request)
  File "C:\Users\phara\OneDrive\Desktop\FMIS\python\dictionary_project\venv\Lib\site-packages\django\core\handlers\base.py", line 197, in _get_response
    response = wrapped_callback(request, *callback_args, **callback_kwargs)
  File "C:\Users\phara\OneDrive\Desktop\FMIS\python\dictionary_project\venv\Lib\site-packages\django\views\decorators\csrf.py", line 65, in _view_wrapper
    return view_func(request, *args, **kwargs)
  File "C:\Users\phara\OneDrive\Desktop\FMIS\python\dictionary_project\venv\Lib\site-packages\django\views\generic\base.py", line 104, in view
    return self.dispatch(request, *args, **kwargs)
           ~~~~~~~~~~~~~^^^^^^^^^^^^^^^^^^^^^^^^^^
  File "C:\Users\phara\OneDrive\Desktop\FMIS\python\dictionary_project\venv\Lib\site-packages\rest_framework\views.py", line 509, in dispatch
    response = self.handle_exception(exc)
  File "C:\Users\phara\OneDrive\Desktop\FMIS\python\dictionary_project\venv\Lib\site-packages\rest_framework\views.py", line 469, in handle_exception
    self.raise_uncaught_exception(exc)
    ~~~~~~~~~~~~~~~~~~~~~~~~~~~~~^^^^^
  File "C:\Users\phara\OneDrive\Desktop\FMIS\python\dictionary_project\venv\Lib\site-packages\rest_framework\views.py", line 480, in raise_uncaught_exception
    raise exc
  File "C:\Users\phara\OneDrive\Desktop\FMIS\python\dictionary_project\venv\Lib\site-packages\rest_framework\views.py", line 506, in dispatch
    response = handler(request, *args, **kwargs)
  File "C:\Users\phara\OneDrive\Desktop\FMIS\python\dictionary_project\venv\Lib\site-packages\drf_yasg\views.py", line 112, in get
    schema = generator.get_schema(request, self.public)
  File "C:\Users\phara\OneDrive\Desktop\FMIS\python\dictionary_project\venv\Lib\site-packages\drf_yasg\generators.py", line 276, in get_schema
    paths, prefix = self.get_paths(endpoints, components, request, public)
                    ~~~~~~~~~~~~~~^^^^^^^^^^^^^^^^^^^^^^^^^^^^^^^^^^^^^^^^
  File "C:\Users\phara\OneDrive\Desktop\FMIS\python\dictionary_project\venv\Lib\site-packages\drf_yasg\generators.py", line 482, in get_paths
    operation = self.get_operation(view, path, prefix, method, components, request)
  File "C:\Users\phara\OneDrive\Desktop\FMIS\python\dictionary_project\venv\Lib\site-packages\drf_yasg\generators.py", line 524, in get_operation
    operation = view_inspector.get_operation(operation_keys)
  File "C:\Users\phara\OneDrive\Desktop\FMIS\python\dictionary_project\venv\Lib\site-packages\drf_yasg\inspectors\view.py", line 36, in get_operation
    parameters = self.add_manual_parameters(parameters)
  File "C:\Users\phara\OneDrive\Desktop\FMIS\python\dictionary_project\venv\Lib\site-packages\drf_yasg\inspectors\view.py", line 166, in add_manual_parameters
    raise SwaggerGenerationError("cannot add form parameters when the request has a request body; "
                                 "did you forget to set an appropriate parser class on the view?")
drf_yasg.errors.SwaggerGenerationError: cannot add form parameters when the request has a request body; did you forget to set an appropriate parser class on the view?
[2025-04-02 10:37:42,514] ERROR basehttp 19252 2360 - "GET /swagger/?format=openapi HTTP/1.1" 500 161204
